Workbook

Sheet REV
A1: OFERTAS VÁLIDAS APENAS PARA PLANOS CONSUMER
B4: Inclusão de Preços
B5: Alteração de Preços
A7: Preços Elegíveis a Price Back
A8: Preços Elegíveis a Price Oferta
A9: CANAL: | B9: REVENDAS
C11: DATA INÍCIO: | D11: 46092 | J11: COM FIDELIZAÇÃO - GROSS / MIGRAÇÃO / UPGRADE / PORTABILIDADE / BASE SEM MOVIMENTAÇÃO | AB11: TIM FIBRA | AM11: TIM FIXO | AP11: TIM CASA
A12: Regra Reembolso Pós Fidelizado | B12: CATEGORIA MKT | C12: CÓDIGO | D12: DESCRIÇÃO COMERCIAL | E12: DESCRIÇÃO SAP | F12: PRÉ | G12: PREÇO BASE FATURAMENTO RETAIL | H12: CONTROLE NÃO FIDELIZADO - TODOS (Fatura / Express) | I12: PÓS PAGO NÃO FIDELIZADO - VIDE ABA DE REGRAS | J12: TIM CONTROLE | K12: TIM CONTROLE PLUS | L12: TIM CONTROLE PREMIUM | M12: TIM CONTROLE SMART | N12: TIM CONTROLE REDES SOCIAIS | O12: TIM BLACK | P12: TIM BLACK PLUS | Q12: TIM BLACK PREMIUM | R12: TIM BLACK A (15GB) | S12: TIM BLACK B (20GB) | T12: TIM BLACK C (25GB) | U12: TIM BLACK C ULTRA | V12: TIM BLACK FAMÍLIA | W12: TIM BLACK FAMÍLIA A ONE | X12: TIM BLACK FAMÍLIA PLUS | Y12: TIM BLACK FAMÍLIA PREMIUM | Z12: TIM BLACK FAMÍLIA C ONE | AA12: TIM BLACK FAMÍLIA VIP | AB12: TIM Fibra 300M 24 | AC12: TIM Fibra 400M 24 | AD12: TIM Fibra 500M 24 - 2 | AE12: TIM Fibra 600M 24 - 2 | AF12: TIM Fibra 600M P 24 - 2 | AG12: TIM Fibra 600M M 24 - 2 | AH12: TIM Fibra 600M GP 25 | AI12: TIM Fibra 1GB 24 | AJ12: TIM Fibra 1GB P 24 | AK12: TIM Fibra 1GB M 24 | AL12: TIM Fibra 2GB 24 | AM12: TIM FIXO LOCAL TOTAL PLUS (Plano Fidelizado) | AN12: TIM FIXO BRASIL TOTAL PLUS (Plano Fidelizado) | AO12: TIM FIXO TOTAL LDI PLUS (Plano Fidelizado) | AP12: TIM LIVE INTERNET 30GB (sem fidelização) | AQ12: TIM LIVE INTERNET 50GB (sem fidelização) | AR12: TIM LIVE INTERNET 80GB (sem fidelização) | AS12: TIM LIVE INTERNET 30GB PLUS | AT12: TIM LIVE INTERNET 50GB PLUS | AU12: TIM LIVE INTERNET 80GB PLUS | AW12: DATA FIM DA OFERTA | AX12: TECNOLOGIA
A13: ADM | B13: 21X | C13: 4010990 | D13: Alcatel Pixi 4.5 4G | E13: Alcatel Pixi 4.5 4G-Preto | F13: 479 | G13: 479 | H13: 479 | I13: 479 | J13: =M13 -> 479 | K13: =M13 -> 479 | L13: =N13 -> 479 | M13: 479 | N13: 479 | AW13: 31.03.2026 | AX13: 4G
A14: ADM | B14: 21X | C14: 4010991 | D14: Alcatel Pixi 4.5 4G | E14: Alcatel Pixi 4.5 4G-Branco | F14: 479 | G14: 479 | H14: 479 | I14: 479 | J14: =M14 -> 479 | K14: =M14 -> 479 | L14: =N14 -> 479 | M14: 479 | N14: 479 | AW14: 31.03.2026 | AX14: 4G
A15: ADM | B15: 21X | C15: 4011353 | D15: Alcatel Pixi 4.5 4G | E15: Alcatel Pixi 4.5 4G-Preto AM | F15: 479 | G15: 479 | H15: 479 | I15: 479 | J15: =M15 -> 479 | K15: =M15 -> 479 | L15: =N15 -> 479 | M15: 479 | N15: 479 | AW15: 31.03.2026 | AX15: 4G
A16: ADM | B16: 21X | C16: 4011354 | D16: Alcatel Pixi 4.5 4G | E16: Alcatel Pixi 4.5 4G-Branco AM | F16: 479 | G16: 479 | H16: 479 | I16: 479 | J16: =M16 -> 479 | K16: =M16 -> 479 | L16: =N16 -> 479 | M16: 479 | N16: 479 | AW16: 31.03.2026 | AX16: 4G
A17: Price Oferta | B17: 21X | C17: 4013660 | D17: APPLE IPHONE SE 64GB 2GER | E17: APPLE IPHONE SE 64GB 2GER-PRETO | F17: 999 | G17: 549 | H17: 999 | I17: 999 | J17: 799 | K17: 699 | L17: 699 | M17: 799 | N17: 799 | O17: 599 | P17: 599 | Q17: =T17 -> 599 | R17: 599 | S17: 599 | T17: 599 | U17: 599 | V17: 599 | W17: 599 | X17: 549 | Y17: 549 | Z17: 549 | AA17: 549 | AW17: 31.03.2026 | AX17: 4G
A18: Price Oferta | B18: 21X | C18: 4013661 | D18: APPLE IPHONE SE 64GB 2GER | E18: Apple iPhone SE 64GB 2Ger-Branco | F18: 999 | G18: 549 | H18: 999 | I18: 999 | J18: 799 | K18: 699 | L18: 699 | M18: 799 | N18: 799 | O18: 599 | P18: 599 | Q18: =T18 -> 599 | R18: 599 | S18: 599 | T18: 599 | U18: 599 | V18: 599 | W18: 599 | X18: 549 | Y18: 549 | Z18: 549 | AA18: 549 | AW18: 31.03.2026 | AX18: 4G
A19: Price Oferta | B19: 21X | C19: 4013662 | D19: APPLE IPHONE SE 64GB 2GER | E19: Apple iPhone SE 64GB 2Ger-Vermelho | F19: 999 | G19: 549 | H19: 999 | I19: 999 | J19: 799 | K19: 699 | L19: 699 | M19: 799 | N19: 799 | O19: 599 | P19: 599 | Q19: =T19 -> 599 | R19: 599 | S19: 599 | T19: 599 | U19: 599 | V19: 599 | W19: 599 | X19: 549 | Y19: 549 | Z19: 549 | AA19: 549 | AW19: 31.03.2026 | AX19: 4G
A20: Price Oferta | B20: 21X | C20: 4013981 | D20: APPLE IPHONE SE 64GB 2GER | E20: APPLE IPHONE SE 64GB 2GE-PRETO NAC | F20: 999 | G20: 549 | H20: 999 | I20: 999 | J20: 799 | K20: 699 | L20: 699 | M20: 799 | N20: 799 | O20: 599 | P20: 599 | Q20: =T20 -> 599 | R20: 599 | S20: 599 | T20: 599 | U20: 599 | V20: 599 | W20: 599 | X20: 549 | Y20: 549 | Z20: 549 | AA20: 549 | AW20: 31.03.2026 | AX20: 4G
A21: Price Oferta | B21: 21X | C21: 4013984 | D21: APPLE IPHONE SE 64GB 2GER | E21: APPLE IPHONE SE 64GB 2GE-BRANCO NAC | F21: 999 | G21: 549 | H21: 999 | I21: 999 | J21: 799 | K21: 699 | L21: 699 | M21: 799 | N21: 799 | O21: 599 | P21: 599 | Q21: =T21 -> 599 | R21: 599 | S21: 599 | T21: 599 | U21: 599 | V21: 599 | W21: 599 | X21: 549 | Y21: 549 | Z21: 549 | AA21: 549 | AW21: 31.03.2026 | AX21: 4G
A22: Price Oferta | B22: 21X | C22: 4013986 | D22: APPLE IPHONE SE 64GB 2GER | E22: APPLE IPHONE SE 64GB 2GE-VERMELHO NAC | F22: 999 | G22: 549 | H22: 999 | I22: 999 | J22: 799 | K22: 699 | L22: 699 | M22: 799 | N22: 799 | O22: 599 | P22: 599 | Q22: =T22 -> 599 | R22: 599 | S22: 599 | T22: 599 | U22: 599 | V22: 599 | W22: 599 | X22: 549 | Y22: 549 | Z22: 549 | AA22: 549 | AW22: 31.03.2026 | AX22: 4G
A23: Price Oferta | B23: 21X | C23: 4013852 | D23: APPLE IPHONE SE 64GB 2GER | E23: APPLE IPHONE SE 64GB 2GE-PRETO NAC S.KIT | F23: 999 | G23: 549 | H23: 999 | I23: 999 | J23: 799 | K23: 699 | L23: 699 | M23: 799 | N23: 799 | O23: 599 | P23: 599 | Q23: =T23 -> 599 | R23: 599 | S23: 599 | T23: 599 | U23: 599 | V23: 599 | W23: 599 | X23: 549 | Y23: 549 | Z23: 549 | AA23: 549 | AW23: 31.03.2026 | AX23: 4G
A24: Price Oferta | B24: 21X | C24: 4014002 | D24: APPLE IPHONE SE 64GB 2GER | E24: APPLE IPHONE SE 64GB 2GE-BRANC NAC S.KIT | F24: 999 | G24: 549 | H24: 999 | I24: 999 | J24: 799 | K24: 699 | L24: 699 | M24: 799 | N24: 799 | O24: 599 | P24: 599 | Q24: =T24 -> 599 | R24: 599 | S24: 599 | T24: 599 | U24: 599 | V24: 599 | W24: 599 | X24: 549 | Y24: 549 | Z24: 549 | AA24: 549 | AW24: 31.03.2026 | AX24: 4G
A25: Price Oferta | B25: 21X | C25: 4013875 | D25: APPLE IPHONE 12 64GB | E25: APPLE IPHONE 12 64GB-VERDE | F25: 6499 | G25: 2599 | H25: 999 | I25: 999 | J25: 999 | K25: 999 | L25: 999 | M25: 999 | N25: 999 | O25: 999 | P25: 999 | Q25: 999 | R25: 999 | S25: 999 | T25: 999 | U25: 999 | V25: 999 | W25: 999 | X25: 999 | Y25: 999 | Z25: 999 | AA25: 999 | AW25: 31.03.2026 | AX25: 5G
A26: Price Oferta | B26: 21X | C26: 4013877 | D26: APPLE IPHONE 12 64GB | E26: APPLE IPHONE 12 64GB-VERMELHO | F26: 6499 | G26: 2599 | H26: 999 | I26: 999 | J26: 999 | K26: 999 | L26: 999 | M26: 999 | N26: 999 | O26: 999 | P26: 999 | Q26: 999 | R26: 999 | S26: 999 | T26: 999 | U26: 999 | V26: 999 | W26: 999 | X26: 999 | Y26: 999 | Z26: 999 | AA26: 999 | AW26: 31.03.2026 | AX26: 5G
A27: Price Oferta | B27: 21X | C27: 4013878 | D27: APPLE IPHONE 12 64GB | E27: APPLE IPHONE 12 64GB-BRANCO | F27: 6499 | G27: 2599 | H27: 999 | I27: 999 | J27: 999 | K27: 999 | L27: 999 | M27: 999 | N27: 999 | O27: 999 | P27: 999 | Q27: 999 | R27: 999 | S27: 999 | T27: 999 | U27: 999 | V27: 999 | W27: 999 | X27: 999 | Y27: 999 | Z27: 999 | AA27: 999 | AW27: 31.03.2026 | AX27: 5G
A28: Price Oferta | B28: 21X | C28: 4013879 | D28: APPLE IPHONE 12 64GB | E28: APPLE IPHONE 12 64GB-PRETO | F28: 6499 | G28: 2599 | H28: 999 | I28: 999 | J28: 999 | K28: 999 | L28: 999 | M28: 999 | N28: 999 | O28: 999 | P28: 999 | Q28: 999 | R28: 999 | S28: 999 | T28: 999 | U28: 999 | V28: 999 | W28: 999 | X28: 999 | Y28: 999 | Z28: 999 | AA28: 999 | AW28: 31.03.2026 | AX28: 5G
A29: Price Oferta | B29: 21X | C29: 4013880 | D29: APPLE IPHONE 12 64GB | E29: APPLE IPHONE 12 64GB-AZUL | F29: 6499 | G29: 2599 | H29: 999 | I29: 999 | J29: 999 | K29: 999 | L29: 999 | M29: 999 | N29: 999 | O29: 999 | P29: 999 | Q29: 999 | R29: 999 | S29: 999 | T29: 999 | U29: 999 | V29: 999 | W29: 999 | X29: 999 | Y29: 999 | Z29: 999 | AA29: 999 | AW29: 31.03.2026 | AX29: 5G
A30: Price Oferta | B30: 21X | C30: 4014295 | D30: APPLE IPHONE 12 64GB | E30: APPLE IPHONE 12 64GB-ROXO | F30: 6499 | G30: 2599 | H30: 999 | I30: 999 | J30: 999 | K30: 999 | L30: 999 | M30: 999 | N30: 999 | O30: 999 | P30: 999 | Q30: 999 | R30: 999 | S30: 999 | T30: 999 | U30: 999 | V30: 999 | W30: 999 | X30: 999 | Y30: 999 | Z30: 999 | AA30: 999 | AW30: 31.03.2026 | AX30: 5G
A31: Price Oferta | B31: 21X | C31: 4014386 | D31: APPLE IPHONE 12 64GB | E31: APPLE IPHONE 12 64GB-AZUL NAC | F31: 6499 | G31: 2599 | H31: 999 | I31: 999 | J31: 999 | K31: 999 | L31: 999 | M31: 999 | N31: 999 | O31: 999 | P31: 999 | Q31: 999 | R31: 999 | S31: 999 | T31: 999 | U31: 999 | V31: 999 | W31: 999 | X31: 999 | Y31: 999 | Z31: 999 | AA31: 999 | AW31: 31.03.2026 | AX31: 5G
A32: Price Oferta | B32: 21X | C32: 4014380 | D32: APPLE IPHONE 12 64GB | E32: APPLE IPHONE 12 64GB-PRETO NAC | F32: 6499 | G32: 2599 | H32: 999 | I32: 999 | J32: 999 | K32: 999 | L32: 999 | M32: 999 | N32: 999 | O32: 999 | P32: 999 | Q32: 999 | R32: 999 | S32: 999 | T32: 999 | U32: 999 | V32: 999 | W32: 999 | X32: 999 | Y32: 999 | Z32: 999 | AA32: 999 | AW32: 31.03.2026 | AX32: 5G
A33: Price Oferta | B33: 21X | C33: 4014382 | D33: APPLE IPHONE 12 64GB | E33: APPLE IPHONE 12 64GB-BRANCO NAC | F33: 6499 | G33: 2599 | H33: 999 | I33: 999 | J33: 999 | K33: 999 | L33: 999 | M33: 999 | N33: 999 | O33: 999 | P33: 999 | Q33: 999 | R33: 999 | S33: 999 | T33: 999 | U33: 999 | V33: 999 | W33: 999 | X33: 999 | Y33: 999 | Z33: 999 | AA33: 999 | AW33: 31.03.2026 | AX33: 5G
A34: Price Oferta | B34: 21X | C34: 4013881 | D34: APPLE IPHONE 12 128GB | E34: APPLE IPHONE 12 128GB-VERDE | F34: 4499 | G34: 2299 | H34: 999 | I34: 999 | J34: 999 | K34: 999 | L34: 999 | M34: 999 | N34: 999 | O34: 999 | P34: 999 | Q34: 999 | R34: 999 | S34: 999 | T34: 999 | U34: 999 | V34: 999 | W34: 999 | X34: 999 | Y34: 999 | Z34: 999 | AA34: 999 | AW34: 31.03.2026 | AX34: 5G
A35: Price Oferta | B35: 21X | C35: 4013882 | D35: APPLE IPHONE 12 128GB | E35: APPLE IPHONE 12 128GB-VERMELHO | F35: 4499 | G35: 2299 | H35: 999 | I35: 999 | J35: 999 | K35: 999 | L35: 999 | M35: 999 | N35: 999 | O35: 999 | P35: 999 | Q35: 999 | R35: 999 | S35: 999 | T35: 999 | U35: 999 | V35: 999 | W35: 999 | X35: 999 | Y35: 999 | Z35: 999 | AA35: 999 | AW35: 31.03.2026 | AX35: 5G
A36: Price Oferta | B36: 21X | C36: 4013883 | D36: APPLE IPHONE 12 128GB | E36: APPLE IPHONE 12 128GB-BRANCO | F36: 4499 | G36: 2299 | H36: 999 | I36: 999 | J36: 999 | K36: 999 | L36: 999 | M36: 999 | N36: 999 | O36: 999 | P36: 999 | Q36: 999 | R36: 999 | S36: 999 | T36: 999 | U36: 999 | V36: 999 | W36: 999 | X36: 999 | Y36: 999 | Z36: 999 | AA36: 999 | AW36: 31.03.2026 | AX36: 5G
... A69: Price Oferta | B69: 21X | C69: 4014884 | D69: APPLE IPHONE 13 PRO 256GB | E69: APPLE IPHONE 13 PRO 256GB-VERDE ALPINO | F69: 10499 | G69: 5199 | H69: 3999 | I69: 3999 | J69: 3999 | K69: 3999 | L69: 3999 | M69: 3999 | N69: 3999 | O69: 3999 | P69: 3999 | Q69: 3999 | R69: 3999 | S69: 3999 | T69: 3999 | U69: 3999 | V69: 3999 | W69: 3999 | X69: 3999 | Y69: 3999 | Z69: 3999 | AA69: 3999 | AW69: 31.03.2026 | AX69: 5G
A70: Price Oferta | B70: 21X | C70: 4014593 | D70: APPLE IPHONE 13 PRO MAX 256GB | E70: APPLE IPHONE 13 PRO MAX 256GB-GRAFITE | F70: 11499 | G70: 6199 | H70: 6999 | I70: 6999 | J70: =M70 -> 6799 | K70: 6699 | L70: 6699 | M70: 6799 | N70: 6799 | O70: =R70 -> 6499 | P70: =S70 -> 6299 | Q70: 5999 | R70: 6499 | S70: 6299 | T70: 5999 | U70: 5899 | V70: 5899 | W70: 5799 | X70: 5699 | Y70: 5499 | Z70: 5399 | AA70: 5399 | AW70: 31.03.2026 | AX70: 5G
A71: Price Oferta | B71: 21X | C71: 4014599 | D71: APPLE IPHONE 13 PRO MAX 256GB | E71: APPLE IPHONE 13 PRO MAX 256GB-PRATEADO | F71: 11499 | G71: 6199 | H71: 6999 | I71: 6999 | J71: =M71 -> 6799 | K71: 6699 | L71: 6699 | M71: 6799 | N71: 6799 | O71: =R71 -> 6499 | P71: =S71 -> 6299 | Q71: 5999 | R71: 6499 | S71: 6299 | T71: 5999 | U71: 5899 | V71: 5899 | W71: 5799 | X71: 5699 | Y71: 5499 | Z71: 5399 | AA71: 5399 | AW71: 31.03.2026 | AX71: 5G
A72: Price Oferta | B72: 21X | C72: 4014605 | D72: APPLE IPHONE 13 PRO MAX 256GB | E72: APPLE IPHONE 13 PRO MAX 256GB-DOURADO | F72: 11499 | G72: 6199 | H72: 6999 | I72: 6999 | J72: =M72 -> 6799 | K72: 6699 | L72: 6699 | M72: 6799 | N72: 6799 | O72: =R72 -> 6499 | P72: =S72 -> 6299 | Q72: 5999 | R72: 6499 | S72: 6299 | T72: 5999 | U72: 5899 | V72: 5899 | W72: 5799 | X72: 5699 | Y72: 5499 | Z72: 5399 | AA72: 5399 | AW72: 31.03.2026 | AX72: 5G
A73: Price Oferta | B73: 21X | C73: 4014612 | D73: APPLE IPHONE 13 PRO MAX 256GB | E73: APPLE IPHONE 13 PRO MAX 256GB-AZUL SIERR | F73: 11499 | G73: 6199 | H73: 6999 | I73: 6999 | J73: =M73 -> 6799 | K73: 6699 | L73: 6699 | M73: 6799 | N73: 6799 | O73: =R73 -> 6499 | P73: =S73 -> 6299 | Q73: 5999 | R73: 6499 | S73: 6299 | T73: 5999 | U73: 5899 | V73: 5899 | W73: 5799 | X73: 5699 | Y73: 5499 | Z73: 5399 | AA73: 5399 | AW73: 31.03.2026 | AX73: 5G
A74: Price Oferta | B74: 21X | C74: 4014868 | D74: APPLE IPHONE 13 PRO MAX 256GB | E74: APPLE IPHONE 13 PRO MAX 256GB-VERDE ALP | F74: 11499 | G74: 6199 | H74: 6999 | I74: 6999 | J74: =M74 -> 6799 | K74: 6699 | L74: 6699 | M74: 6799 | N74: 6799 | O74: =R74 -> 6499 | P74: =S74 -> 6299 | Q74: 5999 | R74: 6499 | S74: 6299 | T74: 5999 | U74: 5899 | V74: 5899 | W74: 5799 | X74: 5699 | Y74: 5499 | Z74: 5399 | AA74: 5399 | AW74: 31.03.2026 | AX74: 5G
A75: Price Oferta | B75: 21X | C75: 4015019 | D75: APPLE IPHONE 14 128GB | E75: APPLE IPHONE 14 128GB-AZUL | F75: 7299 | G75: 3899 | H75: 5299 | I75: 5299 | J75: 4199 | K75: 4199 | L75: 4199 | M75: 4199 | N75: 4199 | O75: 3899 | P75: 3799 | Q75: 3099 | R75: 3899 | S75: 3799 | T75: 3099 | U75: 3099 | V75: 3099 | W75: 3099 | X75: 2999 | Y75: 2499 | Z75: 2499 | AA75: 2499 | AW75: 31.03.2026 | AX75: 5G
A76: Price Oferta | B76: 21X | C76: 4015165 | D76: APPLE IPHONE 14 128GB | E76: APPLE IPHONE 14 128GB-ROXO | F76: 7299 | G76: 3899 | H76: 5299 | I76: 5299 | J76: 4199 | K76: 4199 | L76: 4199 | M76: 4199 | N76: 4199 | O76: 3899 | P76: 3799 | Q76: 3099 | R76: 3899 | S76: 3799 | T76: 3099 | U76: 3099 | V76: 3099 | W76: 3099 | X76: 2999 | Y76: 2499 | Z76: 2499 | AA76: 2499 | AW76: 31.03.2026 | AX76: 5G
...

Sheet ACESSÓRIOS REV
B1: TABELA DE PREÇOS - ACESSÓRIOS
B3: CANAL: | C3: REVENDAS
B4: Inclusão de Preço
B5: Alteração de Preço
C6: DATA INÍCIO: | D6: =REV!D11 -> 46092 | AB6: TIM FIBRA
B7: CATEGORIA MKT | C7: CÓDIGO | D7: DESCRIÇÃO COMERCIAL | E7: DESCRIÇÃO SAP | F7: PRÉ | G7: PREÇO BASE FATURAMENTO RETAIL | H7: CONTROLE NÃO FIDELIZADO - TODOS (Fatura / Express) | I7: PÓS PAGO NÃO FIDELIZADO - VIDE ABA DE REGRAS | J7: TIM CONTROLE | K7: TIM CONTROLE PLUS | L7: TIM CONTROLE PREMIUM | M7: TIM CONTROLE SMART | N7: TIM CONTROLE REDES SOCIAIS | O7: TIM BLACK | P7: TIM BLACK PLUS | Q7: TIM BLACK PREMIUM | R7: TIM BLACK A (15GB) | S7: TIM BLACK B (20GB) | T7: TIM BLACK C (25GB) | U7: TIM BLACK C ULTRA | V7: TIM BLACK FAMÍLIA | W7: TIM BLACK FAMÍLIA A ONE | X7: TIM BLACK FAMÍLIA PLUS | Y7: TIM BLACK FAMÍLIA PREMIUM | Z7: TIM BLACK FAMÍLIA C ONE | AA7: TIM BLACK FAMÍLIA VIP | AB7: TIM Fibra 300M 24 | AC7: TIM Fibra 400M 24 | AD7: TIM Fibra 500M 24 - 2 | AE7: TIM Fibra 600M 24 - 2 | AF7: TIM Fibra 600M P 24 - 2 | AG7: TIM Fibra 600M M 24 - 2 | AH7: TIM Fibra 600M GP 25 | AI7: TIM Fibra 1GB 24 | AJ7: TIM Fibra 1GB P 24 | AK7: TIM Fibra 1GB M 24 | AL7: TIM Fibra 2GB 24 | AM7: DATA FIM DA OFERTA
B8: SMARTHOME | C8: 4014927 | D8: BALANCA INTELIGENTE GEONAV | E8: BALANCA INTELIGENTE GEONAV-BRANCO | F8: 199 | G8: 199 | AB8: 169 | AC8: 169 | AD8: 169 | AE8: 169 | AF8: 169 | AG8: 169 | AH8: 169 | AI8: 169 | AJ8: 169 | AK8: 169 | AL8: 169 | AM8: 31.12.9999
B9: GAMER | C9: 4016500 | D9: BASE DE CARREGAMENTO SONY DUALSENSE | E9: BASE DE CARREGAMENTO SONY DUALSENSE-BRAN | F9: 199 | G9: 199 | AM9: 31.12.9999
B10: MUSICA | C10: 4014444 | D10: CAIXA DE SOM BT JBL CHARGE 5 | E10: CAIXA DE SOM BT JBL CHARGE 5-PRETO | F10: 799 | G10: 799 | H10: 799 | I10: 799 | J10: 749 | K10: 749 | L10: 749 | M10: 749 | N10: 749 | O10: 699 | P10: 599 | Q10: 449 | R10: 699 | S10: 599 | T10: 449 | U10: 449 | V10: 449 | W10: 449 | X10: 449 | Y10: 449 | Z10: 449 | AA10: 449 | AM10: 31.12.9999
B11: MUSICA | C11: 4017142 | D11: CAIXA DE SOM BT JBL CHARGE 6 | E11: CAIXA DE SOM BT JBL CHARGE 6-AZUL | F11: 999 | G11: 999 | H11: 999 | I11: 999 | J11: 949 | K11: 949 | L11: 949 | M11: 949 | N11: 949 | O11: 899 | P11: 799 | Q11: 599 | R11: 899 | S11: 799 | T11: 599 | U11: 599 | V11: 599 | W11: 599 | X11: 549 | Y11: 549 | Z11: 549 | AA11: 549 | AM11: 31.12.9999
B12: MUSICA | C12: 4014958 | D12: CAIXA DE SOM BT JBL FLIP 6 | E12: CAIXA DE SOM BT JBL FLIP 6-PRETO | F12: 399 | G12: 399 | H12: 399 | I12: 399 | J12: 349 | K12: 349 | L12: 349 | M12: 349 | N12: 349 | O12: 299 | P12: 299 | Q12: 249 | R12: 299 | S12: 249 | T12: 249 | U12: 249 | V12: 249 | W12: 249 | X12: 249 | Y12: 249 | Z12: 249 | AA12: 249 | AM12: 31.12.9999
B13: MÚSICA | C13: 4017062 | D13: CAIXA DE SOM BT JBL FLIP 7 | E13: CAIXA DE SOM BT JBL FLIP 7-PRETO | F13: 899 | G13: 899 | H13: 899 | I13: 899 | J13: 849 | K13: 849 | L13: 849 | M13: 849 | N13: 849 | O13: 799 | P13: 799 | Q13: 699 | R13: 799 | S13: 699 | T13: 499 | U13: 499 | V13: 499 | W13: 499 | X13: 499 | Y13: 499 | Z13: 499 | AA13: 499 | AM13: 31.12.9999
B14: MUSICA | C14: 4016330 | D14: CAIXA DE SOM BT JBL GO4 | E14: CAIXA DE SOM BT JBL GO4-PRETO | F14: 299 | G14: 199 | H14: 299 | I14: 299 | J14: 249 | K14: 249 | L14: 249 | M14: 249 | N14: 249 | O14: 199 | P14: 199 | Q14: 199 | R14: 199 | S14: 199 | T14: 199 | U14: 199 | V14: 199 | W14: 199 | X14: 199 | Y14: 199 | Z14: 199 | AA14: 199 | AB14: 249 | AC14: 249 | AD14: 249 | AE14: 249 | AF14: 249 | AG14: 249 | AH14: 249 | AI14: 249 | AJ14: 249 | AK14: 249 | AL14: 249 | AM14: 31.12.9999
B15: MUSICA | C15: 4015270 | D15: CAIXA DE SOM JBL BOOMBOX 3 | E15: CAIXA DE SOM JBL BOOMBOX 3-PRETO | F15: 2499 | G15: 999 | H15: 2499 | I15: 2499 | J15: 2449 | K15: 2449 | L15: 2449 | M15: 2449 | N15: 2449 | O15: 2399 | P15: 2299 | Q15: 1299 | R15: 2399 | S15: 2299 | T15: 1299 | U15: 1299 | V15: 1299 | W15: 1299 | X15: 1299 | Y15: 999 | Z15: 999 | AA15: 949 | AB15: 2449 | AC15: 2449 | AD15: 2449 | AE15: 2449 | AF15: 2399 | AG15: 2399 | AH15: 1299 | AI15: 1299 | AJ15: 1299 | AK15: 1299 | AL15: 999 | AM15: 31.12.9999
B16: MUSICA | C16: 4015688 | D16: CAIXA DE SOM JBL BOOMBOX 3 | E16: CAIXA DE SOM JBL BOOMBOX 3-PRETO AM | F16: 2499 | G16: 999 | H16: 2499 | I16: 2499 | J16: 2449 | K16: 2449 | L16: 2449 | M16: 2449 | N16: 2449 | O16: 2399 | P16: 2299 | Q16: 1299 | R16: 2399 | S16: 2299 | T16: 1299 | U16: 1299 | V16: 1299 | W16: 1299 | X16: 1299 | Y16: 999 | Z16: 999 | AA16: 949 | AB16: 2449 | AC16: 2449 | AD16: 2449 | AE16: 2449 | AF16: 2399 | AG16: 2399 | AH16: 1299 | AI16: 1299 | AJ16: 1299 | AK16: 1299 | AL16: 999 | AM16: 31.12.9999
B17: MUSICA | C17: 4016341 | D17: CAIXA DE SOM JBL ENCORE ESSENTIAL | E17: CAIXA DE SOM JBL ENCORE ESSENTIAL-PRE AM | F17: 1199 | G17: 1199 | H17: 1199 | I17: 1199 | J17: 1149 | K17: 1149 | L17: 1149 | M17: 1149 | N17: 1149 | O17: 1099 | P17: 1099 | Q17: 999 | R17: 1099 | S17: 999 | T17: 799 | U17: 799 | V17: 799 | W17: 799 | X17: 699 | Y17: 649 | Z17: 649 | AA17: 649 | AM17: 31.12.9999
B18: MUSICA | C18: 4015273 | D18: CAIXA DE SOM JBL ENCORE ESSENTIAL | E18: CAIXA DE SOM JBL ENCORE ESSENTIAL-PRETO | F18: 1199 | G18: 1199 | H18: 1199 | I18: 1199 | J18: 1149 | K18: 1149 | L18: 1149 | M18: 1149 | N18: 1149 | O18: 1099 | P18: 1099 | Q18: 999 | R18: 1099 | S18: 999 | T18: 799 | U18: 799 | V18: 799 | W18: 799 | X18: 699 | Y18: 649 | Z18: 649 | AA18: 649 | AM18: 31.12.9999
B19: MUSICA | C19: 4017250 | D19: CAIXA DE SOM JBL ENCORE ESSENTIAL 2 | E19: CAIXA DE SOM JBL ENCORE ESSENTIAL 2-PRET | F19: 1699 | G19: 999 | H19: 1699 | I19: 1699 | J19: 1649 | K19: 1649 | L19: 1649 | M19: 1649 | N19: 1649 | O19: 1599 | P19: 1499 | Q19: 999 | R19: 1599 | S19: 1499 | T19: 999 | U19: 999 | V19: 999 | W19: 999 | X19: 999 | Y19: 899 | Z19: 899 | AA19: 899 | AB19: 1649 | AC19: 1649 | AD19: 1649 | AE19: 1649 | AF19: 1599 | AG19: 1599 | AH19: 1599 | AI19: 999 | AJ19: 999 | AK19: 999 | AL19: 899 | AM19: 31.12.9999
B20: CAIXA DE SOM | C20: 4017581 | D20: CAIXA DE SOM JBL GO ESSENTIAL 2 | E20: CAIXA DE SOM JBL GO ESSENTIAL 2-PRETO | F20: 219 | G20: 219 | H20: 219 | I20: 219 | J20: 149 | K20: 149 | L20: 149 | M20: 149 | N20: 149 | O20: 99 | P20: 99 | Q20: 99 | R20: 99 | S20: 99 | T20: 99 | U20: 99 | V20: 99 | W20: 99 | X20: 99 | Y20: 99 | Z20: 99 | AA20: 99 | AM20: 31.12.9999
B21: MUSICA | C21: 4016351 | D21: CAIXA DE SOM JBL XTREME 4 | E21: CAIXA DE SOM JBL XTREME 4 | F21: 999 | G21: 999 | H21: 999 | I21: 999 | J21: 949 | K21: 949 | L21: 949 | M21: 949 | N21: 949 | O21: 899 | P21: 899 | Q21: 799 | R21: 899 | S21: 799 | T21: 599 | U21: 599 | V21: 599 | W21: 599 | X21: 549 | Y21: 549 | Z21: 549 | AA21: 549 | AM21: 31.12.9999
B22: BASICO | C22: 4016004 | D22: CAPA CLEAR GALAXY S24 | E22: CAPA CLEAR GALAXY S24-TRANSPARENTE | F22: 129 | G22: 129 | AM22: 31.12.9999
B23: BASICO | C23: 4016005 | D23: CAPA CLEAR GALAXY S24 PLUS | E23: CAPA CLEAR GALAXY S24 PLUS-TRANSPARENTE | F23: 129 | G23: 129 | AM23: 31.12.9999
B24: BASICO | C24: 4016006 | D24: CAPA CLEAR GALAXY S24 ULTRA | E24: CAPA CLEAR GALAXY S24 ULTRA-TRANSPARENTE | F24: 129 | G24: 129 | AM24: 31.12.9999
B25: BASICO | C25: 4015729 | D25: CAPA PROTECTIC COVER GALAXY S23 FE | E25: CAPA PROTECTIC COVER GALAXY S23 FE-TRANS | F25: 10 | G25: 10 | AM25: 31.12.9999
B26: BASICO | C26: 4013975 | D26: CARREGADOR APPLE USB-C 20W | E26: CARREGADOR APPLE USB-C 20W-BRANCO | F26: 219 | G26: 219 | AM26: 31.12.9999
B27: CARREGADOR | C27: 4016254 | D27: CARREGADOR APPLE USB-C 20W 2024 | E27: CARREGADOR APPLE USB-C 20W 2024-BRANCO | F27: 219 | G27: 219 | AM27: 31.12.9999
B28: GAMER | C28: 4016340 | D28: CONTROLE SEM FIO PS5 DUALSENSE | E28: CONTROLE SEM FIO PS5 DUALSENSE-BRANCO | F28: 499 | G28: 399 | H28: 499 | I28: 499 | J28: 449 | K28: 449 | L28: 449 | M28: 449 | N28: 449 | O28: 399 | P28: 299 | Q28: 299 | R28: 399 | S28: 299 | T28: 299 | U28: 299 | V28: 299 | W28: 299 | X28: 299 | Y28: 299 | Z28: 299 | AA28: 299 | AB28: 449 | AC28: 449 | AD28: 449 | AE28: 449 | AF28: 399 | AG28: 399 | AH28: 299 | AI28: 299 | AJ28: 299 | AK28: 299 | AL28: 299 | AM28: 31.12.9999
B29: GAMER | C29: 4016494 | D29: CONTROLE SEM FIO PS5 DUALSENSE | E29: CONTROLE SEM FIO PS5 DUALSENSE-PRETO | F29: 499 | G29: 399 | H29: 499 | I29: 499 | J29: 449 | K29: 449 | L29: 449 | M29: 449 | N29: 449 | O29: 399 | P29: 299 | Q29: 299 | R29: 399 | S29: 299 | T29: 299 | U29: 299 | V29: 299 | W29: 299 | X29: 299 | Y29: 299 | Z29: 299 | AA29: 299 | AB29: 449 | AC29: 449 | AD29: 449 | AE29: 449 | AF29: 399 | AG29: 399 | AH29: 299 | AI29: 299 | AJ29: 299 | AK29: 299 | AL29: 299 | AM29: 31.12.9999
B30: GAMER | C30: 4017140 | D30: CONTROLE SEM FIO PS5 DUALSENSE | E30: CONTROLE SEM FIO PS5 DUALSENSE-CAMUFLADO | F30: 499 | G30: 399 | H30: 499 | I30: 499 | J30: 449 | K30: 449 | L30: 449 | M30: 449 | N30: 449 | O30: 399 | P30: 299 | Q30: 299 | R30: 399 | S30: 299 | T30: 299 | U30: 299 | V30: 299 | W30: 299 | X30: 299 | Y30: 299 | Z30: 299 | AA30: 299 | AB30: 449 | AC30: 449 | AD30: 449 | AE30: 449 | AF30: 399 | AG30: 399 | AH30: 299 | AI30: 299 | AJ30: 299 | AK30: 299 | AL30: 299 | AM30: 31.12.9999
B31: GAMER | C31: 4015506 | D31: CONTROLE SEM FIO XBOX SERIES | E31: CONTROLE SEM FIO XBOX SERIES-BRANCO | F31: 299 | G31: 299 | H31: 299 | I31: 299 | J31: 249 | K31: 249 | L31: 249 | M31: 249 | N31: 249 | O31: 199 | P31: 199 | Q31: 199 | R31: 199 | S31: 199 | T31: 199 | U31: 199 | V31: 199 | W31: 199 | X31: 199 | Y31: 199 | Z31: 199 | AA31: 199 | AM31: 31.12.9999
B32: GADGETS | C32: 4015637 | D32: ESTABILIZADOR DJI OSMO MOBILE SE | E32: ESTABILIZADOR DJI OSMO MOBILE SE-CINZA | F32: 999 | G32: 999 | H32: 999 | I32: 999 | J32: 949 | K32: 949 | L32: 949 | M32: 949 | N32: 949 | O32: 899 | P32: 799 | Q32: 599 | R32: 899 | S32: 799 | T32: 599 | U32: 599 | V32: 599 | W32: 599 | X32: 549 | Y32: 549 | Z32: 549 | AA32: 549 | AM32: 31.12.9999
B33: GADGETS | C33: 4015591 | D33: FILME INSTAX MINI 10 FOTOS | E33: FILME INSTAX MINI 10 FOTOS-BRANCO | F33: 49 | G33: 49 | AM33: 31.12.9999
B34: GADGETS | C34: 4015592 | D34: FILME INSTAX MINI 20 FOTOS | E34: FILME INSTAX MINI 20 FOTOS-BRANCO | F34: 89 | G34: 89 | AM34: 31.12.9999
B35: MUSICA | C35: 4013141 | D35: FONE APPLE EARPODS | E35: FONE APPLE EARPODS-BRANCO | F35: 199 | G35: 199 | AM35: 31.12.9999
B36: MUSICA | C36: 4015880 | D36: FONE APPLE EARPODS USBC | E36: FONE APPLE EARPODS USBC-BRANCO | F36: 199 | G36: 199 | AM36: 31.12.9999
B37: MUSICA | C37: 4016971 | D37: FONE APPLE EARPODS USBC 2024 | E37: FONE APPLE EARPODS USBC 2024-BRANCO | F37: 199 | G37: 199 | AM37: 31.12.9999
B38: MUSICA | C38: 4013617 | D38: FONE JBL TUNE 110 | E38: FONE JBL TUNE 110-PRETO | F38: 99 | G38: 99 | AM38: 31.12.9999
B39: MUSICA | C39: 4014261 | D39: FONE JBL TUNE 125BT | E39: FONE JBL TUNE 125BT-PRETO | F39: 149 | G39: 149 | AM39: 31.12.9999
B40: MUSICA | C40: 4015696 | D40: FONE SAMSUNG GALAXY BUDS FE | E40: FONE SAMSUNG GALAXY BUDS FE-GRAFITE | F40: 449 | G40: 449 | H40: 449 | I40: 449 | J40: 399 | K40: 399 | L40: 399 | M40: 399 | N40: 399 | O40: 349 | P40: 249 | Q40: 249 | R40: 349 | S40: 249 | T40: 249 | U40: 249 | V40: 249 | W40: 249 | X40: 249 | Y40: 249 | Z40: 249 | AA40: 249 | AB40: =$H40-70 -> 379 | AC40: =$H40-70 -> 379 | AD40: =$H40-70 -> 379 | AE40: =$H40-100 -> 349 | AF40: =$H40-100 -> 349 | AG40: =$H40-100 -> 349 | AH40: 249 | AI40: =$H40-200 -> 249 | AJ40: =$H40-200 -> 249 | AK40: =$H40-200 -> 249 | AL40: =$H40-200 -> 249 | AM40: 31.12.9999
B41: FONE DE OUVIDO | C41: 4016533 | D41: FONE TWS GALAXY BUDS 3 2024 | E41: FONE TWS GALAXY BUDS 3 2024-BRANCO | F41: 799 | G41: 799 | H41: 799 | I41: 799 | J41: 749 | K41: 749 | L41: 749 | M41: 749 | N41: 749 | O41: 699 | P41: 599 | Q41: 399 | R41: 699 | S41: 599 | T41: 399 | U41: 399 | V41: 399 | W41: 399 | X41: 399 | Y41: 399 | Z41: 399 | AA41: 399 | AM41: 31.12.9999
...

Sheet TRADE IN
A1: OFERTAS VÁLIDAS APENAS PARA PLANOS CONSUMER
B4: Inclusão de Preços
B5: Alteração de Preços
A7: Preços Elegíveis a Price Back
A8: Preços Elegíveis a Price Oferta
A9: CANAL: | B9: REVENDAS
C11: DATA INÍCIO: | D11: =REV!D11 -> 46092 | J11: COM FIDELIZAÇÃO - GROSS / MIGRAÇÃO / UPGRADE / PORTABILIDADE / BASE SEM MOVIMENTAÇÃO | AB11: TIM FIBRA | AM11: TIM FIXO | AP11: TIM CASA
A12: Regra Reembolso Pós Fidelizado | B12: CATEGORIA MKT | C12: CÓDIGO | D12: DESCRIÇÃO COMERCIAL | E12: DESCRIÇÃO SAP | F12: BOOST TRADE IN | G12: PREÇO BASE FATURAMENTO RETAIL | H12: CONTROLE NÃO FIDELIZADO - TODOS (Fatura / Express) | I12: PÓS PAGO NÃO FIDELIZADO - VIDE ABA DE REGRAS | J12: TIM CONTROLE | K12: TIM CONTROLE PLUS | L12: TIM CONTROLE PREMIUM | M12: TIM CONTROLE SMART | N12: TIM CONTROLE REDES SOCIAIS | O12: TIM BLACK | P12: TIM BLACK PLUS | Q12: TIM BLACK PREMIUM | R12: TIM BLACK A (15GB) | S12: TIM BLACK B (20GB) | T12: TIM BLACK C (25GB) | U12: TIM BLACK C ULTRA | V12: TIM BLACK FAMÍLIA | W12: TIM BLACK FAMÍLIA A ONE | X12: TIM BLACK FAMÍLIA PLUS | Y12: TIM BLACK FAMÍLIA PREMIUM | Z12: TIM BLACK FAMÍLIA C ONE | AA12: TIM BLACK FAMÍLIA VIP | AB12: TIM Fibra 300M 24 | AC12: TIM Fibra 400M 24 | AD12: TIM Fibra 500M 24 - 2 | AE12: TIM Fibra 600M 24 - 2 | AF12: TIM Fibra 600M P 24 - 2 | AG12: TIM Fibra 600M M 24 - 2 | AH12: TIM Fibra 600M GP 25 | AI12: TIM Fibra 1GB 24 | AJ12: TIM Fibra 1GB P 24 | AK12: TIM Fibra 1GB M 24 | AL12: TIM Fibra 2GB 24 | AM12: TIM FIXO LOCAL TOTAL PLUS (Plano Fidelizado) | AN12: TIM FIXO BRASIL TOTAL PLUS (Plano Fidelizado) | AO12: TIM FIXO TOTAL LDI PLUS (Plano Fidelizado) | AP12: TIM LIVE INTERNET 30GB (sem fidelização) | AQ12: TIM LIVE INTERNET 50GB (sem fidelização) | AR12: TIM LIVE INTERNET 80GB (sem fidelização) | AS12: TIM LIVE INTERNET 30GB PLUS | AT12: TIM LIVE INTERNET 50GB PLUS | AU12: TIM LIVE INTERNET 80GB PLUS | AW12: DATA FIM DA OFERTA | AX12: TECNOLOGIA
A13: ADM | B13: 21X | C13: 4010990 | D13: Alcatel Pixi 4.5 4G | E13: Alcatel Pixi 4.5 4G-Preto | J13: =IF(VLOOKUP($C13,REV!$C:$AA,8,0)-'TRADE IN'!$F13=0,"",(VLOOKUP($C13,REV!$C:$AA,8,0)-'TRADE IN'!$F13)) -> 479 | K13: =IF(VLOOKUP($C13,REV!$C:$AA,9,0)-'TRADE IN'!$F13=0,"",(VLOOKUP($C13,REV!$C:$AA,9,0)-'TRADE IN'!$F13)) -> 479 | L13: =IF(VLOOKUP($C13,REV!$C:$AA,10,0)-'TRADE IN'!$F22=0,"",(VLOOKUP($C13,REV!$C:$AA,10,0)-'TRADE IN'!$F13)) -> 479 | M13: =IF(VLOOKUP($C13,REV!$C:$AA,11,0)-'TRADE IN'!$F22=0,"",(VLOOKUP($C13,REV!$C:$AA,11,0)-'TRADE IN'!$F13)) -> 479 | N13: =IF(VLOOKUP($C13,REV!$C:$AA,12,0)-'TRADE IN'!$F22=0,"",(VLOOKUP($C13,REV!$C:$AA,12,0)-'TRADE IN'!$F13)) -> 479 | O13: =IF(VLOOKUP($C13,REV!$C:$AA,13,0)-'TRADE IN'!$F22=0,"",(VLOOKUP($C13,REV!$C:$AA,13,0)-'TRADE IN'!$F13)) | P13: =IF(VLOOKUP($C13,REV!$C:$AA,14,0)-'TRADE IN'!$F22=0,"",(VLOOKUP($C13,REV!$C:$AA,14,0)-'TRADE IN'!$F13)) | Q13: =IF(VLOOKUP($C13,REV!$C:$AA,15,0)-'TRADE IN'!$F22=0,"",(VLOOKUP($C13,REV!$C:$AA,15,0)-'TRADE IN'!$F13)) | R13: =IF(VLOOKUP($C13,REV!$C:$AA,16,0)-'TRADE IN'!$F22=0,"",(VLOOKUP($C13,REV!$C:$AA,16,0)-'TRADE IN'!$F13)) | S13: =IF(VLOOKUP($C13,REV!$C:$AA,17,0)-'TRADE IN'!$F22=0,"",(VLOOKUP($C13,REV!$C:$AA,17,0)-'TRADE IN'!$F13)) | T13: =IF(VLOOKUP($C13,REV!$C:$AA,18,0)-'TRADE IN'!$F22=0,"",(VLOOKUP($C13,REV!$C:$AA,18,0)-'TRADE IN'!$F13)) | U13: =IF(VLOOKUP($C13,REV!$C:$AA,19,0)-'TRADE IN'!$F22=0,"",(VLOOKUP($C13,REV!$C:$AA,19,0)-'TRADE IN'!$F13)) | V13: =IF(VLOOKUP($C13,REV!$C:$AA,20,0)-'TRADE IN'!$F22=0,"",(VLOOKUP($C13,REV!$C:$AA,20,0)-'TRADE IN'!$F13)) | W13: =IF(VLOOKUP($C13,REV!$C:$AA,21,0)-'TRADE IN'!$F22=0,"",(VLOOKUP($C13,REV!$C:$AA,21,0)-'TRADE IN'!$F13)) | X13: =IF(VLOOKUP($C13,REV!$C:$AA,22,0)-'TRADE IN'!$F22=0,"",(VLOOKUP($C13,REV!$C:$AA,22,0)-'TRADE IN'!$F13)) | Y13: =IF(VLOOKUP($C13,REV!$C:$AA,23,0)-'TRADE IN'!$F22=0,"",(VLOOKUP($C13,REV!$C:$AA,23,0)-'TRADE IN'!$F13)) | Z13: =IF(VLOOKUP($C13,REV!$C:$AA,24,0)-'TRADE IN'!$F22=0,"",(VLOOKUP($C13,REV!$C:$AA,24,0)-'TRADE IN'!$F13)) | AA13: =IF(VLOOKUP($C13,REV!$C:$AA,25,0)-'TRADE IN'!$F22=0,"",(VLOOKUP($C13,REV!$C:$AA,25,0)-'TRADE IN'!$F13)) | AW13: =IF(REV!AW13=0,"",REV!AW13) -> 31.03.2026 | AX13: 4G
A14: ADM | B14: 21X | C14: 4010991 | D14: Alcatel Pixi 4.5 4G | E14: Alcatel Pixi 4.5 4G-Branco | J14: =IF(VLOOKUP($C14,REV!$C:$AA,8,0)-'TRADE IN'!$F14=0,"",(VLOOKUP($C14,REV!$C:$AA,8,0)-'TRADE IN'!$F14)) -> 479 | K14: =IF(VLOOKUP($C14,REV!$C:$AA,9,0)-'TRADE IN'!$F14=0,"",(VLOOKUP($C14,REV!$C:$AA,9,0)-'TRADE IN'!$F14)) -> 479 | L14: =IF(VLOOKUP($C14,REV!$C:$AA,10,0)-'TRADE IN'!$F23=0,"",(VLOOKUP($C14,REV!$C:$AA,10,0)-'TRADE IN'!$F14)) -> 479 | M14: =IF(VLOOKUP($C14,REV!$C:$AA,11,0)-'TRADE IN'!$F23=0,"",(VLOOKUP($C14,REV!$C:$AA,11,0)-'TRADE IN'!$F14)) -> 479 | N14: =IF(VLOOKUP($C14,REV!$C:$AA,12,0)-'TRADE IN'!$F23=0,"",(VLOOKUP($C14,REV!$C:$AA,12,0)-'TRADE IN'!$F14)) -> 479 | O14: =IF(VLOOKUP($C14,REV!$C:$AA,13,0)-'TRADE IN'!$F23=0,"",(VLOOKUP($C14,REV!$C:$AA,13,0)-'TRADE IN'!$F14)) | P14: =IF(VLOOKUP($C14,REV!$C:$AA,14,0)-'TRADE IN'!$F23=0,"",(VLOOKUP($C14,REV!$C:$AA,14,0)-'TRADE IN'!$F14)) | Q14: =IF(VLOOKUP($C14,REV!$C:$AA,15,0)-'TRADE IN'!$F23=0,"",(VLOOKUP($C14,REV!$C:$AA,15,0)-'TRADE IN'!$F14)) | R14: =IF(VLOOKUP($C14,REV!$C:$AA,16,0)-'TRADE IN'!$F23=0,"",(VLOOKUP($C14,REV!$C:$AA,16,0)-'TRADE IN'!$F14)) | S14: =IF(VLOOKUP($C14,REV!$C:$AA,17,0)-'TRADE IN'!$F23=0,"",(VLOOKUP($C14,REV!$C:$AA,17,0)-'TRADE IN'!$F14)) | T14: =IF(VLOOKUP($C14,REV!$C:$AA,18,0)-'TRADE IN'!$F23=0,"",(VLOOKUP($C14,REV!$C:$AA,18,0)-'TRADE IN'!$F14)) | U14: =IF(VLOOKUP($C14,REV!$C:$AA,19,0)-'TRADE IN'!$F23=0,"",(VLOOKUP($C14,REV!$C:$AA,19,0)-'TRADE IN'!$F14)) | V14: =IF(VLOOKUP($C14,REV!$C:$AA,20,0)-'TRADE IN'!$F23=0,"",(VLOOKUP($C14,REV!$C:$AA,20,0)-'TRADE IN'!$F14)) | W14: =IF(VLOOKUP($C14,REV!$C:$AA,21,0)-'TRADE IN'!$F23=0,"",(VLOOKUP($C14,REV!$C:$AA,21,0)-'TRADE IN'!$F14)) | X14: =IF(VLOOKUP($C14,REV!$C:$AA,22,0)-'TRADE IN'!$F23=0,"",(VLOOKUP($C14,REV!$C:$AA,22,0)-'TRADE IN'!$F14)) | Y14: =IF(VLOOKUP($C14,REV!$C:$AA,23,0)-'TRADE IN'!$F23=0,"",(VLOOKUP($C14,REV!$C:$AA,23,0)-'TRADE IN'!$F14)) | Z14: =IF(VLOOKUP($C14,REV!$C:$AA,24,0)-'TRADE IN'!$F23=0,"",(VLOOKUP($C14,REV!$C:$AA,24,0)-'TRADE IN'!$F14)) | AA14: =IF(VLOOKUP($C14,REV!$C:$AA,25,0)-'TRADE IN'!$F23=0,"",(VLOOKUP($C14,REV!$C:$AA,25,0)-'TRADE IN'!$F14)) | AW14: =IF(REV!AW14=0,"",REV!AW14) -> 31.03.2026 | AX14: 4G
A15: ADM | B15: 21X | C15: 4011353 | D15: Alcatel Pixi 4.5 4G | E15: Alcatel Pixi 4.5 4G-Preto AM | J15: =IF(VLOOKUP($C15,REV!$C:$AA,8,0)-'TRADE IN'!$F15=0,"",(VLOOKUP($C15,REV!$C:$AA,8,0)-'TRADE IN'!$F15)) -> 479 | K15: =IF(VLOOKUP($C15,REV!$C:$AA,9,0)-'TRADE IN'!$F15=0,"",(VLOOKUP($C15,REV!$C:$AA,9,0)-'TRADE IN'!$F15)) -> 479 | L15: =IF(VLOOKUP($C15,REV!$C:$AA,10,0)-'TRADE IN'!$F24=0,"",(VLOOKUP($C15,REV!$C:$AA,10,0)-'TRADE IN'!$F15)) -> 479 | M15: =IF(VLOOKUP($C15,REV!$C:$AA,11,0)-'TRADE IN'!$F24=0,"",(VLOOKUP($C15,REV!$C:$AA,11,0)-'TRADE IN'!$F15)) -> 479 | N15: =IF(VLOOKUP($C15,REV!$C:$AA,12,0)-'TRADE IN'!$F24=0,"",(VLOOKUP($C15,REV!$C:$AA,12,0)-'TRADE IN'!$F15)) -> 479 | O15: =IF(VLOOKUP($C15,REV!$C:$AA,13,0)-'TRADE IN'!$F24=0,"",(VLOOKUP($C15,REV!$C:$AA,13,0)-'TRADE IN'!$F15)) | P15: =IF(VLOOKUP($C15,REV!$C:$AA,14,0)-'TRADE IN'!$F24=0,"",(VLOOKUP($C15,REV!$C:$AA,14,0)-'TRADE IN'!$F15)) | Q15: =IF(VLOOKUP($C15,REV!$C:$AA,15,0)-'TRADE IN'!$F24=0,"",(VLOOKUP($C15,REV!$C:$AA,15,0)-'TRADE IN'!$F15)) | R15: =IF(VLOOKUP($C15,REV!$C:$AA,16,0)-'TRADE IN'!$F24=0,"",(VLOOKUP($C15,REV!$C:$AA,16,0)-'TRADE IN'!$F15)) | S15: =IF(VLOOKUP($C15,REV!$C:$AA,17,0)-'TRADE IN'!$F24=0,"",(VLOOKUP($C15,REV!$C:$AA,17,0)-'TRADE IN'!$F15)) | T15: =IF(VLOOKUP($C15,REV!$C:$AA,18,0)-'TRADE IN'!$F24=0,"",(VLOOKUP($C15,REV!$C:$AA,18,0)-'TRADE IN'!$F15)) | U15: =IF(VLOOKUP($C15,REV!$C:$AA,19,0)-'TRADE IN'!$F24=0,"",(VLOOKUP($C15,REV!$C:$AA,19,0)-'TRADE IN'!$F15)) | V15: =IF(VLOOKUP($C15,REV!$C:$AA,20,0)-'TRADE IN'!$F24=0,"",(VLOOKUP($C15,REV!$C:$AA,20,0)-'TRADE IN'!$F15)) | W15: =IF(VLOOKUP($C15,REV!$C:$AA,21,0)-'TRADE IN'!$F24=0,"",(VLOOKUP($C15,REV!$C:$AA,21,0)-'TRADE IN'!$F15)) | X15: =IF(VLOOKUP($C15,REV!$C:$AA,22,0)-'TRADE IN'!$F24=0,"",(VLOOKUP($C15,REV!$C:$AA,22,0)-'TRADE IN'!$F15)) | Y15: =IF(VLOOKUP($C15,REV!$C:$AA,23,0)-'TRADE IN'!$F24=0,"",(VLOOKUP($C15,REV!$C:$AA,23,0)-'TRADE IN'!$F15)) | Z15: =IF(VLOOKUP($C15,REV!$C:$AA,24,0)-'TRADE IN'!$F24=0,"",(VLOOKUP($C15,REV!$C:$AA,24,0)-'TRADE IN'!$F15)) | AA15: =IF(VLOOKUP($C15,REV!$C:$AA,25,0)-'TRADE IN'!$F24=0,"",(VLOOKUP($C15,REV!$C:$AA,25,0)-'TRADE IN'!$F15)) | AW15: =IF(REV!AW15=0,"",REV!AW15) -> 31.03.2026 | AX15: 4G
A16: ADM | B16: 21X | C16: 4011354 | D16: Alcatel Pixi 4.5 4G | E16: Alcatel Pixi 4.5 4G-Branco AM | J16: =IF(VLOOKUP($C16,REV!$C:$AA,8,0)-'TRADE IN'!$F16=0,"",(VLOOKUP($C16,REV!$C:$AA,8,0)-'TRADE IN'!$F16)) -> 479 | K16: =IF(VLOOKUP($C16,REV!$C:$AA,9,0)-'TRADE IN'!$F16=0,"",(VLOOKUP($C16,REV!$C:$AA,9,0)-'TRADE IN'!$F16)) -> 479 | L16: =IF(VLOOKUP($C16,REV!$C:$AA,10,0)-'TRADE IN'!$F25=0,"",(VLOOKUP($C16,REV!$C:$AA,10,0)-'TRADE IN'!$F16)) -> 479 | M16: =IF(VLOOKUP($C16,REV!$C:$AA,11,0)-'TRADE IN'!$F25=0,"",(VLOOKUP($C16,REV!$C:$AA,11,0)-'TRADE IN'!$F16)) -> 479 | N16: =IF(VLOOKUP($C16,REV!$C:$AA,12,0)-'TRADE IN'!$F25=0,"",(VLOOKUP($C16,REV!$C:$AA,12,0)-'TRADE IN'!$F16)) -> 479 | O16: =IF(VLOOKUP($C16,REV!$C:$AA,13,0)-'TRADE IN'!$F25=0,"",(VLOOKUP($C16,REV!$C:$AA,13,0)-'TRADE IN'!$F16)) | P16: =IF(VLOOKUP($C16,REV!$C:$AA,14,0)-'TRADE IN'!$F25=0,"",(VLOOKUP($C16,REV!$C:$AA,14,0)-'TRADE IN'!$F16)) | Q16: =IF(VLOOKUP($C16,REV!$C:$AA,15,0)-'TRADE IN'!$F25=0,"",(VLOOKUP($C16,REV!$C:$AA,15,0)-'TRADE IN'!$F16)) | R16: =IF(VLOOKUP($C16,REV!$C:$AA,16,0)-'TRADE IN'!$F25=0,"",(VLOOKUP($C16,REV!$C:$AA,16,0)-'TRADE IN'!$F16)) | S16: =IF(VLOOKUP($C16,REV!$C:$AA,17,0)-'TRADE IN'!$F25=0,"",(VLOOKUP($C16,REV!$C:$AA,17,0)-'TRADE IN'!$F16)) | T16: =IF(VLOOKUP($C16,REV!$C:$AA,18,0)-'TRADE IN'!$F25=0,"",(VLOOKUP($C16,REV!$C:$AA,18,0)-'TRADE IN'!$F16)) | U16: =IF(VLOOKUP($C16,REV!$C:$AA,19,0)-'TRADE IN'!$F25=0,"",(VLOOKUP($C16,REV!$C:$AA,19,0)-'TRADE IN'!$F16)) | V16: =IF(VLOOKUP($C16,REV!$C:$AA,20,0)-'TRADE IN'!$F25=0,"",(VLOOKUP($C16,REV!$C:$AA,20,0)-'TRADE IN'!$F16)) | W16: =IF(VLOOKUP($C16,REV!$C:$AA,21,0)-'TRADE IN'!$F25=0,"",(VLOOKUP($C16,REV!$C:$AA,21,0)-'TRADE IN'!$F16)) | X16: =IF(VLOOKUP($C16,REV!$C:$AA,22,0)-'TRADE IN'!$F25=0,"",(VLOOKUP($C16,REV!$C:$AA,22,0)-'TRADE IN'!$F16)) | Y16: =IF(VLOOKUP($C16,REV!$C:$AA,23,0)-'TRADE IN'!$F25=0,"",(VLOOKUP($C16,REV!$C:$AA,23,0)-'TRADE IN'!$F16)) | Z16: =IF(VLOOKUP($C16,REV!$C:$AA,24,0)-'TRADE IN'!$F25=0,"",(VLOOKUP($C16,REV!$C:$AA,24,0)-'TRADE IN'!$F16)) | AA16: =IF(VLOOKUP($C16,REV!$C:$AA,25,0)-'TRADE IN'!$F25=0,"",(VLOOKUP($C16,REV!$C:$AA,25,0)-'TRADE IN'!$F16)) | AW16: =IF(REV!AW16=0,"",REV!AW16) -> 31.03.2026 | AX16: 4G
A17: Price Oferta | B17: 21X | C17: 4013660 | D17: APPLE IPHONE SE 64GB 2GER | E17: APPLE IPHONE SE 64GB 2GER-PRETO | J17: =IF(VLOOKUP($C17,REV!$C:$AA,8,0)-'TRADE IN'!$F17=0,"",(VLOOKUP($C17,REV!$C:$AA,8,0)-'TRADE IN'!$F17)) -> 799 | K17: =IF(VLOOKUP($C17,REV!$C:$AA,9,0)-'TRADE IN'!$F17=0,"",(VLOOKUP($C17,REV!$C:$AA,9,0)-'TRADE IN'!$F17)) -> 699 | L17: =IF(VLOOKUP($C17,REV!$C:$AA,10,0)-'TRADE IN'!$F26=0,"",(VLOOKUP($C17,REV!$C:$AA,10,0)-'TRADE IN'!$F17)) -> 699 | M17: =IF(VLOOKUP($C17,REV!$C:$AA,11,0)-'TRADE IN'!$F26=0,"",(VLOOKUP($C17,REV!$C:$AA,11,0)-'TRADE IN'!$F17)) -> 799 | N17: =IF(VLOOKUP($C17,REV!$C:$AA,12,0)-'TRADE IN'!$F26=0,"",(VLOOKUP($C17,REV!$C:$AA,12,0)-'TRADE IN'!$F17)) -> 799 | O17: =IF(VLOOKUP($C17,REV!$C:$AA,13,0)-'TRADE IN'!$F26=0,"",(VLOOKUP($C17,REV!$C:$AA,13,0)-'TRADE IN'!$F17)) -> 599 | P17: =IF(VLOOKUP($C17,REV!$C:$AA,14,0)-'TRADE IN'!$F26=0,"",(VLOOKUP($C17,REV!$C:$AA,14,0)-'TRADE IN'!$F17)) -> 599 | Q17: =IF(VLOOKUP($C17,REV!$C:$AA,15,0)-'TRADE IN'!$F26=0,"",(VLOOKUP($C17,REV!$C:$AA,15,0)-'TRADE IN'!$F17)) -> 599 | R17: =IF(VLOOKUP($C17,REV!$C:$AA,16,0)-'TRADE IN'!$F26=0,"",(VLOOKUP($C17,REV!$C:$AA,16,0)-'TRADE IN'!$F17)) -> 599 | S17: =IF(VLOOKUP($C17,REV!$C:$AA,17,0)-'TRADE IN'!$F26=0,"",(VLOOKUP($C17,REV!$C:$AA,17,0)-'TRADE IN'!$F17)) -> 599 | T17: =IF(VLOOKUP($C17,REV!$C:$AA,18,0)-'TRADE IN'!$F26=0,"",(VLOOKUP($C17,REV!$C:$AA,18,0)-'TRADE IN'!$F17)) -> 599 | U17: =IF(VLOOKUP($C17,REV!$C:$AA,19,0)-'TRADE IN'!$F26=0,"",(VLOOKUP($C17,REV!$C:$AA,19,0)-'TRADE IN'!$F17)) -> 599 | V17: =IF(VLOOKUP($C17,REV!$C:$AA,20,0)-'TRADE IN'!$F26=0,"",(VLOOKUP($C17,REV!$C:$AA,20,0)-'TRADE IN'!$F17)) -> 599 | W17: =IF(VLOOKUP($C17,REV!$C:$AA,21,0)-'TRADE IN'!$F26=0,"",(VLOOKUP($C17,REV!$C:$AA,21,0)-'TRADE IN'!$F17)) -> 599 | X17: =IF(VLOOKUP($C17,REV!$C:$AA,22,0)-'TRADE IN'!$F26=0,"",(VLOOKUP($C17,REV!$C:$AA,22,0)-'TRADE IN'!$F17)) -> 549 | Y17: =IF(VLOOKUP($C17,REV!$C:$AA,23,0)-'TRADE IN'!$F26=0,"",(VLOOKUP($C17,REV!$C:$AA,23,0)-'TRADE IN'!$F17)) -> 549 | Z17: =IF(VLOOKUP($C17,REV!$C:$AA,24,0)-'TRADE IN'!$F26=0,"",(VLOOKUP($C17,REV!$C:$AA,24,0)-'TRADE IN'!$F17)) -> 549 | AA17: =IF(VLOOKUP($C17,REV!$C:$AA,25,0)-'TRADE IN'!$F26=0,"",(VLOOKUP($C17,REV!$C:$AA,25,0)-'TRADE IN'!$F17)) -> 549 | AW17: =IF(REV!AW17=0,"",REV!AW17) -> 31.03.2026 | AX17: 4G
A18: Price Oferta | B18: 21X | C18: 4013661 | D18: APPLE IPHONE SE 64GB 2GER | E18: Apple iPhone SE 64GB 2Ger-Branco | J18: =IF(VLOOKUP($C18,REV!$C:$AA,8,0)-'TRADE IN'!$F18=0,"",(VLOOKUP($C18,REV!$C:$AA,8,0)-'TRADE IN'!$F18)) -> 799 | K18: =IF(VLOOKUP($C18,REV!$C:$AA,9,0)-'TRADE IN'!$F18=0,"",(VLOOKUP($C18,REV!$C:$AA,9,0)-'TRADE IN'!$F18)) -> 699 | L18: =IF(VLOOKUP($C18,REV!$C:$AA,10,0)-'TRADE IN'!$F27=0,"",(VLOOKUP($C18,REV!$C:$AA,10,0)-'TRADE IN'!$F18)) -> 699 | M18: =IF(VLOOKUP($C18,REV!$C:$AA,11,0)-'TRADE IN'!$F27=0,"",(VLOOKUP($C18,REV!$C:$AA,11,0)-'TRADE IN'!$F18)) -> 799 | N18: =IF(VLOOKUP($C18,REV!$C:$AA,12,0)-'TRADE IN'!$F27=0,"",(VLOOKUP($C18,REV!$C:$AA,12,0)-'TRADE IN'!$F18)) -> 799 | O18: =IF(VLOOKUP($C18,REV!$C:$AA,13,0)-'TRADE IN'!$F27=0,"",(VLOOKUP($C18,REV!$C:$AA,13,0)-'TRADE IN'!$F18)) -> 599 | P18: =IF(VLOOKUP($C18,REV!$C:$AA,14,0)-'TRADE IN'!$F27=0,"",(VLOOKUP($C18,REV!$C:$AA,14,0)-'TRADE IN'!$F18)) -> 599 | Q18: =IF(VLOOKUP($C18,REV!$C:$AA,15,0)-'TRADE IN'!$F27=0,"",(VLOOKUP($C18,REV!$C:$AA,15,0)-'TRADE IN'!$F18)) -> 599 | R18: =IF(VLOOKUP($C18,REV!$C:$AA,16,0)-'TRADE IN'!$F27=0,"",(VLOOKUP($C18,REV!$C:$AA,16,0)-'TRADE IN'!$F18)) -> 599 | S18: =IF(VLOOKUP($C18,REV!$C:$AA,17,0)-'TRADE IN'!$F27=0,"",(VLOOKUP($C18,REV!$C:$AA,17,0)-'TRADE IN'!$F18)) -> 599 | T18: =IF(VLOOKUP($C18,REV!$C:$AA,18,0)-'TRADE IN'!$F27=0,"",(VLOOKUP($C18,REV!$C:$AA,18,0)-'TRADE IN'!$F18)) -> 599 | U18: =IF(VLOOKUP($C18,REV!$C:$AA,19,0)-'TRADE IN'!$F27=0,"",(VLOOKUP($C18,REV!$C:$AA,19,0)-'TRADE IN'!$F18)) -> 599 | V18: =IF(VLOOKUP($C18,REV!$C:$AA,20,0)-'TRADE IN'!$F27=0,"",(VLOOKUP($C18,REV!$C:$AA,20,0)-'TRADE IN'!$F18)) -> 599 | W18: =IF(VLOOKUP($C18,REV!$C:$AA,21,0)-'TRADE IN'!$F27=0,"",(VLOOKUP($C18,REV!$C:$AA,21,0)-'TRADE IN'!$F18)) -> 599 | X18: =IF(VLOOKUP($C18,REV!$C:$AA,22,0)-'TRADE IN'!$F27=0,"",(VLOOKUP($C18,REV!$C:$AA,22,0)-'TRADE IN'!$F18)) -> 549 | Y18: =IF(VLOOKUP($C18,REV!$C:$AA,23,0)-'TRADE IN'!$F27=0,"",(VLOOKUP($C18,REV!$C:$AA,23,0)-'TRADE IN'!$F18)) -> 549 | Z18: =IF(VLOOKUP($C18,REV!$C:$AA,24,0)-'TRADE IN'!$F27=0,"",(VLOOKUP($C18,REV!$C:$AA,24,0)-'TRADE IN'!$F18)) -> 549 | AA18: =IF(VLOOKUP($C18,REV!$C:$AA,25,0)-'TRADE IN'!$F27=0,"",(VLOOKUP($C18,REV!$C:$AA,25,0)-'TRADE IN'!$F18)) -> 549 | AW18: =IF(REV!AW18=0,"",REV!AW18) -> 31.03.2026 | AX18: 4G
A19: Price Oferta | B19: 21X | C19: 4013662 | D19: APPLE IPHONE SE 64GB 2GER | E19: Apple iPhone SE 64GB 2Ger-Vermelho | J19: =IF(VLOOKUP($C19,REV!$C:$AA,8,0)-'TRADE IN'!$F19=0,"",(VLOOKUP($C19,REV!$C:$AA,8,0)-'TRADE IN'!$F19)) -> 799 | K19: =IF(VLOOKUP($C19,REV!$C:$AA,9,0)-'TRADE IN'!$F19=0,"",(VLOOKUP($C19,REV!$C:$AA,9,0)-'TRADE IN'!$F19)) -> 699 | L19: =IF(VLOOKUP($C19,REV!$C:$AA,10,0)-'TRADE IN'!$F28=0,"",(VLOOKUP($C19,REV!$C:$AA,10,0)-'TRADE IN'!$F19)) -> 699 | M19: =IF(VLOOKUP($C19,REV!$C:$AA,11,0)-'TRADE IN'!$F28=0,"",(VLOOKUP($C19,REV!$C:$AA,11,0)-'TRADE IN'!$F19)) -> 799 | N19: =IF(VLOOKUP($C19,REV!$C:$AA,12,0)-'TRADE IN'!$F28=0,"",(VLOOKUP($C19,REV!$C:$AA,12,0)-'TRADE IN'!$F19)) -> 799 | O19: =IF(VLOOKUP($C19,REV!$C:$AA,13,0)-'TRADE IN'!$F28=0,"",(VLOOKUP($C19,REV!$C:$AA,13,0)-'TRADE IN'!$F19)) -> 599 | P19: =IF(VLOOKUP($C19,REV!$C:$AA,14,0)-'TRADE IN'!$F28=0,"",(VLOOKUP($C19,REV!$C:$AA,14,0)-'TRADE IN'!$F19)) -> 599 | Q19: =IF(VLOOKUP($C19,REV!$C:$AA,15,0)-'TRADE IN'!$F28=0,"",(VLOOKUP($C19,REV!$C:$AA,15,0)-'TRADE IN'!$F19)) -> 599 | R19: =IF(VLOOKUP($C19,REV!$C:$AA,16,0)-'TRADE IN'!$F28=0,"",(VLOOKUP($C19,REV!$C:$AA,16,0)-'TRADE IN'!$F19)) -> 599 | S19: =IF(VLOOKUP($C19,REV!$C:$AA,17,0)-'TRADE IN'!$F28=0,"",(VLOOKUP($C19,REV!$C:$AA,17,0)-'TRADE IN'!$F19)) -> 599 | T19: =IF(VLOOKUP($C19,REV!$C:$AA,18,0)-'TRADE IN'!$F28=0,"",(VLOOKUP($C19,REV!$C:$AA,18,0)-'TRADE IN'!$F19)) -> 599 | U19: =IF(VLOOKUP($C19,REV!$C:$AA,19,0)-'TRADE IN'!$F28=0,"",(VLOOKUP($C19,REV!$C:$AA,19,0)-'TRADE IN'!$F19)) -> 599 | V19: =IF(VLOOKUP($C19,REV!$C:$AA,20,0)-'TRADE IN'!$F28=0,"",(VLOOKUP($C19,REV!$C:$AA,20,0)-'TRADE IN'!$F19)) -> 599 | W19: =IF(VLOOKUP($C19,REV!$C:$AA,21,0)-'TRADE IN'!$F28=0,"",(VLOOKUP($C19,REV!$C:$AA,21,0)-'TRADE IN'!$F19)) -> 599 | X19: =IF(VLOOKUP($C19,REV!$C:$AA,22,0)-'TRADE IN'!$F28=0,"",(VLOOKUP($C19,REV!$C:$AA,22,0)-'TRADE IN'!$F19)) -> 549 | Y19: =IF(VLOOKUP($C19,REV!$C:$AA,23,0)-'TRADE IN'!$F28=0,"",(VLOOKUP($C19,REV!$C:$AA,23,0)-'TRADE IN'!$F19)) -> 549 | Z19: =IF(VLOOKUP($C19,REV!$C:$AA,24,0)-'TRADE IN'!$F28=0,"",(VLOOKUP($C19,REV!$C:$AA,24,0)-'TRADE IN'!$F19)) -> 549 | AA19: =IF(VLOOKUP($C19,REV!$C:$AA,25,0)-'TRADE IN'!$F28=0,"",(VLOOKUP($C19,REV!$C:$AA,25,0)-'TRADE IN'!$F19)) -> 549 | AW19: =IF(REV!AW19=0,"",REV!AW19) -> 31.03.2026 | AX19: 4G
A20: Price Oferta | B20: 21X | C20: 4013981 | D20: APPLE IPHONE SE 64GB 2GER | E20: APPLE IPHONE SE 64GB 2GE-PRETO NAC | J20: =IF(VLOOKUP($C20,REV!$C:$AA,8,0)-'TRADE IN'!$F20=0,"",(VLOOKUP($C20,REV!$C:$AA,8,0)-'TRADE IN'!$F20)) -> 799 | K20: =IF(VLOOKUP($C20,REV!$C:$AA,9,0)-'TRADE IN'!$F20=0,"",(VLOOKUP($C20,REV!$C:$AA,9,0)-'TRADE IN'!$F20)) -> 699 | L20: =IF(VLOOKUP($C20,REV!$C:$AA,10,0)-'TRADE IN'!$F29=0,"",(VLOOKUP($C20,REV!$C:$AA,10,0)-'TRADE IN'!$F20)) -> 699 | M20: =IF(VLOOKUP($C20,REV!$C:$AA,11,0)-'TRADE IN'!$F29=0,"",(VLOOKUP($C20,REV!$C:$AA,11,0)-'TRADE IN'!$F20)) -> 799 | N20: =IF(VLOOKUP($C20,REV!$C:$AA,12,0)-'TRADE IN'!$F29=0,"",(VLOOKUP($C20,REV!$C:$AA,12,0)-'TRADE IN'!$F20)) -> 799 | O20: =IF(VLOOKUP($C20,REV!$C:$AA,13,0)-'TRADE IN'!$F29=0,"",(VLOOKUP($C20,REV!$C:$AA,13,0)-'TRADE IN'!$F20)) -> 599 | P20: =IF(VLOOKUP($C20,REV!$C:$AA,14,0)-'TRADE IN'!$F29=0,"",(VLOOKUP($C20,REV!$C:$AA,14,0)-'TRADE IN'!$F20)) -> 599 | Q20: =IF(VLOOKUP($C20,REV!$C:$AA,15,0)-'TRADE IN'!$F29=0,"",(VLOOKUP($C20,REV!$C:$AA,15,0)-'TRADE IN'!$F20)) -> 599 | R20: =IF(VLOOKUP($C20,REV!$C:$AA,16,0)-'TRADE IN'!$F29=0,"",(VLOOKUP($C20,REV!$C:$AA,16,0)-'TRADE IN'!$F20)) -> 599 | S20: =IF(VLOOKUP($C20,REV!$C:$AA,17,0)-'TRADE IN'!$F29=0,"",(VLOOKUP($C20,REV!$C:$AA,17,0)-'TRADE IN'!$F20)) -> 599 | T20: =IF(VLOOKUP($C20,REV!$C:$AA,18,0)-'TRADE IN'!$F29=0,"",(VLOOKUP($C20,REV!$C:$AA,18,0)-'TRADE IN'!$F20)) -> 599 | U20: =IF(VLOOKUP($C20,REV!$C:$AA,19,0)-'TRADE IN'!$F29=0,"",(VLOOKUP($C20,REV!$C:$AA,19,0)-'TRADE IN'!$F20)) -> 599 | V20: =IF(VLOOKUP($C20,REV!$C:$AA,20,0)-'TRADE IN'!$F29=0,"",(VLOOKUP($C20,REV!$C:$AA,20,0)-'TRADE IN'!$F20)) -> 599 | W20: =IF(VLOOKUP($C20,REV!$C:$AA,21,0)-'TRADE IN'!$F29=0,"",(VLOOKUP($C20,REV!$C:$AA,21,0)-'TRADE IN'!$F20)) -> 599 | X20: =IF(VLOOKUP($C20,REV!$C:$AA,22,0)-'TRADE IN'!$F29=0,"",(VLOOKUP($C20,REV!$C:$AA,22,0)-'TRADE IN'!$F20)) -> 549 | Y20: =IF(VLOOKUP($C20,REV!$C:$AA,23,0)-'TRADE IN'!$F29=0,"",(VLOOKUP($C20,REV!$C:$AA,23,0)-'TRADE IN'!$F20)) -> 549 | Z20: =IF(VLOOKUP($C20,REV!$C:$AA,24,0)-'TRADE IN'!$F29=0,"",(VLOOKUP($C20,REV!$C:$AA,24,0)-'TRADE IN'!$F20)) -> 549 | AA20: =IF(VLOOKUP($C20,REV!$C:$AA,25,0)-'TRADE IN'!$F29=0,"",(VLOOKUP($C20,REV!$C:$AA,25,0)-'TRADE IN'!$F20)) -> 549 | AW20: =IF(REV!AW20=0,"",REV!AW20) -> 31.03.2026 | AX20: 4G
A21: Price Oferta | B21: 21X | C21: 4013984 | D21: APPLE IPHONE SE 64GB 2GER | E21: APPLE IPHONE SE 64GB 2GE-BRANCO NAC | J21: =IF(VLOOKUP($C21,REV!$C:$AA,8,0)-'TRADE IN'!$F21=0,"",(VLOOKUP($C21,REV!$C:$AA,8,0)-'TRADE IN'!$F21)) -> 799 | K21: =IF(VLOOKUP($C21,REV!$C:$AA,9,0)-'TRADE IN'!$F21=0,"",(VLOOKUP($C21,REV!$C:$AA,9,0)-'TRADE IN'!$F21)) -> 699 | L21: =IF(VLOOKUP($C21,REV!$C:$AA,10,0)-'TRADE IN'!$F30=0,"",(VLOOKUP($C21,REV!$C:$AA,10,0)-'TRADE IN'!$F21)) -> 699 | M21: =IF(VLOOKUP($C21,REV!$C:$AA,11,0)-'TRADE IN'!$F30=0,"",(VLOOKUP($C21,REV!$C:$AA,11,0)-'TRADE IN'!$F21)) -> 799 | N21: =IF(VLOOKUP($C21,REV!$C:$AA,12,0)-'TRADE IN'!$F30=0,"",(VLOOKUP($C21,REV!$C:$AA,12,0)-'TRADE IN'!$F21)) -> 799 | O21: =IF(VLOOKUP($C21,REV!$C:$AA,13,0)-'TRADE IN'!$F30=0,"",(VLOOKUP($C21,REV!$C:$AA,13,0)-'TRADE IN'!$F21)) -> 599 | P21: =IF(VLOOKUP($C21,REV!$C:$AA,14,0)-'TRADE IN'!$F30=0,"",(VLOOKUP($C21,REV!$C:$AA,14,0)-'TRADE IN'!$F21)) -> 599 | Q21: =IF(VLOOKUP($C21,REV!$C:$AA,15,0)-'TRADE IN'!$F30=0,"",(VLOOKUP($C21,REV!$C:$AA,15,0)-'TRADE IN'!$F21)) -> 599 | R21: =IF(VLOOKUP($C21,REV!$C:$AA,16,0)-'TRADE IN'!$F30=0,"",(VLOOKUP($C21,REV!$C:$AA,16,0)-'TRADE IN'!$F21)) -> 599 | S21: =IF(VLOOKUP($C21,REV!$C:$AA,17,0)-'TRADE IN'!$F30=0,"",(VLOOKUP($C21,REV!$C:$AA,17,0)-'TRADE IN'!$F21)) -> 599 | T21: =IF(VLOOKUP($C21,REV!$C:$AA,18,0)-'TRADE IN'!$F30=0,"",(VLOOKUP($C21,REV!$C:$AA,18,0)-'TRADE IN'!$F21)) -> 599 | U21: =IF(VLOOKUP($C21,REV!$C:$AA,19,0)-'TRADE IN'!$F30=0,"",(VLOOKUP($C21,REV!$C:$AA,19,0)-'TRADE IN'!$F21)) -> 599 | V21: =IF(VLOOKUP($C21,REV!$C:$AA,20,0)-'TRADE IN'!$F30=0,"",(VLOOKUP($C21,REV!$C:$AA,20,0)-'TRADE IN'!$F21)) -> 599 | W21: =IF(VLOOKUP($C21,REV!$C:$AA,21,0)-'TRADE IN'!$F30=0,"",(VLOOKUP($C21,REV!$C:$AA,21,0)-'TRADE IN'!$F21)) -> 599 | X21: =IF(VLOOKUP($C21,REV!$C:$AA,22,0)-'TRADE IN'!$F30=0,"",(VLOOKUP($C21,REV!$C:$AA,22,0)-'TRADE IN'!$F21)) -> 549 | Y21: =IF(VLOOKUP($C21,REV!$C:$AA,23,0)-'TRADE IN'!$F30=0,"",(VLOOKUP($C21,REV!$C:$AA,23,0)-'TRADE IN'!$F21)) -> 549 | Z21: =IF(VLOOKUP($C21,REV!$C:$AA,24,0)-'TRADE IN'!$F30=0,"",(VLOOKUP($C21,REV!$C:$AA,24,0)-'TRADE IN'!$F21)) -> 549 | AA21: =IF(VLOOKUP($C21,REV!$C:$AA,25,0)-'TRADE IN'!$F30=0,"",(VLOOKUP($C21,REV!$C:$AA,25,0)-'TRADE IN'!$F21)) -> 549 | AW21: =IF(REV!AW21=0,"",REV!AW21) -> 31.03.2026 | AX21: 4G
A22: Price Oferta | B22: 21X | C22: 4013986 | D22: APPLE IPHONE SE 64GB 2GER | E22: APPLE IPHONE SE 64GB 2GE-VERMELHO NAC | J22: =IF(VLOOKUP($C22,REV!$C:$AA,8,0)-'TRADE IN'!$F22=0,"",(VLOOKUP($C22,REV!$C:$AA,8,0)-'TRADE IN'!$F22)) -> 799 | K22: =IF(VLOOKUP($C22,REV!$C:$AA,9,0)-'TRADE IN'!$F22=0,"",(VLOOKUP($C22,REV!$C:$AA,9,0)-'TRADE IN'!$F22)) -> 699 | L22: =IF(VLOOKUP($C22,REV!$C:$AA,10,0)-'TRADE IN'!$F31=0,"",(VLOOKUP($C22,REV!$C:$AA,10,0)-'TRADE IN'!$F22)) -> 699 | M22: =IF(VLOOKUP($C22,REV!$C:$AA,11,0)-'TRADE IN'!$F31=0,"",(VLOOKUP($C22,REV!$C:$AA,11,0)-'TRADE IN'!$F22)) -> 799 | N22: =IF(VLOOKUP($C22,REV!$C:$AA,12,0)-'TRADE IN'!$F31=0,"",(VLOOKUP($C22,REV!$C:$AA,12,0)-'TRADE IN'!$F22)) -> 799 | O22: =IF(VLOOKUP($C22,REV!$C:$AA,13,0)-'TRADE IN'!$F31=0,"",(VLOOKUP($C22,REV!$C:$AA,13,0)-'TRADE IN'!$F22)) -> 599 | P22: =IF(VLOOKUP($C22,REV!$C:$AA,14,0)-'TRADE IN'!$F31=0,"",(VLOOKUP($C22,REV!$C:$AA,14,0)-'TRADE IN'!$F22)) -> 599 | Q22: =IF(VLOOKUP($C22,REV!$C:$AA,15,0)-'TRADE IN'!$F31=0,"",(VLOOKUP($C22,REV!$C:$AA,15,0)-'TRADE IN'!$F22)) -> 599 | R22: =IF(VLOOKUP($C22,REV!$C:$AA,16,0)-'TRADE IN'!$F31=0,"",(VLOOKUP($C22,REV!$C:$AA,16,0)-'TRADE IN'!$F22)) -> 599 | S22: =IF(VLOOKUP($C22,REV!$C:$AA,17,0)-'TRADE IN'!$F31=0,"",(VLOOKUP($C22,REV!$C:$AA,17,0)-'TRADE IN'!$F22)) -> 599 | T22: =IF(VLOOKUP($C22,REV!$C:$AA,18,0)-'TRADE IN'!$F31=0,"",(VLOOKUP($C22,REV!$C:$AA,18,0)-'TRADE IN'!$F22)) -> 599 | U22: =IF(VLOOKUP($C22,REV!$C:$AA,19,0)-'TRADE IN'!$F31=0,"",(VLOOKUP($C22,REV!$C:$AA,19,0)-'TRADE IN'!$F22)) -> 599 | V22: =IF(VLOOKUP($C22,REV!$C:$AA,20,0)-'TRADE IN'!$F31=0,"",(VLOOKUP($C22,REV!$C:$AA,20,0)-'TRADE IN'!$F22)) -> 599 | W22: =IF(VLOOKUP($C22,REV!$C:$AA,21,0)-'TRADE IN'!$F31=0,"",(VLOOKUP($C22,REV!$C:$AA,21,0)-'TRADE IN'!$F22)) -> 599 | X22: =IF(VLOOKUP($C22,REV!$C:$AA,22,0)-'TRADE IN'!$F31=0,"",(VLOOKUP($C22,REV!$C:$AA,22,0)-'TRADE IN'!$F22)) -> 549 | Y22: =IF(VLOOKUP($C22,REV!$C:$AA,23,0)-'TRADE IN'!$F31=0,"",(VLOOKUP($C22,REV!$C:$AA,23,0)-'TRADE IN'!$F22)) -> 549 | Z22: =IF(VLOOKUP($C22,REV!$C:$AA,24,0)-'TRADE IN'!$F31=0,"",(VLOOKUP($C22,REV!$C:$AA,24,0)-'TRADE IN'!$F22)) -> 549 | AA22: =IF(VLOOKUP($C22,REV!$C:$AA,25,0)-'TRADE IN'!$F31=0,"",(VLOOKUP($C22,REV!$C:$AA,25,0)-'TRADE IN'!$F22)) -> 549 | AW22: =IF(REV!AW22=0,"",REV!AW22) -> 31.03.2026 | AX22: 4G
A23: Price Oferta | B23: 21X | C23: 4013852 | D23: APPLE IPHONE SE 64GB 2GER | E23: APPLE IPHONE SE 64GB 2GE-PRETO NAC S.KIT | J23: =IF(VLOOKUP($C23,REV!$C:$AA,8,0)-'TRADE IN'!$F23=0,"",(VLOOKUP($C23,REV!$C:$AA,8,0)-'TRADE IN'!$F23)) -> 799 | K23: =IF(VLOOKUP($C23,REV!$C:$AA,9,0)-'TRADE IN'!$F23=0,"",(VLOOKUP($C23,REV!$C:$AA,9,0)-'TRADE IN'!$F23)) -> 699 | L23: =IF(VLOOKUP($C23,REV!$C:$AA,10,0)-'TRADE IN'!$F32=0,"",(VLOOKUP($C23,REV!$C:$AA,10,0)-'TRADE IN'!$F23)) -> 699 | M23: =IF(VLOOKUP($C23,REV!$C:$AA,11,0)-'TRADE IN'!$F32=0,"",(VLOOKUP($C23,REV!$C:$AA,11,0)-'TRADE IN'!$F23)) -> 799 | N23: =IF(VLOOKUP($C23,REV!$C:$AA,12,0)-'TRADE IN'!$F32=0,"",(VLOOKUP($C23,REV!$C:$AA,12,0)-'TRADE IN'!$F23)) -> 799 | O23: =IF(VLOOKUP($C23,REV!$C:$AA,13,0)-'TRADE IN'!$F32=0,"",(VLOOKUP($C23,REV!$C:$AA,13,0)-'TRADE IN'!$F23)) -> 599 | P23: =IF(VLOOKUP($C23,REV!$C:$AA,14,0)-'TRADE IN'!$F32=0,"",(VLOOKUP($C23,REV!$C:$AA,14,0)-'TRADE IN'!$F23)) -> 599 | Q23: =IF(VLOOKUP($C23,REV!$C:$AA,15,0)-'TRADE IN'!$F32=0,"",(VLOOKUP($C23,REV!$C:$AA,15,0)-'TRADE IN'!$F23)) -> 599 | R23: =IF(VLOOKUP($C23,REV!$C:$AA,16,0)-'TRADE IN'!$F32=0,"",(VLOOKUP($C23,REV!$C:$AA,16,0)-'TRADE IN'!$F23)) -> 599 | S23: =IF(VLOOKUP($C23,REV!$C:$AA,17,0)-'TRADE IN'!$F32=0,"",(VLOOKUP($C23,REV!$C:$AA,17,0)-'TRADE IN'!$F23)) -> 599 | T23: =IF(VLOOKUP($C23,REV!$C:$AA,18,0)-'TRADE IN'!$F32=0,"",(VLOOKUP($C23,REV!$C:$AA,18,0)-'TRADE IN'!$F23)) -> 599 | U23: =IF(VLOOKUP($C23,REV!$C:$AA,19,0)-'TRADE IN'!$F32=0,"",(VLOOKUP($C23,REV!$C:$AA,19,0)-'TRADE IN'!$F23)) -> 599 | V23: =IF(VLOOKUP($C23,REV!$C:$AA,20,0)-'TRADE IN'!$F32=0,"",(VLOOKUP($C23,REV!$C:$AA,20,0)-'TRADE IN'!$F23)) -> 599 | W23: =IF(VLOOKUP($C23,REV!$C:$AA,21,0)-'TRADE IN'!$F32=0,"",(VLOOKUP($C23,REV!$C:$AA,21,0)-'TRADE IN'!$F23)) -> 599 | X23: =IF(VLOOKUP($C23,REV!$C:$AA,22,0)-'TRADE IN'!$F32=0,"",(VLOOKUP($C23,REV!$C:$AA,22,0)-'TRADE IN'!$F23)) -> 549 | Y23: =IF(VLOOKUP($C23,REV!$C:$AA,23,0)-'TRADE IN'!$F32=0,"",(VLOOKUP($C23,REV!$C:$AA,23,0)-'TRADE IN'!$F23)) -> 549 | Z23: =IF(VLOOKUP($C23,REV!$C:$AA,24,0)-'TRADE IN'!$F32=0,"",(VLOOKUP($C23,REV!$C:$AA,24,0)-'TRADE IN'!$F23)) -> 549 | AA23: =IF(VLOOKUP($C23,REV!$C:$AA,25,0)-'TRADE IN'!$F32=0,"",(VLOOKUP($C23,REV!$C:$AA,25,0)-'TRADE IN'!$F23)) -> 549 | AW23: =IF(REV!AW23=0,"",REV!AW23) -> 31.03.2026 | AX23: 4G
A24: Price Oferta | B24: 21X | C24: 4014002 | D24: APPLE IPHONE SE 64GB 2GER | E24: APPLE IPHONE SE 64GB 2GE-BRANC NAC S.KIT | J24: =IF(VLOOKUP($C24,REV!$C:$AA,8,0)-'TRADE IN'!$F24=0,"",(VLOOKUP($C24,REV!$C:$AA,8,0)-'TRADE IN'!$F24)) -> 799 | K24: =IF(VLOOKUP($C24,REV!$C:$AA,9,0)-'TRADE IN'!$F24=0,"",(VLOOKUP($C24,REV!$C:$AA,9,0)-'TRADE IN'!$F24)) -> 699 | L24: =IF(VLOOKUP($C24,REV!$C:$AA,10,0)-'TRADE IN'!$F33=0,"",(VLOOKUP($C24,REV!$C:$AA,10,0)-'TRADE IN'!$F24)) -> 699 | M24: =IF(VLOOKUP($C24,REV!$C:$AA,11,0)-'TRADE IN'!$F33=0,"",(VLOOKUP($C24,REV!$C:$AA,11,0)-'TRADE IN'!$F24)) -> 799 | N24: =IF(VLOOKUP($C24,REV!$C:$AA,12,0)-'TRADE IN'!$F33=0,"",(VLOOKUP($C24,REV!$C:$AA,12,0)-'TRADE IN'!$F24)) -> 799 | O24: =IF(VLOOKUP($C24,REV!$C:$AA,13,0)-'TRADE IN'!$F33=0,"",(VLOOKUP($C24,REV!$C:$AA,13,0)-'TRADE IN'!$F24)) -> 599 | P24: =IF(VLOOKUP($C24,REV!$C:$AA,14,0)-'TRADE IN'!$F33=0,"",(VLOOKUP($C24,REV!$C:$AA,14,0)-'TRADE IN'!$F24)) -> 599 | Q24: =IF(VLOOKUP($C24,REV!$C:$AA,15,0)-'TRADE IN'!$F33=0,"",(VLOOKUP($C24,REV!$C:$AA,15,0)-'TRADE IN'!$F24)) -> 599 | R24: =IF(VLOOKUP($C24,REV!$C:$AA,16,0)-'TRADE IN'!$F33=0,"",(VLOOKUP($C24,REV!$C:$AA,16,0)-'TRADE IN'!$F24)) -> 599 | S24: =IF(VLOOKUP($C24,REV!$C:$AA,17,0)-'TRADE IN'!$F33=0,"",(VLOOKUP($C24,REV!$C:$AA,17,0)-'TRADE IN'!$F24)) -> 599 | T24: =IF(VLOOKUP($C24,REV!$C:$AA,18,0)-'TRADE IN'!$F33=0,"",(VLOOKUP($C24,REV!$C:$AA,18,0)-'TRADE IN'!$F24)) -> 599 | U24: =IF(VLOOKUP($C24,REV!$C:$AA,19,0)-'TRADE IN'!$F33=0,"",(VLOOKUP($C24,REV!$C:$AA,19,0)-'TRADE IN'!$F24)) -> 599 | V24: =IF(VLOOKUP($C24,REV!$C:$AA,20,0)-'TRADE IN'!$F33=0,"",(VLOOKUP($C24,REV!$C:$AA,20,0)-'TRADE IN'!$F24)) -> 599 | W24: =IF(VLOOKUP($C24,REV!$C:$AA,21,0)-'TRADE IN'!$F33=0,"",(VLOOKUP($C24,REV!$C:$AA,21,0)-'TRADE IN'!$F24)) -> 599 | X24: =IF(VLOOKUP($C24,REV!$C:$AA,22,0)-'TRADE IN'!$F33=0,"",(VLOOKUP($C24,REV!$C:$AA,22,0)-'TRADE IN'!$F24)) -> 549 | Y24: =IF(VLOOKUP($C24,REV!$C:$AA,23,0)-'TRADE IN'!$F33=0,"",(VLOOKUP($C24,REV!$C:$AA,23,0)-'TRADE IN'!$F24)) -> 549 | Z24: =IF(VLOOKUP($C24,REV!$C:$AA,24,0)-'TRADE IN'!$F33=0,"",(VLOOKUP($C24,REV!$C:$AA,24,0)-'TRADE IN'!$F24)) -> 549 | AA24: =IF(VLOOKUP($C24,REV!$C:$AA,25,0)-'TRADE IN'!$F33=0,"",(VLOOKUP($C24,REV!$C:$AA,25,0)-'TRADE IN'!$F24)) -> 549 | AW24: =IF(REV!AW24=0,"",REV!AW24) -> 31.03.2026 | AX24: 4G
... A182: Price Oferta | B182: 21X | C182: 4016613 | D182: APPLE IPHONE 16 PRO MAX 512GB | E182: APPLE IPHONE 16 PRO MAX 512GB-DESERTO | J182: =IF(VLOOKUP($C182,REV!$C:$AA,8,0)-'TRADE IN'!$F182=0,"",(VLOOKUP($C182,REV!$C:$AA,8,0)-'TRADE IN'!$F182)) -> 11999 | K182: =IF(VLOOKUP($C182,REV!$C:$AA,9,0)-'TRADE IN'!$F182=0,"",(VLOOKUP($C182,REV!$C:$AA,9,0)-'TRADE IN'!$F182)) -> 11999 | L182: =IF(VLOOKUP($C182,REV!$C:$AA,10,0)-'TRADE IN'!$F191=0,"",(VLOOKUP($C182,REV!$C:$AA,10,0)-'TRADE IN'!$F182)) -> 11999 | M182: =IF(VLOOKUP($C182,REV!$C:$AA,11,0)-'TRADE IN'!$F191=0,"",(VLOOKUP($C182,REV!$C:$AA,11,0)-'TRADE IN'!$F182)) -> 11999 | N182: =IF(VLOOKUP($C182,REV!$C:$AA,12,0)-'TRADE IN'!$F191=0,"",(VLOOKUP($C182,REV!$C:$AA,12,0)-'TRADE IN'!$F182)) -> 11999 | O182: =IF(VLOOKUP($C182,REV!$C:$AA,13,0)-'TRADE IN'!$F191=0,"",(VLOOKUP($C182,REV!$C:$AA,13,0)-'TRADE IN'!$F182)) -> 11699 | P182: =IF(VLOOKUP($C182,REV!$C:$AA,14,0)-'TRADE IN'!$F191=0,"",(VLOOKUP($C182,REV!$C:$AA,14,0)-'TRADE IN'!$F182)) -> 11599 | Q182: =IF(VLOOKUP($C182,REV!$C:$AA,15,0)-'TRADE IN'!$F191=0,"",(VLOOKUP($C182,REV!$C:$AA,15,0)-'TRADE IN'!$F182)) -> 10999 | R182: =IF(VLOOKUP($C182,REV!$C:$AA,16,0)-'TRADE IN'!$F191=0,"",(VLOOKUP($C182,REV!$C:$AA,16,0)-'TRADE IN'!$F182)) -> 11699 | S182: =IF(VLOOKUP($C182,REV!$C:$AA,17,0)-'TRADE IN'!$F191=0,"",(VLOOKUP($C182,REV!$C:$AA,17,0)-'TRADE IN'!$F182)) -> 11599 | T182: =IF(VLOOKUP($C182,REV!$C:$AA,18,0)-'TRADE IN'!$F191=0,"",(VLOOKUP($C182,REV!$C:$AA,18,0)-'TRADE IN'!$F182)) -> 10999 | U182: =IF(VLOOKUP($C182,REV!$C:$AA,19,0)-'TRADE IN'!$F191=0,"",(VLOOKUP($C182,REV!$C:$AA,19,0)-'TRADE IN'!$F182)) -> 10999 | V182: =IF(VLOOKUP($C182,REV!$C:$AA,20,0)-'TRADE IN'!$F191=0,"",(VLOOKUP($C182,REV!$C:$AA,20,0)-'TRADE IN'!$F182)) -> 10999 | W182: =IF(VLOOKUP($C182,REV!$C:$AA,21,0)-'TRADE IN'!$F191=0,"",(VLOOKUP($C182,REV!$C:$AA,21,0)-'TRADE IN'!$F182)) -> 10999 | X182: =IF(VLOOKUP($C182,REV!$C:$AA,22,0)-'TRADE IN'!$F191=0,"",(VLOOKUP($C182,REV!$C:$AA,22,0)-'TRADE IN'!$F182)) -> 10799 | Y182: =IF(VLOOKUP($C182,REV!$C:$AA,23,0)-'TRADE IN'!$F191=0,"",(VLOOKUP($C182,REV!$C:$AA,23,0)-'TRADE IN'!$F182)) -> 10299 | Z182: =IF(VLOOKUP($C182,REV!$C:$AA,24,0)-'TRADE IN'!$F191=0,"",(VLOOKUP($C182,REV!$C:$AA,24,0)-'TRADE IN'!$F182)) -> 10299 | AA182: =IF(VLOOKUP($C182,REV!$C:$AA,25,0)-'TRADE IN'!$F191=0,"",(VLOOKUP($C182,REV!$C:$AA,25,0)-'TRADE IN'!$F182)) -> 10299 | AW182: =IF(REV!AW182=0,"",REV!AW182) -> 31.03.2026 | AX182: 5G
A183: Price Oferta | B183: 21X | C183: 4016619 | D183: APPLE IPHONE 16 PRO MAX 512GB | E183: APPLE IPHONE 16 PRO MAX 512GB-PRETO | J183: =IF(VLOOKUP($C183,REV!$C:$AA,8,0)-'TRADE IN'!$F183=0,"",(VLOOKUP($C183,REV!$C:$AA,8,0)-'TRADE IN'!$F183)) -> 11999 | K183: =IF(VLOOKUP($C183,REV!$C:$AA,9,0)-'TRADE IN'!$F183=0,"",(VLOOKUP($C183,REV!$C:$AA,9,0)-'TRADE IN'!$F183)) -> 11999 | L183: =IF(VLOOKUP($C183,REV!$C:$AA,10,0)-'TRADE IN'!$F194=0,"",(VLOOKUP($C183,REV!$C:$AA,10,0)-'TRADE IN'!$F183)) -> 11999 | M183: =IF(VLOOKUP($C183,REV!$C:$AA,11,0)-'TRADE IN'!$F194=0,"",(VLOOKUP($C183,REV!$C:$AA,11,0)-'TRADE IN'!$F183)) -> 11999 | N183: =IF(VLOOKUP($C183,REV!$C:$AA,12,0)-'TRADE IN'!$F194=0,"",(VLOOKUP($C183,REV!$C:$AA,12,0)-'TRADE IN'!$F183)) -> 11999 | O183: =IF(VLOOKUP($C183,REV!$C:$AA,13,0)-'TRADE IN'!$F194=0,"",(VLOOKUP($C183,REV!$C:$AA,13,0)-'TRADE IN'!$F183)) -> 11699 | P183: =IF(VLOOKUP($C183,REV!$C:$AA,14,0)-'TRADE IN'!$F194=0,"",(VLOOKUP($C183,REV!$C:$AA,14,0)-'TRADE IN'!$F183)) -> 11599 | Q183: =IF(VLOOKUP($C183,REV!$C:$AA,15,0)-'TRADE IN'!$F194=0,"",(VLOOKUP($C183,REV!$C:$AA,15,0)-'TRADE IN'!$F183)) -> 10999 | R183: =IF(VLOOKUP($C183,REV!$C:$AA,16,0)-'TRADE IN'!$F194=0,"",(VLOOKUP($C183,REV!$C:$AA,16,0)-'TRADE IN'!$F183)) -> 11699 | S183: =IF(VLOOKUP($C183,REV!$C:$AA,17,0)-'TRADE IN'!$F194=0,"",(VLOOKUP($C183,REV!$C:$AA,17,0)-'TRADE IN'!$F183)) -> 11599 | T183: =IF(VLOOKUP($C183,REV!$C:$AA,18,0)-'TRADE IN'!$F194=0,"",(VLOOKUP($C183,REV!$C:$AA,18,0)-'TRADE IN'!$F183)) -> 10999 | U183: =IF(VLOOKUP($C183,REV!$C:$AA,19,0)-'TRADE IN'!$F194=0,"",(VLOOKUP($C183,REV!$C:$AA,19,0)-'TRADE IN'!$F183)) -> 10999 | V183: =IF(VLOOKUP($C183,REV!$C:$AA,20,0)-'TRADE IN'!$F194=0,"",(VLOOKUP($C183,REV!$C:$AA,20,0)-'TRADE IN'!$F183)) -> 10999 | W183: =IF(VLOOKUP($C183,REV!$C:$AA,21,0)-'TRADE IN'!$F194=0,"",(VLOOKUP($C183,REV!$C:$AA,21,0)-'TRADE IN'!$F183)) -> 10999 | X183: =IF(VLOOKUP($C183,REV!$C:$AA,22,0)-'TRADE IN'!$F194=0,"",(VLOOKUP($C183,REV!$C:$AA,22,0)-'TRADE IN'!$F183)) -> 10799 | Y183: =IF(VLOOKUP($C183,REV!$C:$AA,23,0)-'TRADE IN'!$F194=0,"",(VLOOKUP($C183,REV!$C:$AA,23,0)-'TRADE IN'!$F183)) -> 10299 | Z183: =IF(VLOOKUP($C183,REV!$C:$AA,24,0)-'TRADE IN'!$F194=0,"",(VLOOKUP($C183,REV!$C:$AA,24,0)-'TRADE IN'!$F183)) -> 10299 | AA183: =IF(VLOOKUP($C183,REV!$C:$AA,25,0)-'TRADE IN'!$F194=0,"",(VLOOKUP($C183,REV!$C:$AA,25,0)-'TRADE IN'!$F183)) -> 10299 | AW183: =IF(REV!AW183=0,"",REV!AW183) -> 31.03.2026 | AX183: 5G
