Workbook

Sheet REV
A1: OFERTAS VÁLIDAS APENAS PARA PLANOS CONSUMER
B4: Inclusão de Preços
B5: Alteração de Preços
A7: Preços Elegíveis a Price Back
A8: Preços Elegíveis a Price Oferta
A9: CANAL: | B9: REVENDAS
C11: DATA INÍCIO: | D11: 46311 | J11: COM FIDELIZAÇÃO - GROSS / MIGRAÇÃO / UPGRADE / PORTABILIDADE / BASE SEM MOVIMENTAÇÃO | AM11: TIM FIXO | AP11: TIM CASA | AY11: 0.0202 | AZ11: 0.0182 | BA11: 0.0103
A12: Regra Reembolso Pós Fidelizado | B12: CATEGORIA MKT | C12: CÓDIGO | D12: DESCRIÇÃO COMERCIAL | E12: DESCRIÇÃO SAP | F12: PRÉ | G12: PREÇO BASE FATURAMENTO RETAIL | H12: CONTROLE NÃO FIDELIZADO - TODOS (Fatura / Express) | I12: PÓS PAGO NÃO FIDELIZADO - VIDE ABA DE REGRAS | J12: TIM CONTROLE | K12: TIM CONTROLE PLUS | L12: TIM CONTROLE PREMIUM | M12: TIM CONTROLE SMART | N12: TIM CONTROLE REDES SOCIAIS | O12: TIM BLACK | P12: TIM BLACK PLUS | Q12: TIM BLACK PREMIUM | R12: TIM BLACK A (15GB) | S12: TIM BLACK B (20GB) | T12: TIM BLACK C (25GB) | U12: TIM BLACK C ULTRA | V12: TIM BLACK FAMÍLIA | W12: TIM BLACK FAMÍLIA A ONE | X12: TIM BLACK FAMÍLIA PLUS | Y12: TIM BLACK FAMÍLIA PREMIUM | Z12: TIM BLACK FAMÍLIA C ONE | AA12: TIM BLACK FAMÍLIA VIP | AB12: TIM Fibra 400M 24 | AC12: TIM Fibra 500M 24 - 2 | AD12: TIM Fibra 600M 24 - 2 | AE12: TIM Fibra 600M P 24 - 2 | AF12: TIM Fibra 600M M 24 - 2 | AG12: TIM Ultrafibra 800M YT26 | AH12: TIM Fibra 600M GP 25 | AI12: TIM Fibra 1GB 24 | AJ12: TIM Fibra 1GB P 24 | AK12: TIM Fibra 1GB M 24 | AL12: TIM Fibra 2GB 24 | AM12: TIM FIXO LOCAL TOTAL PLUS (Plano Fidelizado) | AN12: TIM FIXO BRASIL TOTAL PLUS (Plano Fidelizado) | AO12: TIM FIXO TOTAL LDI PLUS (Plano Fidelizado) | AP12: TIM LIVE INTERNET 30GB (sem fidelização) | AQ12: TIM LIVE INTERNET 50GB (sem fidelização) | AR12: TIM LIVE INTERNET 80GB (sem fidelização) | AS12: TIM LIVE INTERNET 30GB PLUS | AT12: TIM LIVE INTERNET 50GB PLUS | AU12: TIM LIVE INTERNET 80GB PLUS | AW12: DATA FIM DA OFERTA | AX12: TECNOLOGIA | AY12: Seguro Completo (valor mensal) | AZ12: Roubo e Furto (valor mensal) | BA12: Quebra e danos (valor mensal)
A13: Price Oferta | B13: 21X | C13: 4014380 | D13: APPLE IPHONE 12 64GB | E13: APPLE IPHONE 12 64GB-PRETO NAC | F13: 6499 | G13: 2599 | H13: 999 | I13: 999 | J13: 999 | K13: 999 | L13: 999 | M13: 999 | N13: 999 | O13: 999 | P13: 999 | Q13: 999 | R13: 999 | S13: 999 | T13: 999 | U13: 999 | V13: 999 | W13: 999 | X13: 999 | Y13: 999 | Z13: 999 | AA13: 999 | AW13: 03.11.2026 | AX13: 5G | AY13: =$H13*AY$11 -> 20.1798 | AZ13: =($H13*AZ$11) -> 18.1818 | BA13: =$H13*BA$11 -> 10.2897
A14: Price Oferta | B14: 21X | C14: 4014382 | D14: APPLE IPHONE 12 64GB | E14: APPLE IPHONE 12 64GB-BRANCO NAC | F14: 6499 | G14: 2599 | H14: 999 | I14: 999 | J14: 999 | K14: 999 | L14: 999 | M14: 999 | N14: 999 | O14: 999 | P14: 999 | Q14: 999 | R14: 999 | S14: 999 | T14: 999 | U14: 999 | V14: 999 | W14: 999 | X14: 999 | Y14: 999 | Z14: 999 | AA14: 999 | AW14: 03.11.2026 | AX14: 5G | AY14: =$H14*AY$11 -> 20.1798 | AZ14: =($H14*AZ$11) -> 18.1818 | BA14: =$H14*BA$11 -> 10.2897
A15: Price Oferta | B15: 21X | C15: 4014391 | D15: APPLE IPHONE 12 128GB | E15: APPLE IPHONE 12 128GB-PRETO NAC | F15: 4499 | G15: 2299 | H15: 999 | I15: 999 | J15: 999 | K15: 999 | L15: 999 | M15: 999 | N15: 999 | O15: 999 | P15: 999 | Q15: 999 | R15: 999 | S15: 999 | T15: 999 | U15: 999 | V15: 999 | W15: 999 | X15: 999 | Y15: 999 | Z15: 999 | AA15: 999 | AW15: 03.11.2026 | AX15: 5G | AY15: =$H15*AY$11 -> 20.1798 | AZ15: =($H15*AZ$11) -> 18.1818 | BA15: =$H15*BA$11 -> 10.2897
A16: Price Oferta | B16: 21X | C16: 4014723 | D16: APPLE IPHONE 13 128GB | E16: APPLE IPHONE 13 128GB-PRETO NAC | F16: 6099 | G16: 3199 | H16: 4499 | I16: 4499 | J16: 3599 | K16: 3499 | L16: 3499 | M16: 3599 | N16: 3499 | O16: 3099 | P16: 2999 | Q16: 2499 | R16: 3099 | S16: 2999 | T16: 2499 | U16: 2499 | V16: 2499 | W16: 2499 | X16: 2299 | Y16: 1999 | Z16: 1999 | AA16: 1999 | AW16: 03.11.2026 | AX16: 5G | AY16: =$H16*AY$11 -> 90.8798 | AZ16: =($H16*AZ$11) -> 81.8818 | BA16: =$H16*BA$11 -> 46.3397
A17: Price Oferta | B17: 21X | C17: 4014594 | D17: APPLE IPHONE 13 256GB | E17: APPLE IPHONE 13 256GB-PRETO | F17: 6299 | G17: 2799 | H17: 3899 | I17: 3899 | J17: 3799 | K17: 3799 | L17: 3799 | M17: 3799 | N17: 3799 | O17: 3599 | P17: 3499 | Q17: 2999 | R17: 3599 | S17: 3499 | T17: 2999 | U17: 2999 | V17: 2999 | W17: 2999 | X17: 2799 | Y17: 2499 | Z17: 2499 | AA17: 2499 | AW17: 03.11.2026 | AX17: 5G | AY17: =$H17*AY$11 -> 78.7598 | AZ17: =($H17*AZ$11) -> 70.9618 | BA17: =$H17*BA$11 -> 40.1597
A18: Price Oferta | B18: 21X | C18: 4014837 | D18: APPLE IPHONE 13 256GB | E18: APPLE IPHONE 13 256GB-AZUL NAC | F18: 6299 | G18: 2799 | H18: 3899 | I18: 3899 | J18: 3799 | K18: 3799 | L18: 3799 | M18: 3799 | N18: 3799 | O18: 3599 | P18: 3499 | Q18: 2999 | R18: 3599 | S18: 3499 | T18: 2999 | U18: 2999 | V18: 2999 | W18: 2999 | X18: 2799 | Y18: 2499 | Z18: 2499 | AA18: 2499 | AW18: 03.11.2026 | AX18: 5G | AY18: =$H18*AY$11 -> 78.7598 | AZ18: =($H18*AZ$11) -> 70.9618 | BA18: =$H18*BA$11 -> 40.1597
A19: Price Oferta | B19: 21X | C19: 4014833 | D19: APPLE IPHONE 13 256GB | E19: APPLE IPHONE 13 256GB-PRETO NAC | F19: 6299 | G19: 2799 | H19: 3899 | I19: 3899 | J19: 3799 | K19: 3799 | L19: 3799 | M19: 3799 | N19: 3799 | O19: 3599 | P19: 3499 | Q19: 2999 | R19: 3599 | S19: 3499 | T19: 2999 | U19: 2999 | V19: 2999 | W19: 2999 | X19: 2799 | Y19: 2499 | Z19: 2499 | AA19: 2499 | AW19: 03.11.2026 | AX19: 5G | AY19: =$H19*AY$11 -> 78.7598 | AZ19: =($H19*AZ$11) -> 70.9618 | BA19: =$H19*BA$11 -> 40.1597
A20: Price Oferta | B20: 21X | C20: 4014836 | D20: APPLE IPHONE 13 256GB | E20: APPLE IPHONE 13 256GB-VERMELHO NAC | F20: 6299 | G20: 2799 | H20: 3899 | I20: 3899 | J20: 3799 | K20: 3799 | L20: 3799 | M20: 3799 | N20: 3799 | O20: 3599 | P20: 3499 | Q20: 2999 | R20: 3599 | S20: 3499 | T20: 2999 | U20: 2999 | V20: 2999 | W20: 2999 | X20: 2799 | Y20: 2499 | Z20: 2499 | AA20: 2499 | AW20: 03.11.2026 | AX20: 5G | AY20: =$H20*AY$11 -> 78.7598 | AZ20: =($H20*AZ$11) -> 70.9618 | BA20: =$H20*BA$11 -> 40.1597
A21: Price Oferta | B21: 21X | C21: 4015185 | D21: APPLE IPHONE 14 128GB | E21: APPLE IPHONE 14 128GB-PRETO | F21: 7299 | G21: 3899 | H21: 5299 | I21: 5299 | J21: 4199 | K21: 4199 | L21: 4199 | M21: 4199 | N21: 4199 | O21: 3899 | P21: 3799 | Q21: 3099 | R21: 3899 | S21: 3799 | T21: 3099 | U21: 3099 | V21: 3099 | W21: 3099 | X21: 2999 | Y21: 2499 | Z21: 2499 | AA21: 2499 | AW21: 03.11.2026 | AX21: 5G | AY21: =$H21*AY$11 -> 107.0398 | AZ21: =($H21*AZ$11) -> 96.4418 | BA21: =$H21*BA$11 -> 54.5797
A22: Price Oferta | B22: 21X | C22: 4015262 | D22: APPLE IPHONE 14 128GB | E22: APPLE IPHONE 14 128GB-PRETO NAC | F22: 7299 | G22: 3899 | H22: 5299 | I22: 5299 | J22: 4199 | K22: 4199 | L22: 4199 | M22: 4199 | N22: 4199 | O22: 3899 | P22: 3799 | Q22: 3099 | R22: 3899 | S22: 3799 | T22: 3099 | U22: 3099 | V22: 3099 | W22: 3099 | X22: 2999 | Y22: 2499 | Z22: 2499 | AA22: 2499 | AW22: 03.11.2026 | AX22: 5G | AY22: =$H22*AY$11 -> 107.0398 | AZ22: =($H22*AZ$11) -> 96.4418 | BA22: =$H22*BA$11 -> 54.5797
A23: Price Oferta | B23: 21X | C23: 4015180 | D23: APPLE IPHONE 14 256GB | E23: APPLE IPHONE 14 256GB-BRANCO | F23: 7799 | G23: 2899 | H23: 4399 | I23: 4399 | J23: 4399 | K23: 4399 | L23: 4399 | M23: 4399 | N23: 4399 | O23: 4299 | P23: 4199 | Q23: 3499 | R23: 4299 | S23: 4199 | T23: 3499 | U23: 3499 | V23: 3499 | W23: 3499 | X23: 3399 | Y23: 2499 | Z23: 2499 | AA23: 2449 | AB23: 4399 | AC23: 4399 | AD23: 4399 | AE23: 4199 | AF23: 4199 | AG23: 4199 | AH23: 4199 | AI23: 3499 | AJ23: 3499 | AK23: 3499 | AL23: 2499 | AW23: 03.11.2026 | AX23: 5G | AY23: =$H23*AY$11 -> 88.8598 | AZ23: =($H23*AZ$11) -> 80.0618 | BA23: =$H23*BA$11 -> 45.3097
A24: Price Oferta | B24: 21X | C24: 4015186 | D24: APPLE IPHONE 14 256GB | E24: APPLE IPHONE 14 256GB-PRETO | F24: 7799 | G24: 2899 | H24: 4399 | I24: 4399 | J24: 4399 | K24: 4399 | L24: 4399 | M24: 4399 | N24: 4399 | O24: 4299 | P24: 4199 | Q24: 3499 | R24: 4299 | S24: 4199 | T24: 3499 | U24: 3499 | V24: 3499 | W24: 3499 | X24: 3399 | Y24: 2499 | Z24: 2499 | AA24: 2449 | AB24: 4399 | AC24: 4399 | AD24: 4399 | AE24: 4199 | AF24: 4199 | AG24: 4199 | AH24: 4199 | AI24: 3499 | AJ24: 3499 | AK24: 3499 | AL24: 2499 | AW24: 03.11.2026 | AX24: 5G | AY24: =$H24*AY$11 -> 88.8598 | AZ24: =($H24*AZ$11) -> 80.0618 | BA24: =$H24*BA$11 -> 45.3097
A25: Price Oferta | B25: 21X | C25: 4015267 | D25: APPLE IPHONE 14 256GB | E25: APPLE IPHONE 14 256GB-PRETO NAC | F25: 7799 | G25: 2899 | H25: 4399 | I25: 4399 | J25: 4399 | K25: 4399 | L25: 4399 | M25: 4399 | N25: 4399 | O25: 4299 | P25: 4199 | Q25: 3499 | R25: 4299 | S25: 4199 | T25: 3499 | U25: 3499 | V25: 3499 | W25: 3499 | X25: 3399 | Y25: 2499 | Z25: 2499 | AA25: 2449 | AB25: 4399 | AC25: 4399 | AD25: 4399 | AE25: 4199 | AF25: 4199 | AG25: 4199 | AH25: 4199 | AI25: 3499 | AJ25: 3499 | AK25: 3499 | AL25: 2499 | AW25: 03.11.2026 | AX25: 5G | AY25: =$H25*AY$11 -> 88.8598 | AZ25: =($H25*AZ$11) -> 80.0618 | BA25: =$H25*BA$11 -> 45.3097
A26: Price Oferta | B26: 21X | C26: 4015268 | D26: APPLE IPHONE 14 256GB | E26: APPLE IPHONE 14 256GB-BRANCO NAC | F26: 7799 | G26: 2899 | H26: 4399 | I26: 4399 | J26: 4399 | K26: 4399 | L26: 4399 | M26: 4399 | N26: 4399 | O26: 4299 | P26: 4199 | Q26: 3499 | R26: 4299 | S26: 4199 | T26: 3499 | U26: 3499 | V26: 3499 | W26: 3499 | X26: 3399 | Y26: 2499 | Z26: 2499 | AA26: 2449 | AB26: 4399 | AC26: 4399 | AD26: 4399 | AE26: 4199 | AF26: 4199 | AG26: 4199 | AH26: 4199 | AI26: 3499 | AJ26: 3499 | AK26: 3499 | AL26: 2499 | AW26: 03.11.2026 | AX26: 5G | AY26: =$H26*AY$11 -> 88.8598 | AZ26: =($H26*AZ$11) -> 80.0618 | BA26: =$H26*BA$11 -> 45.3097
A27: Price Oferta | B27: 21X | C27: 4015179 | D27: APPLE IPHONE 14 PLUS 256GB | E27: APPLE IPHONE 14 PLUS 256GB-BRANCO | F27: 7299 | G27: 3899 | H27: 4599 | I27: 4599 | J27: 4499 | K27: 4499 | L27: 4499 | M27: 4499 | N27: 4499 | O27: 4399 | P27: 4299 | Q27: 3499 | R27: 4399 | S27: 4299 | T27: 3499 | U27: 3499 | V27: 3499 | W27: 3499 | X27: 3399 | Y27: 2899 | Z27: 2899 | AA27: 2899 | AW27: 03.11.2026 | AX27: 5G | AY27: =$H27*AY$11 -> 92.8998 | AZ27: =($H27*AZ$11) -> 83.7018 | BA27: =$H27*BA$11 -> 47.3697
A28: Price Oferta | B28: 21X | C28: 4015187 | D28: APPLE IPHONE 14 PLUS 256GB | E28: APPLE IPHONE 14 PLUS 256GB-PRETO | F28: 7299 | G28: 3899 | H28: 4599 | I28: 4599 | J28: 4499 | K28: 4499 | L28: 4499 | M28: 4499 | N28: 4499 | O28: 4399 | P28: 4299 | Q28: 3499 | R28: 4399 | S28: 4299 | T28: 3499 | U28: 3499 | V28: 3499 | W28: 3499 | X28: 3399 | Y28: 2899 | Z28: 2899 | AA28: 2899 | AW28: 03.11.2026 | AX28: 5G | AY28: =$H28*AY$11 -> 92.8998 | AZ28: =($H28*AZ$11) -> 83.7018 | BA28: =$H28*BA$11 -> 47.3697
A29: Price Oferta | B29: 21X | C29: 4015711 | D29: APPLE IPHONE 14 PLUS 256GB | E29: APPLE IPHONE 14 PLUS 256GB-PRETO NAC | F29: 7299 | G29: 3899 | H29: 4599 | I29: 4599 | J29: 4499 | K29: 4499 | L29: 4499 | M29: 4499 | N29: 4499 | O29: 4399 | P29: 4299 | Q29: 3499 | R29: 4399 | S29: 4299 | T29: 3499 | U29: 3499 | V29: 3499 | W29: 3499 | X29: 3399 | Y29: 2899 | Z29: 2899 | AA29: 2899 | AW29: 03.11.2026 | AX29: 5G | AY29: =$H29*AY$11 -> 92.8998 | AZ29: =($H29*AZ$11) -> 83.7018 | BA29: =$H29*BA$11 -> 47.3697
A30: Price Oferta | B30: 21X | C30: 4015162 | D30: APPLE IPHONE 14 PRO MAX 256GB | E30: APPLE IPHONE 14 PRO MAX 256GB-GRAFITE | F30: 11499 | G30: 6899 | H30: 7999 | I30: 7999 | J30: 6399 | K30: 6399 | L30: 6399 | M30: 6399 | N30: 6399 | O30: 6299 | P30: 6199 | Q30: 5999 | R30: 6299 | S30: 6199 | T30: 5999 | U30: 5999 | V30: 5999 | W30: 5999 | X30: 5899 | Y30: 5499 | Z30: 5499 | AA30: 5499 | AW30: 03.11.2026 | AX30: 5G | AY30: =$H30*AY$11 -> 161.5798 | AZ30: =($H30*AZ$11) -> 145.5818 | BA30: =$H30*BA$11 -> 82.3897
A31: Price Oferta | B31: 21X | C31: 4015112 | D31: APPLE IPHONE 14 PRO 256GB | E31: APPLE IPHONE 14 PRO 256GB-GRAFITE | F31: 10499 | G31: 5899 | H31: 6999 | I31: 6999 | J31: 5899 | K31: 5899 | L31: 5899 | M31: 5899 | N31: 5899 | O31: 5799 | P31: 5699 | Q31: 5499 | R31: 5799 | S31: 5699 | T31: 5499 | U31: 5499 | V31: 5499 | W31: 5499 | X31: 5399 | Y31: 4999 | Z31: 4999 | AA31: 4999 | AW31: 03.11.2026 | AX31: 5G | AY31: =$H31*AY$11 -> 141.3798 | AZ31: =($H31*AZ$11) -> 127.3818 | BA31: =$H31*BA$11 -> 72.0897
A32: Price Oferta | B32: 21X | C32: 4015116 | D32: APPLE IPHONE 14 PRO 256GB | E32: APPLE IPHONE 14 PRO 256GB-DOURADO | F32: 10499 | G32: 5899 | H32: 6999 | I32: 6999 | J32: 5899 | K32: 5899 | L32: 5899 | M32: 5899 | N32: 5899 | O32: 5799 | P32: 5699 | Q32: 5499 | R32: 5799 | S32: 5699 | T32: 5499 | U32: 5499 | V32: 5499 | W32: 5499 | X32: 5399 | Y32: 4999 | Z32: 4999 | AA32: 4999 | AW32: 03.11.2026 | AX32: 5G | AY32: =$H32*AY$11 -> 141.3798 | AZ32: =($H32*AZ$11) -> 127.3818 | BA32: =$H32*BA$11 -> 72.0897
A33: Price Oferta | B33: 21X | C33: 4015742 | D33: APPLE IPHONE 15 128GB | E33: APPLE IPHONE 15 128GB-PRETO | F33: 7299 | G33: 5399 | H33: 5699 | I33: 5699 | J33: 4999 | K33: 4899 | L33: 4899 | M33: 4999 | N33: 4899 | O33: 4799 | P33: 4699 | Q33: 4499 | R33: 4799 | S33: 4699 | T33: 4499 | U33: 4399 | V33: 4399 | W33: 4299 | X33: 4199 | Y33: 3499 | Z33: 3499 | AA33: 3499 | AW33: 03.11.2026 | AX33: 5G | AY33: =$H33*AY$11 -> 115.1198 | AZ33: =($H33*AZ$11) -> 103.7218 | BA33: =$H33*BA$11 -> 58.6997
A34: Price Oferta | B34: 21X | C34: 4015725 | D34: APPLE IPHONE 15 128GB | E34: APPLE IPHONE 15 128GB-ROSA | F34: 7299 | G34: 5399 | H34: 5699 | I34: 5699 | J34: 4999 | K34: 4899 | L34: 4899 | M34: 4999 | N34: 4899 | O34: 4799 | P34: 4699 | Q34: 4499 | R34: 4799 | S34: 4699 | T34: 4499 | U34: 4399 | V34: 4399 | W34: 4299 | X34: 4199 | Y34: 3499 | Z34: 3499 | AA34: 3499 | AW34: 03.11.2026 | AX34: 5G | AY34: =$H34*AY$11 -> 115.1198 | AZ34: =($H34*AZ$11) -> 103.7218 | BA34: =$H34*BA$11 -> 58.6997
A35: Price Oferta | B35: 21X | C35: 4015794 | D35: APPLE IPHONE 15 128GB | E35: APPLE IPHONE 15 128GB-VERDE | F35: 7299 | G35: 5399 | H35: 5699 | I35: 5699 | J35: 4999 | K35: 4899 | L35: 4899 | M35: 4999 | N35: 4899 | O35: 4799 | P35: 4699 | Q35: 4499 | R35: 4799 | S35: 4699 | T35: 4499 | U35: 4399 | V35: 4399 | W35: 4299 | X35: 4199 | Y35: 3499 | Z35: 3499 | AA35: 3499 | AW35: 03.11.2026 | AX35: 5G | AY35: =$H35*AY$11 -> 115.1198 | AZ35: =($H35*AZ$11) -> 103.7218 | BA35: =$H35*BA$11 -> 58.6997
A36: Price Oferta | B36: 21X | C36: 4015808 | D36: APPLE IPHONE 15 128GB | E36: APPLE IPHONE 15 128GB-AMARELO | F36: 7299 | G36: 5399 | H36: 5699 | I36: 5699 | J36: 4999 | K36: 4899 | L36: 4899 | M36: 4999 | N36: 4899 | O36: 4799 | P36: 4699 | Q36: 4499 | R36: 4799 | S36: 4699 | T36: 4499 | U36: 4399 | V36: 4399 | W36: 4299 | X36: 4199 | Y36: 3499 | Z36: 3499 | AA36: 3499 | AW36: 03.11.2026 | AX36: 5G | AY36: =$H36*AY$11 -> 115.1198 | AZ36: =($H36*AZ$11) -> 103.7218 | BA36: =$H36*BA$11 -> 58.6997
A37: Price Oferta | B37: 21X | C37: 4015743 | D37: APPLE IPHONE 15 256GB | E37: APPLE IPHONE 15 256GB-PRETO | F37: 8099 | G37: 3899 | H37: 5199 | I37: 5199 | J37: 5099 | K37: 5099 | L37: 5099 | M37: 5099 | N37: 5099 | O37: 4999 | P37: 4899 | Q37: 3999 | R37: 4999 | S37: 4899 | T37: 3999 | U37: 3999 | V37: 3999 | W37: 3999 | X37: 3899 | Y37: 3699 | Z37: 3699 | AA37: 3649 | AW37: 03.11.2026 | AX37: 5G | AY37: =$H37*AY$11 -> 105.0198 | AZ37: =($H37*AZ$11) -> 94.6218 | BA37: =$H37*BA$11 -> 53.5497
A38: Price Oferta | B38: 21X | C38: 4015770 | D38: APPLE IPHONE 15 256GB | E38: APPLE IPHONE 15 256GB-AZUL | F38: 8099 | G38: 3899 | H38: 5199 | I38: 5199 | J38: 5099 | K38: 5099 | L38: 5099 | M38: 5099 | N38: 5099 | O38: 4999 | P38: 4899 | Q38: 3999 | R38: 4999 | S38: 4899 | T38: 3999 | U38: 3999 | V38: 3999 | W38: 3999 | X38: 3899 | Y38: 3699 | Z38: 3699 | AA38: 3649 | AW38: 03.11.2026 | AX38: 5G | AY38: =$H38*AY$11 -> 105.0198 | AZ38: =($H38*AZ$11) -> 94.6218 | BA38: =$H38*BA$11 -> 53.5497
... A85: Price Oferta | B85: 21X | C85: 4016609 | D85: APPLE IPHONE 16 PRO MAX 512GB | E85: APPLE IPHONE 16 PRO MAX 512GB-TITANIO | F85: 13999 | G85: 10799 | H85: 12099 | I85: 12099 | J85: 11999 | K85: 11999 | L85: 11999 | M85: 11999 | N85: 11999 | O85: 11699 | P85: 11599 | Q85: 10999 | R85: 11699 | S85: 11599 | T85: 10999 | U85: 10999 | V85: 10999 | W85: 10999 | X85: 10799 | Y85: 10299 | Z85: 10299 | AA85: 10299 | AW85: 03.11.2026 | AX85: 5G | AY85: =$H85*AY$11 -> 244.3998 | AZ85: =($H85*AZ$11) -> 220.2018 | BA85: =$H85*BA$11 -> 124.6197
A86: Price Oferta | B86: 21X | C86: 4016916 | D86: APPLE IPHONE 16E 256GB | E86: APPLE IPHONE 16E 256GB-PRETO NAC | F86: 6599 | G86: 2299 | H86: 4799 | I86: 4799 | J86: 4799 | K86: 4799 | L86: 4799 | M86: 4799 | N86: 4799 | O86: 4699 | P86: 4599 | Q86: 3599 | R86: 4699 | S86: 4599 | T86: 3599 | U86: 3599 | V86: 3599 | W86: 3599 | X86: 3499 | Y86: 2799 | Z86: 2799 | AA86: 2749 | AB86: 4799 | AC86: 4799 | AD86: 4799 | AE86: 4699 | AF86: 4599 | AG86: 4599 | AH86: 3599 | AI86: 3599 | AJ86: 3599 | AK86: 3599 | AL86: 2799 | AW86: 03.11.2026 | AX86: 5G | AY86: =$H86*AY$11 -> 96.9398 | AZ86: =($H86*AZ$11) -> 87.3418 | BA86: =$H86*BA$11 -> 49.4297
A87: Price Oferta | B87: 21X | C87: 4016917 | D87: APPLE IPHONE 16E 256GB | E87: APPLE IPHONE 16E 256GB-BRANCO NAC | F87: 6599 | G87: 2299 | H87: 4799 | I87: 4799 | J87: 4799 | K87: 4799 | L87: 4799 | M87: 4799 | N87: 4799 | O87: 4699 | P87: 4599 | Q87: 3599 | R87: 4699 | S87: 4599 | T87: 3599 | U87: 3599 | V87: 3599 | W87: 3599 | X87: 3499 | Y87: 2799 | Z87: 2799 | AA87: 2749 | AB87: 4799 | AC87: 4799 | AD87: 4799 | AE87: 4699 | AF87: 4599 | AG87: 4599 | AH87: 3599 | AI87: 3599 | AJ87: 3599 | AK87: 3599 | AL87: 2799 | AW87: 03.11.2026 | AX87: 5G | AY87: =$H87*AY$11 -> 96.9398 | AZ87: =($H87*AZ$11) -> 87.3418 | BA87: =$H87*BA$11 -> 49.4297
A88: Price Oferta | B88: 21X | C88: 4017449 | D88: APPLE IPHONE 17 256GB | E88: APPLE IPHONE 17 256GB-LAVANDA | F88: 7999 | G88: 5399 | H88: 6499 | I88: 6499 | J88: 6399 | K88: 6399 | L88: 6399 | M88: 6399 | N88: 6399 | O88: 6299 | P88: 6199 | Q88: 5499 | R88: 6299 | S88: 6199 | T88: 5499 | U88: 5499 | V88: 5499 | W88: 5499 | X88: 5399 | Y88: 4999 | Z88: 4999 | AA88: 4949 | AB88: 6399 | AC88: 6399 | AD88: 6399 | AE88: 6299 | AF88: 6199 | AG88: 6199 | AH88: 5499 | AI88: 5499 | AJ88: 5499 | AK88: 5499 | AL88: 4999 | AW88: 03.11.2026 | AX88: 5G | AY88: =$H88*AY$11 -> 131.2798 | AZ88: =($H88*AZ$11) -> 118.2818 | BA88: =$H88*BA$11 -> 66.9397
A89: Price Oferta | B89: 21X | C89: 4017897 | D89: APPLE IPHONE 17 256GB | E89: APPLE IPHONE 17 256GB-LAVANDA NAC | F89: 7999 | G89: 5399 | H89: 6499 | I89: 6499 | J89: 6399 | K89: 6399 | L89: 6399 | M89: 6399 | N89: 6399 | O89: 6299 | P89: 6199 | Q89: 5499 | R89: 6299 | S89: 6199 | T89: 5499 | U89: 5499 | V89: 5499 | W89: 5499 | X89: 5399 | Y89: 4999 | Z89: 4999 | AA89: 4949 | AB89: 6399 | AC89: 6399 | AD89: 6399 | AE89: 6299 | AF89: 6199 | AG89: 6199 | AH89: 5499 | AI89: 5499 | AJ89: 5499 | AK89: 5499 | AL89: 4999 | AW89: 03.11.2026 | AX89: 5G | AY89: =$H89*AY$11 -> 131.2798 | AZ89: =($H89*AZ$11) -> 118.2818 | BA89: =$H89*BA$11 -> 66.9397
A90: Price Oferta | B90: 21X | C90: 4017480 | D90: APPLE IPHONE 17 256GB | E90: APPLE IPHONE 17 256GB-AZUL NEVOA | F90: 7999 | G90: 5399 | H90: 6499 | I90: 6499 | J90: 6399 | K90: 6399 | L90: 6399 | M90: 6399 | N90: 6399 | O90: 6299 | P90: 6199 | Q90: 5499 | R90: 6299 | S90: 6199 | T90: 5499 | U90: 5499 | V90: 5499 | W90: 5499 | X90: 5399 | Y90: 4999 | Z90: 4999 | AA90: 4949 | AB90: 6399 | AC90: 6399 | AD90: 6399 | AE90: 6299 | AF90: 6199 | AG90: 6199 | AH90: 5499 | AI90: 5499 | AJ90: 5499 | AK90: 5499 | AL90: 4999 | AW90: 03.11.2026 | AX90: 5G | AY90: =$H90*AY$11 -> 131.2798 | AZ90: =($H90*AZ$11) -> 118.2818 | BA90: =$H90*BA$11 -> 66.9397
...

Sheet ACESSÓRIOS REV
B1: TABELA DE PREÇOS - ACESSÓRIOS
B3: CANAL: | C3: REVENDAS
B4: Inclusão de Preço
B5: Alteração de Preço
C6: DATA INÍCIO: | D6: =REV!D11 -> 46311
B7: CATEGORIA MKT | C7: CÓDIGO | D7: DESCRIÇÃO COMERCIAL | E7: DESCRIÇÃO SAP | F7: PRÉ | G7: PREÇO BASE FATURAMENTO RETAIL | H7: CONTROLE NÃO FIDELIZADO - TODOS (Fatura / Express) | I7: PÓS PAGO NÃO FIDELIZADO - VIDE ABA DE REGRAS | J7: TIM CONTROLE | K7: TIM CONTROLE PLUS | L7: TIM CONTROLE PREMIUM | M7: TIM CONTROLE SMART | N7: TIM CONTROLE REDES SOCIAIS | O7: TIM BLACK | P7: TIM BLACK PLUS | Q7: TIM BLACK PREMIUM | R7: TIM BLACK A (15GB) | S7: TIM BLACK B (20GB) | T7: TIM BLACK C (25GB) | U7: TIM BLACK C ULTRA | V7: TIM BLACK FAMÍLIA | W7: TIM BLACK FAMÍLIA A ONE | X7: TIM BLACK FAMÍLIA PLUS | Y7: TIM BLACK FAMÍLIA PREMIUM | Z7: TIM BLACK FAMÍLIA C ONE | AA7: TIM BLACK FAMÍLIA VIP | AB7: TIM Fibra 400M 24 | AC7: TIM Fibra 500M 24 - 2 | AD7: TIM Fibra 600M 24 - 2 | AE7: TIM Fibra 600M P 24 - 2 | AF7: TIM Fibra 600M M 24 - 2 | AG7: TIM Ultrafibra 800M YT26 | AH7: TIM Fibra 600M GP 25 | AI7: TIM Fibra 1GB 24 | AJ7: TIM Fibra 1GB P 24 | AK7: TIM Fibra 1GB M 24 | AL7: TIM Fibra 2GB 24 | AM7: DATA FIM DA OFERTA
B8: SMARTHOME | C8: 4014927 | D8: BALANCA INTELIGENTE GEONAV | E8: BALANCA INTELIGENTE GEONAV-BRANCO | F8: 199 | G8: 199 | AB8: 169 | AC8: 169 | AD8: 169 | AE8: 169 | AF8: 169 | AG8: 169 | AH8: 169 | AI8: 169 | AJ8: 169 | AK8: 169 | AL8: 169 | AM8: 31.12.9999
B9: GAMER | C9: 4016500 | D9: BASE DE CARREGAMENTO SONY DUALSENSE | E9: BASE DE CARREGAMENTO SONY DUALSENSE-BRAN | F9: 199 | G9: 199 | AM9: 31.12.9999
B10: MUSICA | C10: 4014444 | D10: CAIXA DE SOM BT JBL CHARGE 5 | E10: CAIXA DE SOM BT JBL CHARGE 5-PRETO | F10: 799 | G10: 799 | H10: 799 | I10: 799 | J10: 749 | K10: 749 | L10: 749 | M10: 749 | N10: 749 | O10: 699 | P10: 599 | Q10: 449 | R10: 699 | S10: 599 | T10: 449 | U10: 449 | V10: 449 | W10: 449 | X10: 449 | Y10: 449 | Z10: 449 | AA10: 449 | AM10: 31.12.9999
B11: MUSICA | C11: 4017142 | D11: CAIXA DE SOM BT JBL CHARGE 6 | E11: CAIXA DE SOM BT JBL CHARGE 6-AZUL | F11: 999 | G11: 999 | H11: 999 | I11: 999 | J11: 949 | K11: 949 | L11: 949 | M11: 949 | N11: 949 | O11: 899 | P11: 799 | Q11: 599 | R11: 899 | S11: 799 | T11: 599 | U11: 599 | V11: 599 | W11: 599 | X11: 549 | Y11: 549 | Z11: 549 | AA11: 549 | AM11: 31.12.9999
B12: MUSICA | C12: 4014958 | D12: CAIXA DE SOM BT JBL FLIP 6 | E12: CAIXA DE SOM BT JBL FLIP 6-PRETO | F12: 299 | G12: 399 | AM12: 31.12.9999
B13: MÚSICA | C13: 4017062 | D13: CAIXA DE SOM BT JBL FLIP 7 | E13: CAIXA DE SOM BT JBL FLIP 7-PRETO | F13: 899 | G13: 899 | H13: 899 | I13: 899 | J13: 849 | K13: 849 | L13: 849 | M13: 849 | N13: 849 | O13: 799 | P13: 699 | Q13: 499 | R13: 799 | S13: 699 | T13: 499 | U13: 499 | V13: 499 | W13: 499 | X13: 499 | Y13: 499 | Z13: 499 | AA13: 499 | AM13: 31.12.9999
B14: MUSICA | C14: 4016330 | D14: CAIXA DE SOM BT JBL GO4 | E14: CAIXA DE SOM BT JBL GO4-PRETO | F14: 199 | G14: 199 | H14: 199 | I14: 199 | J14: 149 | K14: 149 | L14: 149 | M14: 149 | N14: 149 | O14: 149 | P14: 149 | Q14: 149 | R14: 149 | S14: 149 | T14: 149 | U14: 149 | V14: 149 | W14: 149 | X14: 149 | Y14: 149 | Z14: 149 | AA14: 149 | AB14: 149 | AC14: 149 | AD14: 149 | AE14: 149 | AF14: 149 | AG14: 149 | AH14: 149 | AI14: 149 | AJ14: 149 | AK14: 149 | AL14: 149 | AM14: 31.12.9999
B15: INFOTECH | C15: 4018060 | D15: CAIXA DE SOM BT JBL GO5 | E15: CAIXA DE SOM BT JBL GO5-PRETO | F15: 359 | G15: 299 | H15: 359 | I15: 359 | J15: 199 | K15: 199 | L15: 199 | M15: 199 | N15: 199 | O15: 199 | P15: 199 | Q15: 99 | R15: 199 | S15: 199 | T15: 99 | U15: 99 | V15: 99 | W15: 99 | X15: 99 | Y15: 99 | Z15: 99 | AA15: 99 | AB15: 199 | AC15: 199 | AD15: 199 | AE15: 199 | AF15: 199 | AG15: 199 | AH15: 199 | AI15: 99 | AJ15: 99 | AK15: 99 | AL15: 99 | AM15: 31.12.9999
B16: MUSICA | C16: 4015270 | D16: CAIXA DE SOM JBL BOOMBOX 3 | E16: CAIXA DE SOM JBL BOOMBOX 3-PRETO | F16: 1999 | G16: 1999 | H16: 1999 | I16: 1999 | J16: 1949 | K16: 1949 | L16: 1949 | M16: 1949 | N16: 1949 | O16: 1899 | P16: 1799 | Q16: 1599 | R16: 1899 | S16: 1799 | T16: 1599 | U16: 1599 | V16: 1599 | W16: 1599 | X16: 1499 | Y16: 1199 | Z16: 1199 | AA16: 1149 | AM16: 31.12.9999
B17: MUSICA | C17: 4015688 | D17: CAIXA DE SOM JBL BOOMBOX 3 | E17: CAIXA DE SOM JBL BOOMBOX 3-PRETO AM | F17: 1999 | G17: 1999 | H17: 1999 | I17: 1999 | J17: 1949 | K17: 1949 | L17: 1949 | M17: 1949 | N17: 1949 | O17: 1899 | P17: 1799 | Q17: 1599 | R17: 1899 | S17: 1799 | T17: 1599 | U17: 1599 | V17: 1599 | W17: 1599 | X17: 1499 | Y17: 1199 | Z17: 1199 | AA17: 1149 | AM17: 31.12.9999
B18: CAIXA DE SOM | C18: 4017260 | D18: CAIXA DE SOM JBL BOOMBOX 4 | E18: CAIXA DE SOM JBL BOOMBOX 4-PRETO | F18: 2599 | G18: 1999 | H18: 2599 | I18: 2599 | J18: 2549 | K18: 2549 | L18: 2549 | M18: 2549 | N18: 2549 | O18: 2499 | P18: 2399 | Q18: 2199 | R18: 2499 | S18: 2399 | T18: 2199 | U18: 2199 | V18: 2199 | W18: 2199 | X18: 2099 | Y18: 1799 | Z18: 1799 | AA18: 1749 | AB18: 2549 | AC18: 2549 | AD18: 2549 | AE18: 2549 | AF18: 2499 | AG18: 2499 | AH18: 2499 | AI18: 2199 | AJ18: 2199 | AK18: 2199 | AL18: 1799 | AM18: 31.12.9999
B19: CAIXA DE SOM | C19: 4018025 | D19: CAIXA DE SOM JBL BOOMBOX 4 | E19: CAIXA DE SOM JBL BOOMBOX 4-PRETO AM | F19: 2599 | G19: 1999 | H19: 2599 | I19: 2599 | J19: 2549 | K19: 2549 | L19: 2549 | M19: 2549 | N19: 2549 | O19: 2499 | P19: 2399 | Q19: 2199 | R19: 2499 | S19: 2399 | T19: 2199 | U19: 2199 | V19: 2199 | W19: 2199 | X19: 2099 | Y19: 1799 | Z19: 1799 | AA19: 1749 | AB19: 2549 | AC19: 2549 | AD19: 2549 | AE19: 2549 | AF19: 2499 | AG19: 2499 | AH19: 2499 | AI19: 2199 | AJ19: 2199 | AK19: 2199 | AL19: 1799 | AM19: 31.12.9999
B20: MÚSICA | C20: 4016358 | D20: CAIXA DE SOM JBL CLIP 5 | E20: CAIXA DE SOM JBL CLIP 5-PRETO | F20: 399 | G20: 399 | H20: 399 | I20: 399 | J20: 349 | K20: 349 | L20: 349 | M20: 349 | N20: 349 | O20: 299 | P20: 299 | Q20: 299 | R20: 299 | S20: 299 | T20: 299 | U20: 299 | V20: 299 | W20: 299 | X20: 299 | Y20: 299 | Z20: 299 | AA20: 299 | AM20: 31.12.9999
B21: MUSICA | C21: 4016341 | D21: CAIXA DE SOM JBL ENCORE ESSENTIAL | E21: CAIXA DE SOM JBL ENCORE ESSENTIAL-PRE AM | F21: 1199 | G21: 1199 | AM21: 31.12.9999
B22: MUSICA | C22: 4015273 | D22: CAIXA DE SOM JBL ENCORE ESSENTIAL | E22: CAIXA DE SOM JBL ENCORE ESSENTIAL-PRETO | F22: 1199 | G22: 1199 | AM22: 31.12.9999
B23: MUSICA | C23: 4017250 | D23: CAIXA DE SOM JBL ENCORE ESSENTIAL 2 | E23: CAIXA DE SOM JBL ENCORE ESSENTIAL 2-PRET | F23: 1499 | G23: 999 | H23: 1499 | I23: 1499 | J23: 1449 | K23: 1449 | L23: 1449 | M23: 1449 | N23: 1449 | O23: 1399 | P23: 1299 | Q23: 999 | R23: 1399 | S23: 1299 | T23: 1099 | U23: 1099 | V23: 999 | W23: 999 | X23: 999 | Y23: 899 | Z23: 899 | AA23: 899 | AB23: 1449 | AC23: 1449 | AD23: 1449 | AE23: 1399 | AF23: 1399 | AG23: 1399 | AH23: 1399 | AI23: 999 | AJ23: 999 | AK23: 999 | AL23: 899 | AM23: 31.12.9999
B24: CAIXA DE SOM | C24: 4017944 | D24: CAIXA DE SOM JBL ENCORE 2 2MIC | E24: CAIXA DE SOM JBL ENCORE 2 2MIC-PRETO AM | F24: 2699 | G24: 1899 | H24: 2699 | I24: 2699 | J24: 2649 | K24: 2649 | L24: 2649 | M24: 2649 | N24: 2649 | O24: 2599 | P24: 2499 | Q24: 2299 | R24: 2599 | S24: 2499 | T24: 2299 | U24: 2299 | V24: 2299 | W24: 2299 | X24: 2199 | Y24: 1899 | Z24: 1899 | AA24: 1849 | AM24: 31.12.9999
B25: CAIXA DE SOM | C25: 4018027 | D25: CAIXA JBL ENCORE ESSENTIAL 2 | E25: CAIXA JBL ENCORE ESSENTIAL 2-PRETO AM | F25: 1699 | G25: 899 | H25: 1699 | I25: 1699 | J25: 1649 | K25: 1649 | L25: 1649 | M25: 1649 | N25: 1649 | O25: 1599 | P25: 1499 | Q25: 1299 | R25: 1599 | S25: 1499 | T25: 1299 | U25: 1299 | V25: 1299 | W25: 1299 | X25: 1199 | Y25: 899 | Z25: 899 | AA25: 899 | AM25: 31.12.9999
B26: CAIXA DE SOM | C26: 4017581 | D26: CAIXA DE SOM JBL GO ESSENTIAL 2 | E26: CAIXA DE SOM JBL GO ESSENTIAL 2-PRETO | F26: 219 | G26: 219 | AM26: 31.12.9999
B27: MÚSICA | C27: 4017638 | D27: CAIXA DE SOM JBL GRIP 16W | E27: CAIXA DE SOM JBL GRIP 16W-PRETO | F27: 549 | G27: 549 | H27: 549 | I27: 549 | J27: 499 | K27: 499 | L27: 499 | M27: 499 | N27: 499 | O27: 449 | P27: 399 | Q27: 399 | R27: 449 | S27: 399 | T27: 399 | U27: 399 | V27: 399 | W27: 399 | X27: 399 | Y27: 399 | Z27: 399 | AA27: 399 | AM27: 31.12.9999
B28: MUSICA | C28: 4016351 | D28: CAIXA DE SOM JBL XTREME 4 | E28: CAIXA DE SOM JBL XTREME 4 | F28: 799 | G28: 999 | H28: 799 | I28: 799 | J28: 749 | K28: 749 | L28: 749 | M28: 749 | N28: 749 | O28: 699 | P28: 599 | Q28: 449 | R28: 699 | S28: 599 | T28: 449 | U28: 449 | V28: 449 | W28: 449 | X28: 449 | Y28: 449 | Z28: 449 | AA28: 449 | AM28: 31.12.9999
B29: BASICO | C29: 4016004 | D29: CAPA CLEAR GALAXY S24 | E29: CAPA CLEAR GALAXY S24-TRANSPARENTE | F29: 129 | G29: 129 | AM29: 31.12.9999
B30: BASICO | C30: 4016005 | D30: CAPA CLEAR GALAXY S24 PLUS | E30: CAPA CLEAR GALAXY S24 PLUS-TRANSPARENTE | F30: 129 | G30: 129 | AM30: 31.12.9999
B31: BASICO | C31: 4016006 | D31: CAPA CLEAR GALAXY S24 ULTRA | E31: CAPA CLEAR GALAXY S24 ULTRA-TRANSPARENTE | F31: 129 | G31: 129 | AM31: 31.12.9999
B32: BASICO | C32: 4015729 | D32: CAPA PROTECTIC COVER GALAXY S23 FE | E32: CAPA PROTECTIC COVER GALAXY S23 FE-TRANS | F32: 10 | G32: 10 | AM32: 31.12.9999
B33: BASICO | C33: 4013975 | D33: CARREGADOR APPLE USB-C 20W | E33: CARREGADOR APPLE USB-C 20W-BRANCO | F33: 219 | G33: 219 | AM33: 31.12.9999
B34: CARREGADOR | C34: 4016254 | D34: CARREGADOR APPLE USB-C 20W 2024 | E34: CARREGADOR APPLE USB-C 20W 2024-BRANCO | F34: 219 | G34: 219 | AM34: 31.12.9999
B35: GAMES | C35: 4018040 | D35: CONTROLE PS5 DUALSENSE 2026 | E35: CONTROLE PS5 DUALSENSE 2026-BRANCO | F35: 499 | G35: 399 | H35: 499 | I35: 499 | J35: 399 | K35: 399 | L35: 399 | M35: 399 | N35: 399 | O35: 349 | P35: 249 | Q35: 249 | R35: 349 | S35: 249 | T35: 249 | U35: 249 | V35: 249 | W35: 249 | X35: 249 | Y35: 249 | Z35: 249 | AA35: 249 | AB35: 399 | AC35: 399 | AD35: 399 | AE35: 399 | AF35: 299 | AG35: 299 | AH35: 299 | AI35: 249 | AJ35: 249 | AK35: 249 | AL35: 249 | AM35: 31.12.9999
B36: GAMES | C36: 4017939 | D36: CONTROLE PS5 DUALSENSE 2026 | E36: CONTROLE PS5 DUALSENSE 2026-AZUL | F36: 499 | G36: 399 | H36: 499 | I36: 499 | J36: 399 | K36: 399 | L36: 399 | M36: 399 | N36: 399 | O36: 349 | P36: 249 | Q36: 249 | R36: 349 | S36: 249 | T36: 249 | U36: 249 | V36: 249 | W36: 249 | X36: 249 | Y36: 249 | Z36: 249 | AA36: 249 | AB36: 399 | AC36: 399 | AD36: 399 | AE36: 399 | AF36: 299 | AG36: 299 | AH36: 299 | AI36: 249 | AJ36: 249 | AK36: 249 | AL36: 249 | AM36: 31.12.9999
B37: GAMER | C37: 4017938 | D37: CONTROLE PS5 DUALSENSE 2026 | E37: CONTROLE PS5 DUALSENSE 2026-PRETO | F37: 499 | G37: 399 | H37: 499 | I37: 499 | J37: 399 | K37: 399 | L37: 399 | M37: 399 | N37: 399 | O37: 349 | P37: 249 | Q37: 249 | R37: 349 | S37: 249 | T37: 249 | U37: 249 | V37: 249 | W37: 249 | X37: 249 | Y37: 249 | Z37: 249 | AA37: 249 | AB37: 399 | AC37: 399 | AD37: 399 | AE37: 399 | AF37: 299 | AG37: 299 | AH37: 299 | AI37: 249 | AJ37: 249 | AK37: 249 | AL37: 249 | AM37: 31.12.9999
B38: GAMER | C38: 4018041 | D38: CONTROLE PS5 DUALSENSE 2026 | E38: CONTROLE PS5 DUALSENSE 2026-CAMUFLADO | F38: 499 | G38: 399 | H38: 499 | I38: 499 | J38: 399 | K38: 399 | L38: 399 | M38: 399 | N38: 399 | O38: 349 | P38: 249 | Q38: 249 | R38: 349 | S38: 249 | T38: 249 | U38: 249 | V38: 249 | W38: 249 | X38: 249 | Y38: 249 | Z38: 249 | AA38: 249 | AB38: 399 | AC38: 399 | AD38: 399 | AE38: 399 | AF38: 299 | AG38: 299 | AH38: 299 | AI38: 249 | AJ38: 249 | AK38: 249 | AL38: 249 | AM38: 31.12.9999
B39: GAMER | C39: 4016340 | D39: CONTROLE SEM FIO PS5 DUALSENSE | E39: CONTROLE SEM FIO PS5 DUALSENSE-BRANCO | F39: 499 | G39: 399 | H39: 499 | I39: 499 | J39: 399 | K39: 399 | L39: 399 | M39: 399 | N39: 399 | O39: 349 | P39: 249 | Q39: 249 | R39: 349 | S39: 249 | T39: 249 | U39: 249 | V39: 249 | W39: 249 | X39: 249 | Y39: 249 | Z39: 249 | AA39: 249 | AB39: 399 | AC39: 399 | AD39: 399 | AE39: 399 | AF39: 299 | AG39: 299 | AH39: 299 | AI39: 249 | AJ39: 249 | AK39: 249 | AL39: 249 | AM39: 31.12.9999
B40: GAMER | C40: 4016494 | D40: CONTROLE SEM FIO PS5 DUALSENSE | E40: CONTROLE SEM FIO PS5 DUALSENSE-PRETO | F40: 499 | G40: 399 | H40: 499 | I40: 499 | J40: 399 | K40: 399 | L40: 399 | M40: 399 | N40: 399 | O40: 349 | P40: 249 | Q40: 249 | R40: 349 | S40: 249 | T40: 249 | U40: 249 | V40: 249 | W40: 249 | X40: 249 | Y40: 249 | Z40: 249 | AA40: 249 | AB40: 399 | AC40: 399 | AD40: 399 | AE40: 399 | AF40: 299 | AG40: 299 | AH40: 299 | AI40: 249 | AJ40: 249 | AK40: 249 | AL40: 249 | AM40: 31.12.9999
B41: GAMER | C41: 4017140 | D41: CONTROLE SEM FIO PS5 DUALSENSE | E41: CONTROLE SEM FIO PS5 DUALSENSE-CAMUFLADO | F41: 499 | G41: 399 | H41: 499 | I41: 499 | J41: 399 | K41: 399 | L41: 399 | M41: 399 | N41: 399 | O41: 349 | P41: 249 | Q41: 249 | R41: 349 | S41: 249 | T41: 249 | U41: 249 | V41: 249 | W41: 249 | X41: 249 | Y41: 249 | Z41: 249 | AA41: 249 | AB41: 399 | AC41: 399 | AD41: 399 | AE41: 399 | AF41: 299 | AG41: 299 | AH41: 299 | AI41: 249 | AJ41: 249 | AK41: 249 | AL41: 249 | AM41: 31.12.9999
...

Sheet TRADE IN
A1: OFERTAS VÁLIDAS APENAS PARA PLANOS CONSUMER
B4: Inclusão de Preços
B5: Alteração de Preços
A7: Preços Elegíveis a Price Back
A8: Preços Elegíveis a Price Oferta
A9: CANAL: | B9: REVENDAS
C11: DATA INÍCIO: | D11: =REV!D11 -> 46311 | J11: COM FIDELIZAÇÃO - GROSS / MIGRAÇÃO / UPGRADE / PORTABILIDADE / BASE SEM MOVIMENTAÇÃO | AM11: TIM FIXO | AP11: TIM CASA
A12: Regra Reembolso Pós Fidelizado | B12: CATEGORIA MKT | C12: CÓDIGO | D12: DESCRIÇÃO COMERCIAL | E12: DESCRIÇÃO SAP | F12: BOOST TRADE IN | G12: PREÇO BASE FATURAMENTO RETAIL | H12: CONTROLE NÃO FIDELIZADO - TODOS (Fatura / Express) | I12: PÓS PAGO NÃO FIDELIZADO - VIDE ABA DE REGRAS | J12: TIM CONTROLE | K12: TIM CONTROLE PLUS | L12: TIM CONTROLE PREMIUM | M12: TIM CONTROLE SMART | N12: TIM CONTROLE REDES SOCIAIS | O12: TIM BLACK | P12: TIM BLACK PLUS | Q12: TIM BLACK PREMIUM | R12: TIM BLACK A (15GB) | S12: TIM BLACK B (20GB) | T12: TIM BLACK C (25GB) | U12: TIM BLACK C ULTRA | V12: TIM BLACK FAMÍLIA | W12: TIM BLACK FAMÍLIA A ONE | X12: TIM BLACK FAMÍLIA PLUS | Y12: TIM BLACK FAMÍLIA PREMIUM | Z12: TIM BLACK FAMÍLIA C ONE | AA12: TIM BLACK FAMÍLIA VIP | AB12: TIM Fibra 400M 24 | AC12: TIM Fibra 500M 24 - 2 | AD12: TIM Fibra 600M 24 - 2 | AE12: TIM Fibra 600M P 24 - 2 | AF12: TIM Fibra 600M M 24 - 2 | AG12: TIM Ultrafibra 800M YT26 | AH12: TIM Fibra 600M GP 25 | AI12: TIM Fibra 1GB 24 | AJ12: TIM Fibra 1GB P 24 | AK12: TIM Fibra 1GB M 24 | AL12: TIM Fibra 2GB 24 | AM12: TIM FIXO LOCAL TOTAL PLUS (Plano Fidelizado) | AN12: TIM FIXO BRASIL TOTAL PLUS (Plano Fidelizado) | AO12: TIM FIXO TOTAL LDI PLUS (Plano Fidelizado) | AP12: TIM LIVE INTERNET 30GB (sem fidelização) | AQ12: TIM LIVE INTERNET 50GB (sem fidelização) | AR12: TIM LIVE INTERNET 80GB (sem fidelização) | AS12: TIM LIVE INTERNET 30GB PLUS | AT12: TIM LIVE INTERNET 50GB PLUS | AU12: TIM LIVE INTERNET 80GB PLUS | AW12: DATA FIM DA OFERTA | AX12: TECNOLOGIA
A13: Price Oferta | B13: 21X | C13: 4014380 | D13: APPLE IPHONE 12 64GB | E13: APPLE IPHONE 12 64GB-PRETO NAC | J13: =IF(VLOOKUP($C13,REV!$C:$AA,8,0)-'TRADE IN'!$F13=0,"",(VLOOKUP($C13,REV!$C:$AA,8,0)-'TRADE IN'!$F13)) -> 999 | K13: =IF(VLOOKUP($C13,REV!$C:$AA,9,0)-'TRADE IN'!$F13=0,"",(VLOOKUP($C13,REV!$C:$AA,9,0)-'TRADE IN'!$F13)) -> 999 | L13: =IF(VLOOKUP($C13,REV!$C:$AA,10,0)-'TRADE IN'!$F13=0,"",(VLOOKUP($C13,REV!$C:$AA,10,0)-'TRADE IN'!$F13)) -> 999 | M13: =IF(VLOOKUP($C13,REV!$C:$AA,11,0)-'TRADE IN'!$F13=0,"",(VLOOKUP($C13,REV!$C:$AA,11,0)-'TRADE IN'!$F13)) -> 999 | N13: =IF(VLOOKUP($C13,REV!$C:$AA,12,0)-'TRADE IN'!$F13=0,"",(VLOOKUP($C13,REV!$C:$AA,12,0)-'TRADE IN'!$F13)) -> 999 | O13: =IF(VLOOKUP($C13,REV!$C:$AA,13,0)-'TRADE IN'!$F13=0,"",(VLOOKUP($C13,REV!$C:$AA,13,0)-'TRADE IN'!$F13)) -> 999 | P13: =IF(VLOOKUP($C13,REV!$C:$AA,14,0)-'TRADE IN'!$F13=0,"",(VLOOKUP($C13,REV!$C:$AA,14,0)-'TRADE IN'!$F13)) -> 999 | Q13: =IF(VLOOKUP($C13,REV!$C:$AA,15,0)-'TRADE IN'!$F13=0,"",(VLOOKUP($C13,REV!$C:$AA,15,0)-'TRADE IN'!$F13)) -> 999 | R13: =IF(VLOOKUP($C13,REV!$C:$AA,16,0)-'TRADE IN'!$F13=0,"",(VLOOKUP($C13,REV!$C:$AA,16,0)-'TRADE IN'!$F13)) -> 999 | S13: =IF(VLOOKUP($C13,REV!$C:$AA,17,0)-'TRADE IN'!$F13=0,"",(VLOOKUP($C13,REV!$C:$AA,17,0)-'TRADE IN'!$F13)) -> 999 | T13: =IF(VLOOKUP($C13,REV!$C:$AA,18,0)-'TRADE IN'!$F13=0,"",(VLOOKUP($C13,REV!$C:$AA,18,0)-'TRADE IN'!$F13)) -> 999 | U13: =IF(VLOOKUP($C13,REV!$C:$AA,19,0)-'TRADE IN'!$F13=0,"",(VLOOKUP($C13,REV!$C:$AA,19,0)-'TRADE IN'!$F13)) -> 999 | V13: =IF(VLOOKUP($C13,REV!$C:$AA,20,0)-'TRADE IN'!$F13=0,"",(VLOOKUP($C13,REV!$C:$AA,20,0)-'TRADE IN'!$F13)) -> 999 | W13: =IF(VLOOKUP($C13,REV!$C:$AA,21,0)-'TRADE IN'!$F13=0,"",(VLOOKUP($C13,REV!$C:$AA,21,0)-'TRADE IN'!$F13)) -> 999 | X13: =IF(VLOOKUP($C13,REV!$C:$AA,22,0)-'TRADE IN'!$F13=0,"",(VLOOKUP($C13,REV!$C:$AA,22,0)-'TRADE IN'!$F13)) -> 999 | Y13: =IF(VLOOKUP($C13,REV!$C:$AA,23,0)-'TRADE IN'!$F13=0,"",(VLOOKUP($C13,REV!$C:$AA,23,0)-'TRADE IN'!$F13)) -> 999 | Z13: =IF(VLOOKUP($C13,REV!$C:$AA,24,0)-'TRADE IN'!$F13=0,"",(VLOOKUP($C13,REV!$C:$AA,24,0)-'TRADE IN'!$F13)) -> 999 | AA13: =IF(VLOOKUP($C13,REV!$C:$AA,25,0)-'TRADE IN'!$F13=0,"",(VLOOKUP($C13,REV!$C:$AA,25,0)-'TRADE IN'!$F13)) -> 999 | AW13: =REV!AW13 -> 03.11.2026 | AX13: =VLOOKUP(C13,REV!C:AX,48,0) -> 5G
A14: Price Oferta | B14: 21X | C14: 4014382 | D14: APPLE IPHONE 12 64GB | E14: APPLE IPHONE 12 64GB-BRANCO NAC | J14: =IF(VLOOKUP($C14,REV!$C:$AA,8,0)-'TRADE IN'!$F14=0,"",(VLOOKUP($C14,REV!$C:$AA,8,0)-'TRADE IN'!$F14)) -> 999 | K14: =IF(VLOOKUP($C14,REV!$C:$AA,9,0)-'TRADE IN'!$F14=0,"",(VLOOKUP($C14,REV!$C:$AA,9,0)-'TRADE IN'!$F14)) -> 999 | L14: =IF(VLOOKUP($C14,REV!$C:$AA,10,0)-'TRADE IN'!$F14=0,"",(VLOOKUP($C14,REV!$C:$AA,10,0)-'TRADE IN'!$F14)) -> 999 | M14: =IF(VLOOKUP($C14,REV!$C:$AA,11,0)-'TRADE IN'!$F14=0,"",(VLOOKUP($C14,REV!$C:$AA,11,0)-'TRADE IN'!$F14)) -> 999 | N14: =IF(VLOOKUP($C14,REV!$C:$AA,12,0)-'TRADE IN'!$F14=0,"",(VLOOKUP($C14,REV!$C:$AA,12,0)-'TRADE IN'!$F14)) -> 999 | O14: =IF(VLOOKUP($C14,REV!$C:$AA,13,0)-'TRADE IN'!$F14=0,"",(VLOOKUP($C14,REV!$C:$AA,13,0)-'TRADE IN'!$F14)) -> 999 | P14: =IF(VLOOKUP($C14,REV!$C:$AA,14,0)-'TRADE IN'!$F14=0,"",(VLOOKUP($C14,REV!$C:$AA,14,0)-'TRADE IN'!$F14)) -> 999 | Q14: =IF(VLOOKUP($C14,REV!$C:$AA,15,0)-'TRADE IN'!$F14=0,"",(VLOOKUP($C14,REV!$C:$AA,15,0)-'TRADE IN'!$F14)) -> 999 | R14: =IF(VLOOKUP($C14,REV!$C:$AA,16,0)-'TRADE IN'!$F14=0,"",(VLOOKUP($C14,REV!$C:$AA,16,0)-'TRADE IN'!$F14)) -> 999 | S14: =IF(VLOOKUP($C14,REV!$C:$AA,17,0)-'TRADE IN'!$F14=0,"",(VLOOKUP($C14,REV!$C:$AA,17,0)-'TRADE IN'!$F14)) -> 999 | T14: =IF(VLOOKUP($C14,REV!$C:$AA,18,0)-'TRADE IN'!$F14=0,"",(VLOOKUP($C14,REV!$C:$AA,18,0)-'TRADE IN'!$F14)) -> 999 | U14: =IF(VLOOKUP($C14,REV!$C:$AA,19,0)-'TRADE IN'!$F14=0,"",(VLOOKUP($C14,REV!$C:$AA,19,0)-'TRADE IN'!$F14)) -> 999 | V14: =IF(VLOOKUP($C14,REV!$C:$AA,20,0)-'TRADE IN'!$F14=0,"",(VLOOKUP($C14,REV!$C:$AA,20,0)-'TRADE IN'!$F14)) -> 999 | W14: =IF(VLOOKUP($C14,REV!$C:$AA,21,0)-'TRADE IN'!$F14=0,"",(VLOOKUP($C14,REV!$C:$AA,21,0)-'TRADE IN'!$F14)) -> 999 | X14: =IF(VLOOKUP($C14,REV!$C:$AA,22,0)-'TRADE IN'!$F14=0,"",(VLOOKUP($C14,REV!$C:$AA,22,0)-'TRADE IN'!$F14)) -> 999 | Y14: =IF(VLOOKUP($C14,REV!$C:$AA,23,0)-'TRADE IN'!$F14=0,"",(VLOOKUP($C14,REV!$C:$AA,23,0)-'TRADE IN'!$F14)) -> 999 | Z14: =IF(VLOOKUP($C14,REV!$C:$AA,24,0)-'TRADE IN'!$F14=0,"",(VLOOKUP($C14,REV!$C:$AA,24,0)-'TRADE IN'!$F14)) -> 999 | AA14: =IF(VLOOKUP($C14,REV!$C:$AA,25,0)-'TRADE IN'!$F14=0,"",(VLOOKUP($C14,REV!$C:$AA,25,0)-'TRADE IN'!$F14)) -> 999 | AW14: =REV!AW14 -> 03.11.2026 | AX14: =VLOOKUP(C14,REV!C:AX,48,0) -> 5G
A15: Price Oferta | B15: 21X | C15: 4014391 | D15: APPLE IPHONE 12 128GB | E15: APPLE IPHONE 12 128GB-PRETO NAC | J15: =IF(VLOOKUP($C15,REV!$C:$AA,8,0)-'TRADE IN'!$F15=0,"",(VLOOKUP($C15,REV!$C:$AA,8,0)-'TRADE IN'!$F15)) -> 999 | K15: =IF(VLOOKUP($C15,REV!$C:$AA,9,0)-'TRADE IN'!$F15=0,"",(VLOOKUP($C15,REV!$C:$AA,9,0)-'TRADE IN'!$F15)) -> 999 | L15: =IF(VLOOKUP($C15,REV!$C:$AA,10,0)-'TRADE IN'!$F15=0,"",(VLOOKUP($C15,REV!$C:$AA,10,0)-'TRADE IN'!$F15)) -> 999 | M15: =IF(VLOOKUP($C15,REV!$C:$AA,11,0)-'TRADE IN'!$F15=0,"",(VLOOKUP($C15,REV!$C:$AA,11,0)-'TRADE IN'!$F15)) -> 999 | N15: =IF(VLOOKUP($C15,REV!$C:$AA,12,0)-'TRADE IN'!$F15=0,"",(VLOOKUP($C15,REV!$C:$AA,12,0)-'TRADE IN'!$F15)) -> 999 | O15: =IF(VLOOKUP($C15,REV!$C:$AA,13,0)-'TRADE IN'!$F15=0,"",(VLOOKUP($C15,REV!$C:$AA,13,0)-'TRADE IN'!$F15)) -> 999 | P15: =IF(VLOOKUP($C15,REV!$C:$AA,14,0)-'TRADE IN'!$F15=0,"",(VLOOKUP($C15,REV!$C:$AA,14,0)-'TRADE IN'!$F15)) -> 999 | Q15: =IF(VLOOKUP($C15,REV!$C:$AA,15,0)-'TRADE IN'!$F15=0,"",(VLOOKUP($C15,REV!$C:$AA,15,0)-'TRADE IN'!$F15)) -> 999 | R15: =IF(VLOOKUP($C15,REV!$C:$AA,16,0)-'TRADE IN'!$F15=0,"",(VLOOKUP($C15,REV!$C:$AA,16,0)-'TRADE IN'!$F15)) -> 999 | S15: =IF(VLOOKUP($C15,REV!$C:$AA,17,0)-'TRADE IN'!$F15=0,"",(VLOOKUP($C15,REV!$C:$AA,17,0)-'TRADE IN'!$F15)) -> 999 | T15: =IF(VLOOKUP($C15,REV!$C:$AA,18,0)-'TRADE IN'!$F15=0,"",(VLOOKUP($C15,REV!$C:$AA,18,0)-'TRADE IN'!$F15)) -> 999 | U15: =IF(VLOOKUP($C15,REV!$C:$AA,19,0)-'TRADE IN'!$F15=0,"",(VLOOKUP($C15,REV!$C:$AA,19,0)-'TRADE IN'!$F15)) -> 999 | V15: =IF(VLOOKUP($C15,REV!$C:$AA,20,0)-'TRADE IN'!$F15=0,"",(VLOOKUP($C15,REV!$C:$AA,20,0)-'TRADE IN'!$F15)) -> 999 | W15: =IF(VLOOKUP($C15,REV!$C:$AA,21,0)-'TRADE IN'!$F15=0,"",(VLOOKUP($C15,REV!$C:$AA,21,0)-'TRADE IN'!$F15)) -> 999 | X15: =IF(VLOOKUP($C15,REV!$C:$AA,22,0)-'TRADE IN'!$F15=0,"",(VLOOKUP($C15,REV!$C:$AA,22,0)-'TRADE IN'!$F15)) -> 999 | Y15: =IF(VLOOKUP($C15,REV!$C:$AA,23,0)-'TRADE IN'!$F15=0,"",(VLOOKUP($C15,REV!$C:$AA,23,0)-'TRADE IN'!$F15)) -> 999 | Z15: =IF(VLOOKUP($C15,REV!$C:$AA,24,0)-'TRADE IN'!$F15=0,"",(VLOOKUP($C15,REV!$C:$AA,24,0)-'TRADE IN'!$F15)) -> 999 | AA15: =IF(VLOOKUP($C15,REV!$C:$AA,25,0)-'TRADE IN'!$F15=0,"",(VLOOKUP($C15,REV!$C:$AA,25,0)-'TRADE IN'!$F15)) -> 999 | AW15: =REV!AW15 -> 03.11.2026 | AX15: =VLOOKUP(C15,REV!C:AX,48,0) -> 5G
A16: Price Oferta | B16: 21X | C16: 4014723 | D16: APPLE IPHONE 13 128GB | E16: APPLE IPHONE 13 128GB-PRETO NAC | J16: =IF(VLOOKUP($C16,REV!$C:$AA,8,0)-'TRADE IN'!$F16=0,"",(VLOOKUP($C16,REV!$C:$AA,8,0)-'TRADE IN'!$F16)) -> 3599 | K16: =IF(VLOOKUP($C16,REV!$C:$AA,9,0)-'TRADE IN'!$F16=0,"",(VLOOKUP($C16,REV!$C:$AA,9,0)-'TRADE IN'!$F16)) -> 3499 | L16: =IF(VLOOKUP($C16,REV!$C:$AA,10,0)-'TRADE IN'!$F16=0,"",(VLOOKUP($C16,REV!$C:$AA,10,0)-'TRADE IN'!$F16)) -> 3499 | M16: =IF(VLOOKUP($C16,REV!$C:$AA,11,0)-'TRADE IN'!$F16=0,"",(VLOOKUP($C16,REV!$C:$AA,11,0)-'TRADE IN'!$F16)) -> 3599 | N16: =IF(VLOOKUP($C16,REV!$C:$AA,12,0)-'TRADE IN'!$F16=0,"",(VLOOKUP($C16,REV!$C:$AA,12,0)-'TRADE IN'!$F16)) -> 3499 | O16: =IF(VLOOKUP($C16,REV!$C:$AA,13,0)-'TRADE IN'!$F16=0,"",(VLOOKUP($C16,REV!$C:$AA,13,0)-'TRADE IN'!$F16)) -> 3099 | P16: =IF(VLOOKUP($C16,REV!$C:$AA,14,0)-'TRADE IN'!$F16=0,"",(VLOOKUP($C16,REV!$C:$AA,14,0)-'TRADE IN'!$F16)) -> 2999 | Q16: =IF(VLOOKUP($C16,REV!$C:$AA,15,0)-'TRADE IN'!$F16=0,"",(VLOOKUP($C16,REV!$C:$AA,15,0)-'TRADE IN'!$F16)) -> 2499 | R16: =IF(VLOOKUP($C16,REV!$C:$AA,16,0)-'TRADE IN'!$F16=0,"",(VLOOKUP($C16,REV!$C:$AA,16,0)-'TRADE IN'!$F16)) -> 3099 | S16: =IF(VLOOKUP($C16,REV!$C:$AA,17,0)-'TRADE IN'!$F16=0,"",(VLOOKUP($C16,REV!$C:$AA,17,0)-'TRADE IN'!$F16)) -> 2999 | T16: =IF(VLOOKUP($C16,REV!$C:$AA,18,0)-'TRADE IN'!$F16=0,"",(VLOOKUP($C16,REV!$C:$AA,18,0)-'TRADE IN'!$F16)) -> 2499 | U16: =IF(VLOOKUP($C16,REV!$C:$AA,19,0)-'TRADE IN'!$F16=0,"",(VLOOKUP($C16,REV!$C:$AA,19,0)-'TRADE IN'!$F16)) -> 2499 | V16: =IF(VLOOKUP($C16,REV!$C:$AA,20,0)-'TRADE IN'!$F16=0,"",(VLOOKUP($C16,REV!$C:$AA,20,0)-'TRADE IN'!$F16)) -> 2499 | W16: =IF(VLOOKUP($C16,REV!$C:$AA,21,0)-'TRADE IN'!$F16=0,"",(VLOOKUP($C16,REV!$C:$AA,21,0)-'TRADE IN'!$F16)) -> 2499 | X16: =IF(VLOOKUP($C16,REV!$C:$AA,22,0)-'TRADE IN'!$F16=0,"",(VLOOKUP($C16,REV!$C:$AA,22,0)-'TRADE IN'!$F16)) -> 2299 | Y16: =IF(VLOOKUP($C16,REV!$C:$AA,23,0)-'TRADE IN'!$F16=0,"",(VLOOKUP($C16,REV!$C:$AA,23,0)-'TRADE IN'!$F16)) -> 1999 | Z16: =IF(VLOOKUP($C16,REV!$C:$AA,24,0)-'TRADE IN'!$F16=0,"",(VLOOKUP($C16,REV!$C:$AA,24,0)-'TRADE IN'!$F16)) -> 1999 | AA16: =IF(VLOOKUP($C16,REV!$C:$AA,25,0)-'TRADE IN'!$F16=0,"",(VLOOKUP($C16,REV!$C:$AA,25,0)-'TRADE IN'!$F16)) -> 1999 | AW16: =REV!AW16 -> 03.11.2026 | AX16: =VLOOKUP(C16,REV!C:AX,48,0) -> 5G
A17: Price Oferta | B17: 21X | C17: 4014594 | D17: APPLE IPHONE 13 256GB | E17: APPLE IPHONE 13 256GB-PRETO | J17: =IF(VLOOKUP($C17,REV!$C:$AA,8,0)-'TRADE IN'!$F17=0,"",(VLOOKUP($C17,REV!$C:$AA,8,0)-'TRADE IN'!$F17)) -> 3799 | K17: =IF(VLOOKUP($C17,REV!$C:$AA,9,0)-'TRADE IN'!$F17=0,"",(VLOOKUP($C17,REV!$C:$AA,9,0)-'TRADE IN'!$F17)) -> 3799 | L17: =IF(VLOOKUP($C17,REV!$C:$AA,10,0)-'TRADE IN'!$F17=0,"",(VLOOKUP($C17,REV!$C:$AA,10,0)-'TRADE IN'!$F17)) -> 3799 | M17: =IF(VLOOKUP($C17,REV!$C:$AA,11,0)-'TRADE IN'!$F17=0,"",(VLOOKUP($C17,REV!$C:$AA,11,0)-'TRADE IN'!$F17)) -> 3799 | N17: =IF(VLOOKUP($C17,REV!$C:$AA,12,0)-'TRADE IN'!$F17=0,"",(VLOOKUP($C17,REV!$C:$AA,12,0)-'TRADE IN'!$F17)) -> 3799 | O17: =IF(VLOOKUP($C17,REV!$C:$AA,13,0)-'TRADE IN'!$F17=0,"",(VLOOKUP($C17,REV!$C:$AA,13,0)-'TRADE IN'!$F17)) -> 3599 | P17: =IF(VLOOKUP($C17,REV!$C:$AA,14,0)-'TRADE IN'!$F17=0,"",(VLOOKUP($C17,REV!$C:$AA,14,0)-'TRADE IN'!$F17)) -> 3499 | Q17: =IF(VLOOKUP($C17,REV!$C:$AA,15,0)-'TRADE IN'!$F17=0,"",(VLOOKUP($C17,REV!$C:$AA,15,0)-'TRADE IN'!$F17)) -> 2999 | R17: =IF(VLOOKUP($C17,REV!$C:$AA,16,0)-'TRADE IN'!$F17=0,"",(VLOOKUP($C17,REV!$C:$AA,16,0)-'TRADE IN'!$F17)) -> 3599 | S17: =IF(VLOOKUP($C17,REV!$C:$AA,17,0)-'TRADE IN'!$F17=0,"",(VLOOKUP($C17,REV!$C:$AA,17,0)-'TRADE IN'!$F17)) -> 3499 | T17: =IF(VLOOKUP($C17,REV!$C:$AA,18,0)-'TRADE IN'!$F17=0,"",(VLOOKUP($C17,REV!$C:$AA,18,0)-'TRADE IN'!$F17)) -> 2999 | U17: =IF(VLOOKUP($C17,REV!$C:$AA,19,0)-'TRADE IN'!$F17=0,"",(VLOOKUP($C17,REV!$C:$AA,19,0)-'TRADE IN'!$F17)) -> 2999 | V17: =IF(VLOOKUP($C17,REV!$C:$AA,20,0)-'TRADE IN'!$F17=0,"",(VLOOKUP($C17,REV!$C:$AA,20,0)-'TRADE IN'!$F17)) -> 2999 | W17: =IF(VLOOKUP($C17,REV!$C:$AA,21,0)-'TRADE IN'!$F17=0,"",(VLOOKUP($C17,REV!$C:$AA,21,0)-'TRADE IN'!$F17)) -> 2999 | X17: =IF(VLOOKUP($C17,REV!$C:$AA,22,0)-'TRADE IN'!$F17=0,"",(VLOOKUP($C17,REV!$C:$AA,22,0)-'TRADE IN'!$F17)) -> 2799 | Y17: =IF(VLOOKUP($C17,REV!$C:$AA,23,0)-'TRADE IN'!$F17=0,"",(VLOOKUP($C17,REV!$C:$AA,23,0)-'TRADE IN'!$F17)) -> 2499 | Z17: =IF(VLOOKUP($C17,REV!$C:$AA,24,0)-'TRADE IN'!$F17=0,"",(VLOOKUP($C17,REV!$C:$AA,24,0)-'TRADE IN'!$F17)) -> 2499 | AA17: =IF(VLOOKUP($C17,REV!$C:$AA,25,0)-'TRADE IN'!$F17=0,"",(VLOOKUP($C17,REV!$C:$AA,25,0)-'TRADE IN'!$F17)) -> 2499 | AW17: =REV!AW17 -> 03.11.2026 | AX17: =VLOOKUP(C17,REV!C:AX,48,0) -> 5G
A18: Price Oferta | B18: 21X | C18: 4014837 | D18: APPLE IPHONE 13 256GB | E18: APPLE IPHONE 13 256GB-AZUL NAC | J18: =IF(VLOOKUP($C18,REV!$C:$AA,8,0)-'TRADE IN'!$F18=0,"",(VLOOKUP($C18,REV!$C:$AA,8,0)-'TRADE IN'!$F18)) -> 3799 | K18: =IF(VLOOKUP($C18,REV!$C:$AA,9,0)-'TRADE IN'!$F18=0,"",(VLOOKUP($C18,REV!$C:$AA,9,0)-'TRADE IN'!$F18)) -> 3799 | L18: =IF(VLOOKUP($C18,REV!$C:$AA,10,0)-'TRADE IN'!$F18=0,"",(VLOOKUP($C18,REV!$C:$AA,10,0)-'TRADE IN'!$F18)) -> 3799 | M18: =IF(VLOOKUP($C18,REV!$C:$AA,11,0)-'TRADE IN'!$F18=0,"",(VLOOKUP($C18,REV!$C:$AA,11,0)-'TRADE IN'!$F18)) -> 3799 | N18: =IF(VLOOKUP($C18,REV!$C:$AA,12,0)-'TRADE IN'!$F18=0,"",(VLOOKUP($C18,REV!$C:$AA,12,0)-'TRADE IN'!$F18)) -> 3799 | O18: =IF(VLOOKUP($C18,REV!$C:$AA,13,0)-'TRADE IN'!$F18=0,"",(VLOOKUP($C18,REV!$C:$AA,13,0)-'TRADE IN'!$F18)) -> 3599 | P18: =IF(VLOOKUP($C18,REV!$C:$AA,14,0)-'TRADE IN'!$F18=0,"",(VLOOKUP($C18,REV!$C:$AA,14,0)-'TRADE IN'!$F18)) -> 3499 | Q18: =IF(VLOOKUP($C18,REV!$C:$AA,15,0)-'TRADE IN'!$F18=0,"",(VLOOKUP($C18,REV!$C:$AA,15,0)-'TRADE IN'!$F18)) -> 2999 | R18: =IF(VLOOKUP($C18,REV!$C:$AA,16,0)-'TRADE IN'!$F18=0,"",(VLOOKUP($C18,REV!$C:$AA,16,0)-'TRADE IN'!$F18)) -> 3599 | S18: =IF(VLOOKUP($C18,REV!$C:$AA,17,0)-'TRADE IN'!$F18=0,"",(VLOOKUP($C18,REV!$C:$AA,17,0)-'TRADE IN'!$F18)) -> 3499 | T18: =IF(VLOOKUP($C18,REV!$C:$AA,18,0)-'TRADE IN'!$F18=0,"",(VLOOKUP($C18,REV!$C:$AA,18,0)-'TRADE IN'!$F18)) -> 2999 | U18: =IF(VLOOKUP($C18,REV!$C:$AA,19,0)-'TRADE IN'!$F18=0,"",(VLOOKUP($C18,REV!$C:$AA,19,0)-'TRADE IN'!$F18)) -> 2999 | V18: =IF(VLOOKUP($C18,REV!$C:$AA,20,0)-'TRADE IN'!$F18=0,"",(VLOOKUP($C18,REV!$C:$AA,20,0)-'TRADE IN'!$F18)) -> 2999 | W18: =IF(VLOOKUP($C18,REV!$C:$AA,21,0)-'TRADE IN'!$F18=0,"",(VLOOKUP($C18,REV!$C:$AA,21,0)-'TRADE IN'!$F18)) -> 2999 | X18: =IF(VLOOKUP($C18,REV!$C:$AA,22,0)-'TRADE IN'!$F18=0,"",(VLOOKUP($C18,REV!$C:$AA,22,0)-'TRADE IN'!$F18)) -> 2799 | Y18: =IF(VLOOKUP($C18,REV!$C:$AA,23,0)-'TRADE IN'!$F18=0,"",(VLOOKUP($C18,REV!$C:$AA,23,0)-'TRADE IN'!$F18)) -> 2499 | Z18: =IF(VLOOKUP($C18,REV!$C:$AA,24,0)-'TRADE IN'!$F18=0,"",(VLOOKUP($C18,REV!$C:$AA,24,0)-'TRADE IN'!$F18)) -> 2499 | AA18: =IF(VLOOKUP($C18,REV!$C:$AA,25,0)-'TRADE IN'!$F18=0,"",(VLOOKUP($C18,REV!$C:$AA,25,0)-'TRADE IN'!$F18)) -> 2499 | AW18: =REV!AW18 -> 03.11.2026 | AX18: =VLOOKUP(C18,REV!C:AX,48,0) -> 5G
A19: Price Oferta | B19: 21X | C19: 4014833 | D19: APPLE IPHONE 13 256GB | E19: APPLE IPHONE 13 256GB-PRETO NAC | J19: =IF(VLOOKUP($C19,REV!$C:$AA,8,0)-'TRADE IN'!$F19=0,"",(VLOOKUP($C19,REV!$C:$AA,8,0)-'TRADE IN'!$F19)) -> 3799 | K19: =IF(VLOOKUP($C19,REV!$C:$AA,9,0)-'TRADE IN'!$F19=0,"",(VLOOKUP($C19,REV!$C:$AA,9,0)-'TRADE IN'!$F19)) -> 3799 | L19: =IF(VLOOKUP($C19,REV!$C:$AA,10,0)-'TRADE IN'!$F19=0,"",(VLOOKUP($C19,REV!$C:$AA,10,0)-'TRADE IN'!$F19)) -> 3799 | M19: =IF(VLOOKUP($C19,REV!$C:$AA,11,0)-'TRADE IN'!$F19=0,"",(VLOOKUP($C19,REV!$C:$AA,11,0)-'TRADE IN'!$F19)) -> 3799 | N19: =IF(VLOOKUP($C19,REV!$C:$AA,12,0)-'TRADE IN'!$F19=0,"",(VLOOKUP($C19,REV!$C:$AA,12,0)-'TRADE IN'!$F19)) -> 3799 | O19: =IF(VLOOKUP($C19,REV!$C:$AA,13,0)-'TRADE IN'!$F19=0,"",(VLOOKUP($C19,REV!$C:$AA,13,0)-'TRADE IN'!$F19)) -> 3599 | P19: =IF(VLOOKUP($C19,REV!$C:$AA,14,0)-'TRADE IN'!$F19=0,"",(VLOOKUP($C19,REV!$C:$AA,14,0)-'TRADE IN'!$F19)) -> 3499 | Q19: =IF(VLOOKUP($C19,REV!$C:$AA,15,0)-'TRADE IN'!$F19=0,"",(VLOOKUP($C19,REV!$C:$AA,15,0)-'TRADE IN'!$F19)) -> 2999 | R19: =IF(VLOOKUP($C19,REV!$C:$AA,16,0)-'TRADE IN'!$F19=0,"",(VLOOKUP($C19,REV!$C:$AA,16,0)-'TRADE IN'!$F19)) -> 3599 | S19: =IF(VLOOKUP($C19,REV!$C:$AA,17,0)-'TRADE IN'!$F19=0,"",(VLOOKUP($C19,REV!$C:$AA,17,0)-'TRADE IN'!$F19)) -> 3499 | T19: =IF(VLOOKUP($C19,REV!$C:$AA,18,0)-'TRADE IN'!$F19=0,"",(VLOOKUP($C19,REV!$C:$AA,18,0)-'TRADE IN'!$F19)) -> 2999 | U19: =IF(VLOOKUP($C19,REV!$C:$AA,19,0)-'TRADE IN'!$F19=0,"",(VLOOKUP($C19,REV!$C:$AA,19,0)-'TRADE IN'!$F19)) -> 2999 | V19: =IF(VLOOKUP($C19,REV!$C:$AA,20,0)-'TRADE IN'!$F19=0,"",(VLOOKUP($C19,REV!$C:$AA,20,0)-'TRADE IN'!$F19)) -> 2999 | W19: =IF(VLOOKUP($C19,REV!$C:$AA,21,0)-'TRADE IN'!$F19=0,"",(VLOOKUP($C19,REV!$C:$AA,21,0)-'TRADE IN'!$F19)) -> 2999 | X19: =IF(VLOOKUP($C19,REV!$C:$AA,22,0)-'TRADE IN'!$F19=0,"",(VLOOKUP($C19,REV!$C:$AA,22,0)-'TRADE IN'!$F19)) -> 2799 | Y19: =IF(VLOOKUP($C19,REV!$C:$AA,23,0)-'TRADE IN'!$F19=0,"",(VLOOKUP($C19,REV!$C:$AA,23,0)-'TRADE IN'!$F19)) -> 2499 | Z19: =IF(VLOOKUP($C19,REV!$C:$AA,24,0)-'TRADE IN'!$F19=0,"",(VLOOKUP($C19,REV!$C:$AA,24,0)-'TRADE IN'!$F19)) -> 2499 | AA19: =IF(VLOOKUP($C19,REV!$C:$AA,25,0)-'TRADE IN'!$F19=0,"",(VLOOKUP($C19,REV!$C:$AA,25,0)-'TRADE IN'!$F19)) -> 2499 | AW19: =REV!AW19 -> 03.11.2026 | AX19: =VLOOKUP(C19,REV!C:AX,48,0) -> 5G
A20: Price Oferta | B20: 21X | C20: 4014836 | D20: APPLE IPHONE 13 256GB | E20: APPLE IPHONE 13 256GB-VERMELHO NAC | J20: =IF(VLOOKUP($C20,REV!$C:$AA,8,0)-'TRADE IN'!$F20=0,"",(VLOOKUP($C20,REV!$C:$AA,8,0)-'TRADE IN'!$F20)) -> 3799 | K20: =IF(VLOOKUP($C20,REV!$C:$AA,9,0)-'TRADE IN'!$F20=0,"",(VLOOKUP($C20,REV!$C:$AA,9,0)-'TRADE IN'!$F20)) -> 3799 | L20: =IF(VLOOKUP($C20,REV!$C:$AA,10,0)-'TRADE IN'!$F20=0,"",(VLOOKUP($C20,REV!$C:$AA,10,0)-'TRADE IN'!$F20)) -> 3799 | M20: =IF(VLOOKUP($C20,REV!$C:$AA,11,0)-'TRADE IN'!$F20=0,"",(VLOOKUP($C20,REV!$C:$AA,11,0)-'TRADE IN'!$F20)) -> 3799 | N20: =IF(VLOOKUP($C20,REV!$C:$AA,12,0)-'TRADE IN'!$F20=0,"",(VLOOKUP($C20,REV!$C:$AA,12,0)-'TRADE IN'!$F20)) -> 3799 | O20: =IF(VLOOKUP($C20,REV!$C:$AA,13,0)-'TRADE IN'!$F20=0,"",(VLOOKUP($C20,REV!$C:$AA,13,0)-'TRADE IN'!$F20)) -> 3599 | P20: =IF(VLOOKUP($C20,REV!$C:$AA,14,0)-'TRADE IN'!$F20=0,"",(VLOOKUP($C20,REV!$C:$AA,14,0)-'TRADE IN'!$F20)) -> 3499 | Q20: =IF(VLOOKUP($C20,REV!$C:$AA,15,0)-'TRADE IN'!$F20=0,"",(VLOOKUP($C20,REV!$C:$AA,15,0)-'TRADE IN'!$F20)) -> 2999 | R20: =IF(VLOOKUP($C20,REV!$C:$AA,16,0)-'TRADE IN'!$F20=0,"",(VLOOKUP($C20,REV!$C:$AA,16,0)-'TRADE IN'!$F20)) -> 3599 | S20: =IF(VLOOKUP($C20,REV!$C:$AA,17,0)-'TRADE IN'!$F20=0,"",(VLOOKUP($C20,REV!$C:$AA,17,0)-'TRADE IN'!$F20)) -> 3499 | T20: =IF(VLOOKUP($C20,REV!$C:$AA,18,0)-'TRADE IN'!$F20=0,"",(VLOOKUP($C20,REV!$C:$AA,18,0)-'TRADE IN'!$F20)) -> 2999 | U20: =IF(VLOOKUP($C20,REV!$C:$AA,19,0)-'TRADE IN'!$F20=0,"",(VLOOKUP($C20,REV!$C:$AA,19,0)-'TRADE IN'!$F20)) -> 2999 | V20: =IF(VLOOKUP($C20,REV!$C:$AA,20,0)-'TRADE IN'!$F20=0,"",(VLOOKUP($C20,REV!$C:$AA,20,0)-'TRADE IN'!$F20)) -> 2999 | W20: =IF(VLOOKUP($C20,REV!$C:$AA,21,0)-'TRADE IN'!$F20=0,"",(VLOOKUP($C20,REV!$C:$AA,21,0)-'TRADE IN'!$F20)) -> 2999 | X20: =IF(VLOOKUP($C20,REV!$C:$AA,22,0)-'TRADE IN'!$F20=0,"",(VLOOKUP($C20,REV!$C:$AA,22,0)-'TRADE IN'!$F20)) -> 2799 | Y20: =IF(VLOOKUP($C20,REV!$C:$AA,23,0)-'TRADE IN'!$F20=0,"",(VLOOKUP($C20,REV!$C:$AA,23,0)-'TRADE IN'!$F20)) -> 2499 | Z20: =IF(VLOOKUP($C20,REV!$C:$AA,24,0)-'TRADE IN'!$F20=0,"",(VLOOKUP($C20,REV!$C:$AA,24,0)-'TRADE IN'!$F20)) -> 2499 | AA20: =IF(VLOOKUP($C20,REV!$C:$AA,25,0)-'TRADE IN'!$F20=0,"",(VLOOKUP($C20,REV!$C:$AA,25,0)-'TRADE IN'!$F20)) -> 2499 | AW20: =REV!AW20 -> 03.11.2026 | AX20: =VLOOKUP(C20,REV!C:AX,48,0) -> 5G
A21: Price Oferta | B21: 21X | C21: 4015185 | D21: APPLE IPHONE 14 128GB | E21: APPLE IPHONE 14 128GB-PRETO | J21: =IF(VLOOKUP($C21,REV!$C:$AA,8,0)-'TRADE IN'!$F21=0,"",(VLOOKUP($C21,REV!$C:$AA,8,0)-'TRADE IN'!$F21)) -> 4199 | K21: =IF(VLOOKUP($C21,REV!$C:$AA,9,0)-'TRADE IN'!$F21=0,"",(VLOOKUP($C21,REV!$C:$AA,9,0)-'TRADE IN'!$F21)) -> 4199 | L21: =IF(VLOOKUP($C21,REV!$C:$AA,10,0)-'TRADE IN'!$F21=0,"",(VLOOKUP($C21,REV!$C:$AA,10,0)-'TRADE IN'!$F21)) -> 4199 | M21: =IF(VLOOKUP($C21,REV!$C:$AA,11,0)-'TRADE IN'!$F21=0,"",(VLOOKUP($C21,REV!$C:$AA,11,0)-'TRADE IN'!$F21)) -> 4199 | N21: =IF(VLOOKUP($C21,REV!$C:$AA,12,0)-'TRADE IN'!$F21=0,"",(VLOOKUP($C21,REV!$C:$AA,12,0)-'TRADE IN'!$F21)) -> 4199 | O21: =IF(VLOOKUP($C21,REV!$C:$AA,13,0)-'TRADE IN'!$F21=0,"",(VLOOKUP($C21,REV!$C:$AA,13,0)-'TRADE IN'!$F21)) -> 3899 | P21: =IF(VLOOKUP($C21,REV!$C:$AA,14,0)-'TRADE IN'!$F21=0,"",(VLOOKUP($C21,REV!$C:$AA,14,0)-'TRADE IN'!$F21)) -> 3799 | Q21: =IF(VLOOKUP($C21,REV!$C:$AA,15,0)-'TRADE IN'!$F21=0,"",(VLOOKUP($C21,REV!$C:$AA,15,0)-'TRADE IN'!$F21)) -> 3099 | R21: =IF(VLOOKUP($C21,REV!$C:$AA,16,0)-'TRADE IN'!$F21=0,"",(VLOOKUP($C21,REV!$C:$AA,16,0)-'TRADE IN'!$F21)) -> 3899 | S21: =IF(VLOOKUP($C21,REV!$C:$AA,17,0)-'TRADE IN'!$F21=0,"",(VLOOKUP($C21,REV!$C:$AA,17,0)-'TRADE IN'!$F21)) -> 3799 | T21: =IF(VLOOKUP($C21,REV!$C:$AA,18,0)-'TRADE IN'!$F21=0,"",(VLOOKUP($C21,REV!$C:$AA,18,0)-'TRADE IN'!$F21)) -> 3099 | U21: =IF(VLOOKUP($C21,REV!$C:$AA,19,0)-'TRADE IN'!$F21=0,"",(VLOOKUP($C21,REV!$C:$AA,19,0)-'TRADE IN'!$F21)) -> 3099 | V21: =IF(VLOOKUP($C21,REV!$C:$AA,20,0)-'TRADE IN'!$F21=0,"",(VLOOKUP($C21,REV!$C:$AA,20,0)-'TRADE IN'!$F21)) -> 3099 | W21: =IF(VLOOKUP($C21,REV!$C:$AA,21,0)-'TRADE IN'!$F21=0,"",(VLOOKUP($C21,REV!$C:$AA,21,0)-'TRADE IN'!$F21)) -> 3099 | X21: =IF(VLOOKUP($C21,REV!$C:$AA,22,0)-'TRADE IN'!$F21=0,"",(VLOOKUP($C21,REV!$C:$AA,22,0)-'TRADE IN'!$F21)) -> 2999 | Y21: =IF(VLOOKUP($C21,REV!$C:$AA,23,0)-'TRADE IN'!$F21=0,"",(VLOOKUP($C21,REV!$C:$AA,23,0)-'TRADE IN'!$F21)) -> 2499 | Z21: =IF(VLOOKUP($C21,REV!$C:$AA,24,0)-'TRADE IN'!$F21=0,"",(VLOOKUP($C21,REV!$C:$AA,24,0)-'TRADE IN'!$F21)) -> 2499 | AA21: =IF(VLOOKUP($C21,REV!$C:$AA,25,0)-'TRADE IN'!$F21=0,"",(VLOOKUP($C21,REV!$C:$AA,25,0)-'TRADE IN'!$F21)) -> 2499 | AW21: =REV!AW21 -> 03.11.2026 | AX21: =VLOOKUP(C21,REV!C:AX,48,0) -> 5G
A22: Price Oferta | B22: 21X | C22: 4015262 | D22: APPLE IPHONE 14 128GB | E22: APPLE IPHONE 14 128GB-PRETO NAC | J22: =IF(VLOOKUP($C22,REV!$C:$AA,8,0)-'TRADE IN'!$F22=0,"",(VLOOKUP($C22,REV!$C:$AA,8,0)-'TRADE IN'!$F22)) -> 4199 | K22: =IF(VLOOKUP($C22,REV!$C:$AA,9,0)-'TRADE IN'!$F22=0,"",(VLOOKUP($C22,REV!$C:$AA,9,0)-'TRADE IN'!$F22)) -> 4199 | L22: =IF(VLOOKUP($C22,REV!$C:$AA,10,0)-'TRADE IN'!$F22=0,"",(VLOOKUP($C22,REV!$C:$AA,10,0)-'TRADE IN'!$F22)) -> 4199 | M22: =IF(VLOOKUP($C22,REV!$C:$AA,11,0)-'TRADE IN'!$F22=0,"",(VLOOKUP($C22,REV!$C:$AA,11,0)-'TRADE IN'!$F22)) -> 4199 | N22: =IF(VLOOKUP($C22,REV!$C:$AA,12,0)-'TRADE IN'!$F22=0,"",(VLOOKUP($C22,REV!$C:$AA,12,0)-'TRADE IN'!$F22)) -> 4199 | O22: =IF(VLOOKUP($C22,REV!$C:$AA,13,0)-'TRADE IN'!$F22=0,"",(VLOOKUP($C22,REV!$C:$AA,13,0)-'TRADE IN'!$F22)) -> 3899 | P22: =IF(VLOOKUP($C22,REV!$C:$AA,14,0)-'TRADE IN'!$F22=0,"",(VLOOKUP($C22,REV!$C:$AA,14,0)-'TRADE IN'!$F22)) -> 3799 | Q22: =IF(VLOOKUP($C22,REV!$C:$AA,15,0)-'TRADE IN'!$F22=0,"",(VLOOKUP($C22,REV!$C:$AA,15,0)-'TRADE IN'!$F22)) -> 3099 | R22: =IF(VLOOKUP($C22,REV!$C:$AA,16,0)-'TRADE IN'!$F22=0,"",(VLOOKUP($C22,REV!$C:$AA,16,0)-'TRADE IN'!$F22)) -> 3899 | S22: =IF(VLOOKUP($C22,REV!$C:$AA,17,0)-'TRADE IN'!$F22=0,"",(VLOOKUP($C22,REV!$C:$AA,17,0)-'TRADE IN'!$F22)) -> 3799 | T22: =IF(VLOOKUP($C22,REV!$C:$AA,18,0)-'TRADE IN'!$F22=0,"",(VLOOKUP($C22,REV!$C:$AA,18,0)-'TRADE IN'!$F22)) -> 3099 | U22: =IF(VLOOKUP($C22,REV!$C:$AA,19,0)-'TRADE IN'!$F22=0,"",(VLOOKUP($C22,REV!$C:$AA,19,0)-'TRADE IN'!$F22)) -> 3099 | V22: =IF(VLOOKUP($C22,REV!$C:$AA,20,0)-'TRADE IN'!$F22=0,"",(VLOOKUP($C22,REV!$C:$AA,20,0)-'TRADE IN'!$F22)) -> 3099 | W22: =IF(VLOOKUP($C22,REV!$C:$AA,21,0)-'TRADE IN'!$F22=0,"",(VLOOKUP($C22,REV!$C:$AA,21,0)-'TRADE IN'!$F22)) -> 3099 | X22: =IF(VLOOKUP($C22,REV!$C:$AA,22,0)-'TRADE IN'!$F22=0,"",(VLOOKUP($C22,REV!$C:$AA,22,0)-'TRADE IN'!$F22)) -> 2999 | Y22: =IF(VLOOKUP($C22,REV!$C:$AA,23,0)-'TRADE IN'!$F22=0,"",(VLOOKUP($C22,REV!$C:$AA,23,0)-'TRADE IN'!$F22)) -> 2499 | Z22: =IF(VLOOKUP($C22,REV!$C:$AA,24,0)-'TRADE IN'!$F22=0,"",(VLOOKUP($C22,REV!$C:$AA,24,0)-'TRADE IN'!$F22)) -> 2499 | AA22: =IF(VLOOKUP($C22,REV!$C:$AA,25,0)-'TRADE IN'!$F22=0,"",(VLOOKUP($C22,REV!$C:$AA,25,0)-'TRADE IN'!$F22)) -> 2499 | AW22: =REV!AW22 -> 03.11.2026 | AX22: =VLOOKUP(C22,REV!C:AX,48,0) -> 5G
